Workbook

Sheet Pasaporte - HC
A18: Nombre | B18: Johanna | D18: VIAJA SOLA
A19: Nombre | B19: Miossotis | D19: ES SU PRIMERA VEZ EN MEDELLIN
A20: Apellido | B20: Grotestam
A21: Apellido de casada
A22: Género: . | B22: Femenino
A23: Pasaporte | B23: NV9RKR5F9
A24: Fecha de nacimiento | B24: 02 de noviembre 1975
A25: Edad | B25: 49
A26: Estado civil | B26: soltera
A27: Dirección
A28: Nacionalidad y domicilio:
A29: Email: | B29: miosotisgrotestam6@gmail.com
A30: Teléfono | B30: 599 9 516 2314
A31: Profesión
A32: RH
A33: Seguro | B33: SVB
A34: Peso | B34: 72 kg
A35: Altura | B35: 1.65m
A36: Idioma
A37: Estadia: | B37: 12 al 19 de octubre

Sheet ITINERARIO
C3: ITINERARIO SUGERIDO: | F3: 12 - 19 OCTUBRE
G4: ACP horas | H4: Traslados cerca | I4: Lejos
E5: 45942 | F5: DOMINGO
F6: Vuelo Curazao - Medellín
B7: Aeroturex | D7: Confirmado | F7: Traslado a aeropuerto - hotel | G7: 0.25
F8: Alojamiento
E9: 45943 | F9: LUNES - DIA FESTIVO NO LABORAL
F10: Desayuno en el hotel
E11: 09:00 am | F11: Traslado hotel - punto de encuentro | H11: 1
E12: 04 HORAS | F12: CITY TOUR por la ciudad en chiva Tour compartido grupal
F13: Traslado hotel - punto de encuentro | H13: 1
F14: TARDE LIBRE
E15: 45944 | F15: MARTES
F16: NO desayunar - Tomar agua
E17: 05:30 am | F17: Traslado Hotel - Centro médico | G17: 0.5 | H17: 1
C18: CIMA | D18: Confirmado | E18: 05:45 am | F18: Toma de muestras de sangre para laboratorios clínicos
C19: CIMA | D19: Confirmado | F19: Ecografía de abdomen total
C20: CIMA | D20: Confirmado | F20: Citología Cervical
C21: CIMA | D21: Confirmado | F21: Mamografía
C22: CIMA | D22: Confirmado | F22: Electrocardiograma
C23: CIMA | D23: Confirmado | F23: Radiografía de tórax
E24: 08:00 am | F24: Traslado Hotel - Centro médico | H24: 1
F25: DIA LIBRE
E26: 45945 | F26: MIERCOLES
F27: Desayuno en el hotel
E28: 01:20 pm | F28: Traslado Hotel - Centro médico | G28: 0.5 | H28: 1
B29: El TESORO | C29: UNIVERSE | D29: Confirmado | E29: 02:00 pm | F29: Cita con especialista en Ginecología
B30: El TESORO | C30: UNIVERSE | F30: Ecografía transvaginal
B31: El TESORO | D31: Confirmado | E31: 3:30 pm | F31: Cita con especialista en Medicina Interna revisión de resultados del chequeo
F32: Traslado centro médico - hotel | H32: 1
E33: 45946 | F33: JUEVES
E34: 45947 | F34: VIERNES
F35: Desayuno en el hotel
E36: 06:30 am | F36: Traslado hotel - punto de encuentro | H36: 1
C37: AEROTUREX | E37: 10 HORAS | F37: TOUR A GUATAPÉ GRUPAL
F38: Traslado hotel - punto de encuentro | H38: 1
E39: 45948 | F39: SÁBADO
E40: 45949 | F40: DOMINGO
F41: Desayuno en su hotel
F42: Traslado hotel - aeropuerto
...

Sheet RVA161-1-COSTEO 11-10-2025
U2: Libro diario contable
C3: PAGOS | L3: 3800 | N3: PAGOS | R3: ESTADO DE CUENTA | U3: PAGOS
B4: ACV documentos | C4: Contabilidad | D4: Operativo | E4: Concepto | F4: Proveedor | G4: Valor | H4: Días | K4: Comisionable | O4: RTE FUENTE | P4: Valor pagado | R4: Valor Neto cobrado al cliente | S4: DIFERENCIA | U4: PROVEEDOR - NOMBRE COMERCIAL | V4: ID | W4: Fecha del pago | X4: Valor del pago | Y4: Forma de pago de donde salió el dinero | Z4: Tipo de movimiento | AA4: Comentarios
B5: GMAIL | C5: APP | D5: EMITIDO | E5: Póliza de asistencia médica al viajero - producto visitor por 06 días | F5: Colasistencia | G5: 3500 | H5: 6 | I5: =G5*H5 -> 21000 | K5: =I5/0.6 -> 35000 | L5: =K5/$L$3 -> 9.2105263 | N5: =2750*8 -> 22000 | O5: 0 | P5: =N5-O5 -> 22000 | R5: =I5+6000 -> 27000 | S5: =R5-N5 -> 5000 | U5: PRE COMPRA
B6: APP | C6: FACTURADO | D6: RECARGADO | E6: SIM CARD VIRTUAL con datos Ilimitados | F6: Connecty | G6: 82000 | H6: 1 | I6: =G6*H6 -> 82000 | K6: =I6/0.85 -> 96470.588 | L6: =K6/3913 -> 24.653869 | N6: =97831-14675 -> 83156 | U6: CONECTY - TECNOTRAVEL SAS | W6: 45941 | X6: 97831 | Y6: JURIDICA BANCOLOMBIA | Z6: TRANSFERENCIA
B7: GMAIL | C7: FACTURADO | D7: Confirmado | E7: Traslado aeropuerto - hotel - aeropuerto en CARRO | F7: Aeroturex | G7: 151000 | H7: 2 | I7: =G7*H7 -> 302000 | K7: =I7/0.98 -> 308163.27 | L7: =K7/$H$58 -> 81.095596 | O7: 0
B8: GMAIL | C8: FACTURADO | D8: Confirmado | E8: CITY TOUR compartido grupal | F8: Aeroturex | G8: 71500 | H8: 1 | I8: =G8*H8 -> 71500 | K8: =I8/0.85 -> 84117.647 | L8: =K8/$H$58 -> 22.136223
B9: GMAIL | C9: FACTURADO | D9: Confirmado | E9: Tour grupal a GUATAPÉ | F9: Aeroturex | G9: 140000 | H9: 1 | I9: =G9*H9 -> 140000 | K9: =I9/0.9 -> 155555.56 | L9: =K9/$H$58 -> 40.935673
E10: PAQUETE DE CHEQUEO MÉDICO | I10: 1350000 | L10: 485 | N10: 687500 | O10: =N10*2% -> 13750 | P10: =N10-O10 -> 673750 | R10: =I10 -> 1350000 | S10: =R10-N10 -> 662500 | U10: CIMA OCUPACIONAL | W10: 45941 | X10: 3000000 | Y10: DEPOSITO EN EFECTIVO | Z10: CONSIGNACION CORRESPONSAL
B11: ARCHIVADO | C11: FACTURADO | D11: Confirmado | E11: Citología cervical | F11: CIMA
B12: ARCHIVADO | C12: FACTURADO | D12: Confirmado | E12: Coprológico | F12: CIMA
B13: ARCHIVADO | C13: FACTURADO | D13: Confirmado | E13: Vitamina D25 | F13: CIMA
B14: ARCHIVADO | C14: FACTURADO | D14: Confirmado | E14: Vitamina B12 | F14: CIMA
E15: Perfil lipídico
B16: ARCHIVADO | C16: FACTURADO | D16: Confirmado | E16: Colesterol HDL | F16: CIMA
B17: ARCHIVADO | C17: FACTURADO | D17: Confirmado | E17: Colesterol LDL | F17: CIMA
B18: ARCHIVADO | C18: FACTURADO | D18: Confirmado | E18: Colesterol total | F18: CIMA
B19: ARCHIVADO | C19: FACTURADO | D19: Confirmado | E19: Triglicéridos | F19: CIMA
E20: Perfil Hepático
B21: ARCHIVADO | C21: FACTURADO | D21: Confirmado | E21: ALT- Alanina transferasa | F21: CIMA
B22: ARCHIVADO | C22: FACTURADO | D22: Confirmado | E22: AST - aspartato transferasa | F22: CIMA
B23: ARCHIVADO | C23: FACTURADO | D23: Confirmado | E23: Bilirrubina total y directa | F23: CIMA
B24: ARCHIVADO | C24: FACTURADO | D24: Confirmado | E24: Gama Glutamil transferasa | F24: CIMA
E25: Perfil Renal
B26: ARCHIVADO | C26: FACTURADO | D26: Confirmado | E26: Creatinina | F26: CIMA
B27: ARCHIVADO | C27: FACTURADO | D27: Confirmado | E27: Uroanálisis | F27: CIMA
B28: ARCHIVADO | C28: FACTURADO | D28: Confirmado | E28: Nitrógeno Ureico en Sangre (BUN) | F28: CIMA
E29: Sangre
B30: ARCHIVADO | C30: FACTURADO | D30: Confirmado | E30: Hemograma completo | F30: CIMA
B31: ARCHIVADO | C31: FACTURADO | D31: Confirmado | E31: Hemoglobina glicosilada | F31: CIMA
B32: ARCHIVADO | C32: FACTURADO | D32: Confirmado | E32: Ferritina | F32: CIMA
B33: ARCHIVADO | C33: FACTURADO | D33: Confirmado | E33: Glucosa sérica | F33: CIMA
E34: Perfil Tiroideo
B35: ARCHIVADO | C35: FACTURADO | D35: Confirmado | E35: T4 total | F35: CIMA
B36: ARCHIVADO | C36: FACTURADO | D36: Confirmado | E36: TSH | F36: CIMA
E37: Enfermedades de transmisión sexual
B38: ARCHIVADO | C38: FACTURADO | D38: Confirmado | E38: VDRL | F38: CIMA
B39: ARCHIVADO | C39: FACTURADO | D39: Confirmado | E39: VIH 1 Y 2, Anticuerpos | F39: CIMA
E40: Imágenes diagnósticas
B41: ARCHIVADO | C41: FACTURADO | D41: Confirmado | E41: Radiografía de tórax | F41: CIMA
...

Sheet  Confirmación de 
C2: RESERVA HOTEL ESTELAR | H2: CONFIRMACIÓN CITA CON MEDICINA INTERNA
H3: VALOR DE LA CONSULTA: 240.000
B22: CONFIRMACIÓN CITA CON ESP EN GINECOLOGIA+ECO TRANSVAGINAL UNIVHERSE
C23: TOTAL A PAGAR:350.000

Sheet PAGOS
B3: DEPOSITO PRIMERA NOCHE HOTEL ESTELAR | F3: GINECOLOGIA Y ECOGRAFIA TRANSVAGINAL | J3: INTERNISTA

Sheet VUELO
K8: DVNXC5
C31: P5 7451

Sheet Detalle de los servicios
B2: DETALLE DE LOS SERVICIOS
B3: ='ANTERIOR COSTEO'!E5 -> #REF! | C3: ='ANTERIOR COSTEO'!L5 -> #REF! | E3: PERFIL HORMONAL
B4: ='ANTERIOR COSTEO'!E6 -> #REF! | C4: ='ANTERIOR COSTEO'!L6 -> #REF! | E4: Estradiol total | F4: 15.79
B5: ='ANTERIOR COSTEO'!E7 -> #REF! | C5: ='ANTERIOR COSTEO'!L7 -> #REF! | E5: FSH Hormona foliculoestimulante | F5: 17.11
B6: ='ANTERIOR COSTEO'!E8 -> #REF! | C6: ='ANTERIOR COSTEO'!L8 -> #REF! | E6: LH Hormona Luteinizante | F6: 16.67
B7: ='ANTERIOR COSTEO'!E9 -> #REF! | C7: ='ANTERIOR COSTEO'!L9 -> #REF! | E7: Prolactina | F7: 15.35
B8: ='ANTERIOR COSTEO'!E10 -> #REF! | C8: ='ANTERIOR COSTEO'!L10 -> #REF! | E8: Progesterona | F8: 18.42
B9: ='ANTERIOR COSTEO'!E11 -> #REF! | C9: ='ANTERIOR COSTEO'!L11 -> #REF! | E9: TOTAL | F9: =SUM(F4:F8) -> 83.34
B10: ='ANTERIOR COSTEO'!E12 -> #REF! | C10: ='ANTERIOR COSTEO'!L12 -> #REF!
B11: ='ANTERIOR COSTEO'!E13 -> #REF! | C11: ='ANTERIOR COSTEO'!L13 -> #REF!
B12: ='ANTERIOR COSTEO'!E14 -> #REF! | C12: ='ANTERIOR COSTEO'!L14 -> #REF!
B13: ='ANTERIOR COSTEO'!E15 -> #REF! | C13: ='ANTERIOR COSTEO'!L15 -> #REF!
B14: ='ANTERIOR COSTEO'!E16 -> #REF! | C14: ='ANTERIOR COSTEO'!L16 -> #REF!
B15: ='ANTERIOR COSTEO'!E17 -> #REF! | C15: ='ANTERIOR COSTEO'!L17 -> #REF!
B16: ='ANTERIOR COSTEO'!E18 -> #REF! | C16: ='ANTERIOR COSTEO'!L18 -> #REF!
B17: ='ANTERIOR COSTEO'!E19 -> #REF! | C17: ='ANTERIOR COSTEO'!L19 -> #REF!
B18: ='ANTERIOR COSTEO'!E20 -> #REF! | C18: ='ANTERIOR COSTEO'!L20 -> #REF!
B19: ='ANTERIOR COSTEO'!E21 -> #REF! | C19: ='ANTERIOR COSTEO'!L21 -> #REF!
B20: ='ANTERIOR COSTEO'!E22 -> #REF! | C20: ='ANTERIOR COSTEO'!L22 -> #REF!
B21: ='ANTERIOR COSTEO'!E23 -> #REF! | C21: ='ANTERIOR COSTEO'!L23 -> #REF!
... B51: ='ANTERIOR COSTEO'!E53 -> #REF! | C51: ='ANTERIOR COSTEO'!L53 -> #REF!
B52: Impuesto bancario 4*1000 | C52: ='ANTERIOR COSTEO'!L57 -> #REF!
B53: VALOR TOTAL A PAGAR en DÓLARES | C53: =SUM(C3:C52) -> #REF!
B54: ='ANTERIOR COSTEO'!E57 -> #REF!
B55: ='ANTERIOR COSTEO'!E58 -> #REF!
B56: ='ANTERIOR COSTEO'!E59 -> #REF!
B57: ='ANTERIOR COSTEO'!E60 -> #REF!
B58: ='ANTERIOR COSTEO'!E61 -> #REF!
B59: ='ANTERIOR COSTEO'!E62 -> #REF!
B60: ='ANTERIOR COSTEO'!E63 -> #REF!
B61: ='ANTERIOR COSTEO'!E64 -> #REF!
B62: ='ANTERIOR COSTEO'!E65 -> #REF!
B63: ='ANTERIOR COSTEO'!E66 -> #REF!
B64: ='ANTERIOR COSTEO'!E67 -> #REF!
B65: ='ANTERIOR COSTEO'!E68 -> #REF!
... B91: ='ANTERIOR COSTEO'!E94 -> #REF!
