Workbook

Sheet Facturación
B2: DATOS DE FACTURACIÓN
B3: Centro de costo principal | C3: Centro de costo específico
B4: RESERVAS
B6: CLIENTE - USUARIO
B7: Nombre | C7: Apellido | D7: Tipo | E7: ID | F7: Teléfono | G7: Dirección | H7: Ciudad | I7: Correo electrónico
B10: Forma de pago | C10: Estado de la factura | D10: Concepto | E10: Fecha | F10: Valor Usd | G10: Valor Pesos | H10: Recibo de caja
B15: Ingresos para terceros | C15: Ingresos propios MEDICAL TRIP | D15: Retención en la fuente _____ %
A18: Fecha SS | B18: Tercero | C18: Nit | D18: Fecha de factura | E18: Factura electrónica O documento soporte | F18: Montante total de la factura | G18: Servicio | H18: Ingresos para terceros de esta RVA
H35: =SUM(H19:H34) -> 0

Sheet Pasaporte - HC
C16: Ruthmilda | D16: Pietersz
B19: Ruthmilda | C19: Cresencia | D19: Pietersz | E19: NY1FDD0K1
B20: Nombre | C20: Ruthmilda | D20: Pasaporte | E20: NY1FDD0K1
B21: Nombre | C21: Cresencia | D21: Fecha de nacimiento | E21: 18 de abril de 1955. | I21: Cedric | J21: Guzman | K21: Pietersz | L21: NT662PRR7
B22: Apellido | C22: Pietersz | D22: Edad | E22: 69 | H22: Nombre | I22: Cedric
H23: Nombre | I23: Guzman
B24: Padre | C24: Donato Pietersz | D24: Ruthmilda | E24: Pietersz | H24: Apellido | I24: Pietersz | K24: 27980
B25: Madre | C25: Argenpina Clarinda. | H25: Pasaporte | I25: NT662PRR7
B26: Estado civil
B27: Dirección | C27: Bacoenaweg25, Charo. | I27: cgpietersz@gmail.com
B28: País | C28: Curazao
B29: Email: | C29: cgpietersz@gmail.com
B30: Profesión | C30: pensionista.
B31: Teléfono | C31: =59995158448 -> 59995158448
B32: RH | C32: O+
B33: Seguro | C33: SVB
B34: Peso | C34: 71 kilos
B35: Altura | C35: 1.71 mts
B36: Idioma | C36: Idiomas: Inglés, Papiamento, Español.
B38: Salud
B45: IVS
B46: Usuario | C46: NY1FDD0K1
B47: Contraseña | C47: nY1FDD0K1*

Sheet COSTEO
F1: 910000
R2: Libro diario contable | Z2: Factura electrónica
B3: DOCUMENTOS | D3: PAGOS | E3: RESERVAS | M3: COMISIONABLE | O3: PRECIO VENTA | R3: PAGOS | W3: ESTADO DE CUENTA | Z3: PAGOS | AH3: FACTURA
B4: Ruthmilda | C4: Cedric | D4: Contabilidad | E4: Operativo | F4: Concepto | G4: Proveedor | H4: Valor | I4: Días | J4: Ruthmilda | K4: Cedric | M4: Ruthmilda | N4: Cedric | O4: Ruthmilda | P4: Cedric | R4: Ruthmilda | S4: Cedric | T4: Retención en la fuente | W4: Valor Neto cobrado al cliente | X4: DIFERENCIA | Z4: PROVEEDOR - NOMBRE COMERCIAL | AA4: ID | AB4: Fecha del pago | AC4: Valor del pago | AD4: Forma de pago de donde salió el dinero | AE4: Tipo de movimiento | AF4: Comentarios | AH4: Fecha de la factura | AI4: FACTURA O CUENTA COBRO | AJ4: VALOR REAL DE LA FACTURA | AK4: CONCEPTO
D5: Facturado | E5: Confirmado | F5: Domicilio | G5: Echavarria | H5: 35000 | I5: 1 | J5: =H5*I5 -> 35000 | M5: =J5 -> 35000 | O5: =M5/$I$58 -> 9.0909091 | R5: 21600 | T5: 0 | U5: =R5+S5-T5 -> 21600 | W5: =J5 -> 35000 | X5: =W5-U5 -> 13400 | Z5: Laboratorio Echavarría | AB5: 45763 | AC5: 641000 | AD5: Bancolombia Jurídica | AE5: Transferencia | AF5: Por cajero automático
B6: Archivado | D6: Facturado | E6: Confirmado | F6: Ferritina | G6: Echavarria | H6: 40000 | I6: 1 | J6: =H6*I6 -> 40000 | M6: =J6/0.6 -> 66666.667 | O6: =M6/$I$58 -> 17.316017 | R6: 27300 | T6: 0 | U6: =R6+S6-T6 -> 27300 | W6: =J6 -> 40000 | X6: =W6-U6 -> 12700
B7: Archivado | D7: Facturado | E7: Confirmado | F7: Hemograma completo | G7: Echavarria | H7: 30000 | I7: 1 | J7: =H7*I7 -> 30000 | M7: =J7/0.6 -> 50000 | O7: =M7/$I$58 -> 12.987013 | R7: 11550 | T7: 0 | U7: =R7+S7-T7 -> 11550 | W7: =J7 -> 30000 | X7: =W7-U7 -> 18450
B8: Archivado | D8: Facturado | E8: Confirmado | F8: T3 libre | G8: Echavarria | H8: 25000 | I8: 1 | J8: =H8*I8 -> 25000 | M8: =J8/0.6 -> 41666.667 | O8: =M8/$I$58 -> 10.822511 | R8: 17847 | T8: 0 | U8: =R8+S8-T8 -> 17847 | W8: =J8 -> 25000 | X8: =W8-U8 -> 7153
B9: Archivado | D9: Facturado | E9: Confirmado | F9: T4 libre | G9: Echavarria | H9: 25000 | I9: 1 | J9: =H9*I9 -> 25000 | M9: =J9/0.6 -> 41666.667 | O9: =M9/$I$58 -> 10.822511 | R9: 15200 | T9: 0 | U9: =R9+S9-T9 -> 15200 | W9: =J9 -> 25000 | X9: =W9-U9 -> 9800
B10: Archivado | D10: Facturado | E10: Confirmado | F10: Vitamina D 25 hidroxi | G10: Echavarria | H10: 45000 | I10: 1 | J10: =H10*I10 -> 45000 | M10: =J10/0.6 -> 75000 | O10: =M10/$I$58 -> 19.480519 | R10: 31500 | T10: 0 | U10: =R10+S10-T10 -> 31500 | W10: =J10 -> 45000 | X10: =W10-U10 -> 13500
B11: Archivado | D11: Facturado | E11: Confirmado | F11: Uroanálisis | G11: Echavarria | H11: 15000 | I11: 1 | J11: =H11*I11 -> 15000 | M11: =J11/0.6 -> 25000 | O11: =M11/$I$58 -> 6.4935065 | R11: 6300 | T11: 0 | U11: =R11+S11-T11 -> 6300 | W11: =J11 -> 15000 | X11: =W11-U11 -> 8700
B12: Archivado | D12: Facturado | E12: Confirmado | F12: ALT- Alanina transferasa | G12: Echavarria | H12: 20000 | I12: 1 | J12: =H12*I12 -> 20000 | M12: =J12/0.6 -> 33333.333 | O12: =M12/$I$58 -> 8.6580087 | R12: 6715 | T12: 0 | U12: =R12+S12-T12 -> 6715 | W12: =J12 -> 20000 | X12: =W12-U12 -> 13285
B13: Archivado | D13: Facturado | E13: Confirmado | F13: AST - aspartato transferasa | G13: Echavarria | H13: 20000 | I13: 1 | J13: =H13*I13 -> 20000 | M13: =J13/0.6 -> 33333.333 | O13: =M13/$I$58 -> 8.6580087 | R13: 6712 | T13: 0 | U13: =R13+S13-T13 -> 6712 | W13: =J13 -> 20000 | X13: =W13-U13 -> 13288
B14: Archivado | D14: Facturado | E14: Confirmado | F14: Bilirrubina total y directa | G14: Echavarria | H14: 22000 | I14: 1 | J14: =H14*I14 -> 22000 | M14: =J14/0.6 -> 36666.667 | O14: =M14/$I$58 -> 9.5238095 | R14: 8858 | T14: 0 | U14: =R14+S14-T14 -> 8858 | W14: =J14 -> 22000 | X14: =W14-U14 -> 13142
B15: Archivado | D15: Facturado | E15: Confirmado | F15: Colesterol HDL | G15: Echavarria | H15: 10000 | I15: 1 | J15: =H15*I15 -> 10000 | M15: =J15/0.6 -> 16666.667 | O15: =M15/$I$58 -> 4.3290043 | R15: 22464 | T15: 0 | U15: =R15+S15-T15 -> 22464 | W15: =J15 -> 10000 | X15: =W15-U15 -> -12464
B16: Archivado | D16: Facturado | E16: Confirmado | F16: Colesterol LDL | G16: Echavarria | H16: 12000 | I16: 1 | J16: =H16*I16 -> 12000 | M16: =J16/0.6 -> 20000 | O16: =M16/$I$58 -> 5.1948052 | T16: 0 | U16: =R16+S16-T16 -> 0 | W16: =J16 -> 12000 | X16: =W16-U16 -> 12000
B17: Archivado | D17: Facturado | E17: Confirmado | F17: Colesterol total | G17: Echavarria | H17: 15000 | I17: 1 | J17: =H17*I17 -> 15000 | M17: =J17/0.6 -> 25000 | O17: =M17/$I$58 -> 6.4935065 | T17: 0 | U17: =R17+S17-T17 -> 0 | W17: =J17 -> 15000 | X17: =W17-U17 -> 15000
B18: Archivado | D18: Facturado | E18: Confirmado | F18: Creatinina | G18: Echavarria | H18: 20000 | I18: 1 | J18: =H18*I18 -> 20000 | M18: =J18/0.6 -> 33333.333 | O18: =M18/$I$58 -> 8.6580087 | R18: 5783 | T18: 0 | U18: =R18+S18-T18 -> 5783 | W18: =J18 -> 20000 | X18: =W18-U18 -> 14217
B19: Archivado | D19: Facturado | E19: Confirmado | F19: Gamma glutamil transferasa | G19: Echavarria | H19: 34000 | I19: 1 | J19: =H19*I19 -> 34000 | M19: =J19/0.6 -> 56666.667 | O19: =M19/$I$58 -> 14.718615 | R19: 9239 | T19: 0 | U19: =R19+S19-T19 -> 9239 | W19: =J19 -> 34000 | X19: =W19-U19 -> 24761
B20: Archivado | D20: Facturado | E20: Confirmado | F20: Glucosa sérica | G20: Echavarria | H20: 20000 | I20: 1 | J20: =H20*I20 -> 20000 | M20: =J20/0.6 -> 33333.333 | O20: =M20/$I$58 -> 8.6580087 | R20: 5322 | T20: 0 | U20: =R20+S20-T20 -> 5322 | W20: =J20 -> 20000 | X20: =W20-U20 -> 14678
B21: Archivado | D21: Facturado | E21: Confirmado | F21: Triglicéridos | G21: Echavarria | H21: 10000 | I21: 1 | J21: =H21*I21 -> 10000 | M21: =J21/0.6 -> 16666.667 | O21: =M21/$I$58 -> 4.3290043 | T21: 0 | U21: =R21+S21-T21 -> 0 | W21: =J21 -> 10000 | X21: =W21-U21 -> 10000
B22: Archivado | D22: Facturado | E22: Confirmado | F22: TSH | G22: Echavarria | H22: 35000 | I22: 1 | J22: =H22*I22 -> 35000 | M22: =J22/0.6 -> 58333.333 | O22: =M22/$I$58 -> 15.151515 | R22: 24047 | T22: 0 | U22: =R22+S22-T22 -> 24047 | W22: =J22 -> 35000 | X22: =W22-U22 -> 10953
B23: Archivado | D23: Facturado | E23: Confirmado | F23: Anticuerpos de peroxidasa tiroidea (TPO Ab) - Tiroideos AC Microsomales | G23: Echavarria | H23: 70000 | I23: 1 | J23: =H23*I23 -> 70000 | M23: =J23/0.8 -> 87500 | O23: =M23/$I$58 -> 22.727273 | R23: 34050 | T23: 0 | U23: =R23+S23-T23 -> 34050 | W23: =J23 -> 70000 | X23: =W23-U23 -> 35950
B24: Archivado | D24: Facturado | E24: Confirmado | F24: Anticuerpos del receptor de tirotropina (TRAb) | G24: Echavarria | H24: 90000 | I24: 1 | J24: =H24*I24 -> 90000 | M24: =J24/0.8 -> 112500 | O24: =M24/$I$58 -> 29.220779 | R24: 114270 | T24: 0 | U24: =R24+S24-T24 -> 114270 | W24: =J24 -> 90000 | X24: =W24-U24 -> -24270
B25: Archivado | D25: Facturado | E25: Confirmado | F25: Autoanticuerpos de tiroglobulina (Tg Ab) Tiroides AC Tiroglobulinicos | G25: Echavarria | H25: 100000 | I25: 1 | J25: =H25*I25 -> 100000 | M25: =J25/0.75 -> 133333.33 | O25: =M25/$I$58 -> 34.632035 | R25: 34500 | T25: 0 | U25: =R25+S25-T25 -> 34500 | W25: =J25 -> 100000 | X25: =W25-U25 -> 65500
B26: Archivado | D26: Facturado | E26: Confirmado | F26: CA 19-9 Antígeno de cáncer de tubo digestivo | G26: Echavarria | H26: 75000 | I26: 1 | J26: =H26*I26 -> 75000 | M26: =J26/0.6 -> 125000 | O26: =M26/$I$58 -> 32.467532 | R26: 38400 | T26: 0 | U26: =R26+S26-T26 -> 38400 | W26: =J26 -> 75000 | X26: =W26-U26 -> 36600
B27: Archivado | D27: Facturado | E27: Confirmado | F27: CA-125 - Antígeno de cáncer de ovario | G27: Echavarria | H27: 58000 | I27: 1 | J27: =H27*I27 -> 58000 | M27: =J27/0.6 -> 96666.667 | O27: =M27/$I$58 -> 25.108225 | R27: 31500 | T27: 0 | U27: =R27+S27-T27 -> 31500 | W27: =J27 -> 58000 | X27: =W27-U27 -> 26500
B28: Archivado | D28: Facturado | E28: Confirmado | F28: Dimero D | G28: Echavarria | H28: 30000 | I28: 1 | J28: =H28*I28 -> 30000 | M28: =J28/0.6 -> 50000 | O28: =M28/$I$58 -> 12.987013 | R28: 26000 | T28: 0 | U28: =R28+S28-T28 -> 26000 | W28: =J28 -> 30000 | X28: =W28-U28 -> 4000
B29: Archivado | D29: Facturado | E29: Confirmado | F29: Homocisteína sérica (HCYSP) | G29: Echavarria | H29: 108000 | I29: 1 | J29: =H29*I29 -> 108000 | M29: =J29/0.8 -> 135000 | O29: =M29/$I$58 -> 35.064935 | R29: 107297 | T29: 0 | U29: =R29+S29-T29 -> 107297 | W29: =J29 -> 108000 | X29: =W29-U29 -> 703
B30: Archivado | D30: Facturado | E30: Confirmado | F30: Nitrógeno Ureico en Sangre (BUN) | G30: Echavarria | H30: 20000 | I30: 1 | J30: =H30*I30 -> 20000 | M30: =J30/0.6 -> 33333.333 | O30: =M30/$I$58 -> 8.6580087 | R30: 5520 | T30: 0 | U30: =R30+S30-T30 -> 5520 | W30: =J30 -> 20000 | X30: =W30-U30 -> 14480
B31: Archivado | D31: Facturado | E31: Confirmado | F31: CEA (carcinoembrionario Antígeno) | G31: Echavarria | H31: 60000 | I31: 1 | J31: =H31*I31 -> 60000 | M31: =J31/0.6 -> 100000 | O31: =M31/$I$58 -> 25.974026 | R31: 31141 | T31: 0 | U31: =R31+S31-T31 -> 31141 | W31: =J31 -> 60000 | X31: =W31-U31 -> 28859
B32: No se realizó | D32: DSM | E32: Confirmado | F32: Citología | G32: Idime | H32: 30000 | I32: 1 | J32: =H32*I32 -> 30000 | M32: =J32/0.6 -> 50000 | O32: =M32/$I$58 -> 12.987013 | R32: 17500 | T32: 0 | U32: =R32+S32-T32 -> 17500 | W32: =J32 -> 30000 | X32: =W32-U32 -> 12500 | Z32: IDIME | AB32: 45768
B33: Archivado | D33: DSM | E33: Confirmado | F33: CA 15-3 Antígeno de cáncer de mama | G33: Idime | H33: 78000 | I33: 1 | J33: =H33*I33 -> 78000 | M33: =J33/0.6 -> 130000 | O33: =M33/$I$58 -> 33.766234 | R33: 33600 | T33: 0 | U33: =R33+S33-T33 -> 33600 | W33: =J33 -> 78000 | X33: =W33-U33 -> 44400
B34: Archivado | D34: DSM | E34: Confirmado | F34: Antígeno leucocitario humano B27 (HLA-B27) | G34: Idime | H34: 116000 | I34: 1 | J34: =H34*I34 -> 116000 | M34: =J34/0.8 -> 145000 | O34: =M34/$I$58 -> 37.662338 | R34: 100000 | T34: 0 | U34: =R34+S34-T34 -> 100000 | W34: =J34 -> 116000 | X34: =W34-U34 -> 16000
B35: Archivado | D35: DSM | E35: Confirmado | F35: Hemoglobina Glicosilada | G35: Idime | H35: 35000 | I35: 1 | J35: =H35*I35 -> 35000 | M35: =J35/0.6 -> 58333.333 | O35: =M35/$I$58 -> 15.151515 | R35: 16100 | T35: 0 | U35: =R35+S35-T35 -> 16100 | W35: =J35 -> 35000 | X35: =W35-U35 -> 18900
B36: Archivado | D36: Facturado | E36: Confirmada | F36: Doppler arterial miembros inferiores | G36: CIMA | H36: 255000 | I36: 1 | J36: =H36*I36 -> 255000 | M36: =J36/0.8 -> 318750 | O36: =M36/$I$58 -> 82.792208 | R36: 190000 | T36: =(R36+S36)*2% -> 3800 | U36: =(R36+S36)-T36 -> 186200 | W36: =J36 -> 255000 | X36: =W36-U36 -> 68800 | Z36: CIMA | AB36: 45763 | AC36: 500000 | AD36: Bancolombia Jurídica | AE36: Transferencia | AF36: Por cajero automático
B37: Archivado | D37: Facturado | E37: Confirmada | F37: Doppler venoso de miembros inferiores | G37: CIMA | H37: 221000 | I37: 1 | J37: =H37*I37 -> 221000 | M37: =J37/0.8 -> 276250 | O37: =M37/$I$58 -> 71.753247 | R37: 190000 | T37: =(R37+S37)*2% -> 3800 | U37: =(R37+S37)-T37 -> 186200 | W37: =J37 -> 221000 | X37: =W37-U37 -> 34800
B38: Archivado | D38: Facturado | E38: Confirmada | F38: Prueba de esfuerzo | G38: In care | H38: 240000 | I38: 1 | J38: =H38*I38 -> 240000 | M38: =J38/0.8 -> 300000 | O38: =M38/$I$58 -> 77.922078 | R38: 204000 | T38: =(R38+S38)*2% -> 4080 | U38: =(R38+S38)-T38 -> 199920 | W38: =J38 -> 240000 | X38: =W38-R38 -> 36000 | Z38: Incare | AB38: 45763 | AC38: 200000 | AD38: Bancolombia Jurídica | AE38: Transferencia | AF38: Por cajero automático
B39: Archivado | D39: Facturado | E39: Confirmada | F39: Tomografía Axial Computarizada (TAC) Pelvis | G39: IVS | H39: 220000 | I39: 1 | J39: =H39*I39 -> 220000 | M39: =J39/0.8 -> 275000 | O39: =M39/$I$58 -> 71.428571 | R39: 195040 | T39: =(R39+S39)*2% -> 3900.8 | U39: =(R39+S39)-T39 -> 191139.2 | W39: =J39 -> 220000 | X39: =W39-R39 -> 24960 | Z39: IVS Imágenes salud y vida | AB39: 45763 | AC39: 69598 | AD39: Bancolombia Jurídica | AE39: Transferencia | AF39: Por cajero automático
B40: Archivado | D40: Facturado | E40: Confirmada | F40: Consulta con especialista en Urología | G40: Diego | H40: 280000 | I40: 1 | J40: =H40*I40 -> 280000 | M40: =J40/0.9 -> 311111.11 | O40: =M40/$I$58 -> 80.808081 | R40: 240000 | T40: 0 | U40: =(R40+S40)-T40 -> 240000 | W40: =J40 -> 280000 | X40: =W40-R40 -> 40000 | Z40: Diego Alejandro López Bernal | AB40: 45763 | AC40: 240000 | AD40: Bancolombia Jurídica | AE40: Transferencia | AF40: Por cajero automático
...

Sheet CARPETA
B4: CARPETA RUTHMILDA
A6: Archivada | B6: Medicina general - Historia clínica - Entrevista virtual de planeación | C6: ok
A7: Archivada | B7: Medicina general - Historia clínica - Entrevista virtual de control | C7: ok
A8: Archivada | B8: *Laboratorios clínicos | C8: ok
B10: Historia clínica de Ginecología y Obstetricia | C10: ok
A11: Archivada | B11: *Ecografía pélvica dinámica | C11: ok
A13: Archivada | B13: Historia clínica de Urología | C13: ok
A14: Archivada | B14: *Tomografía Axial Computarizada (TAC) Pelvis | C14: ok
A15: Archivada | B15: *Cistología | C15: ok
A16: Archivada | B16: *Urodinamia | C16: ok
A18: Archivada | B18: Historia clínica de Cardiología
A19: Archivada | B19: *Doppler arterial miembros inferiores | C19: ok
A20: Archivada | B20: *Doppler venoso de miembros inferiores
A21: Archivada | B21: *Prueba de esfuerzo
B23: ESTUDIOS PENDIENTES X REALIZAR
B24: Tomografía coronoria
B25: Holter

Sheet ITINERARIO
B3: ITINERARIO:
B4: Dia | C4: Fecha | D4: Hora | E4: Actividad | F4: ACP horas | G4: Traslados
B5: 1 | C5: 45764 | D5: Jueves | E5: Día festivo - semana santa
D6: 10:26 pm | E6: Recibimiento en el aeropuerto
D7: 11:00 pm | E7: Traslado a aeropuerto - hotel en el Poblado
D8: 12:00 pm | E8: Alojamiento
B9: 2 | C9: 45765 | D9: Viernes | E9: Día festivo - semana santa
E10: Mañana libre
D11: 02:15 pm | E11: El tour sale y llega al parque el poblado
D12: 02:30 pm - 06:30 pm | E12: Tour compartido a la comuna trece
B13: 3 | C13: 45766 | D13: Sábado
E14: La noche anterior tomar un aromática y papaya a las 10pm
D15: 06:30 am | E15: Toma de muestras de sangre laboratorio clínico a domicilio en su hotel
E16: Desayuno ligero
D17: 10:00 am | E17: Traslado hotel - centro médico | F17: 0.5 | G17: 1
D18: 11:00 am | E18: =COSTEO!F39 -> Tomografía Axial Computarizada (TAC) Pelvis
D19: 12:00 pm | E19: Traslado centro médico hotel | G19: 1
E20: Tiempo para almorzar y descansar
D21: 06:45 pm | E21: El tour sale y llega al parque el poblado
D22: 07:00 pm - 11:00 pm | E22: Chiva rumbera
B23: 4 | C23: 45767 | D23: Domingo
E24: Día libre
B25: 5 | C25: 45768 | D25: Lunes
E26: La noche anterior tomar un aromática y papaya a las 10pm
D27: 06:00 am | E27: Encuentro en su hotel, para trasladarlo al centro médico | F27: 0.5 | G27: 1
D28: 06:30 am | E28: Toma de muestra de sangre
D29: 07:00 am | E29: Citología
D30: 07:30 am | E30: Traslado centro médico - centro médico
D31: 08:30 am | E31: =COSTEO!F36 -> Doppler arterial miembros inferiores
D32: 09:00am | E32: =COSTEO!F37 -> Doppler venoso de miembros inferiores
D33: 10:00 am | E33: Traslado centro médico - hotel | G33: 1
E34: Tiempo para desayunar
E35: Tiempo para Almorzar
D36: 01:00 pm | E36: Traslado hotel - centro médico | G36: 1
D37: 02:00 pm | E37: =COSTEO!F38 -> Prueba de esfuerzo | F37: 0.5
D38: 03:00 pm | E38: Consulta con especialista en Urología
E39: Traslado centro médico hotel | G39: 1
B40: 6 | C40: 45769 | D40: Martes
D41: 06:00 am | E41: Traslado Hotel - centro médico | F41: 1 | G41: 1
E42: =COSTEO!E40 -> Confirmada
...

Sheet Pago
F2: INCARE
C3: ECHAVARRIA | D3: IDIME | F3: =COSTEO!F38 -> Prueba de esfuerzo | G3: 204000
B4: =COSTEO!F5 -> Domicilio | C4: =COSTEO!R5 -> 21600 | G4: =G3*2% -> 4080
A5: 1 | B5: =COSTEO!F6 -> Ferritina | C5: =COSTEO!R6 -> 27300 | G5: =G3-G4 -> 199920
A6: 2 | B6: =COSTEO!F7 -> Hemograma completo | C6: =COSTEO!R7 -> 11550
A7: 3 | B7: =COSTEO!F8 -> T3 libre | C7: =COSTEO!R8 -> 17847
A8: 4 | B8: =COSTEO!F9 -> T4 libre | C8: =COSTEO!R9 -> 15200
A9: 5 | B9: =COSTEO!F10 -> Vitamina D 25 hidroxi | C9: =COSTEO!R10 -> 31500 | F9: =COSTEO!F36 -> Doppler arterial miembros inferiores | G9: 255000
A10: 6 | B10: =COSTEO!F11 -> Uroanálisis | C10: =COSTEO!R11 -> 6300 | F10: =COSTEO!F37 -> Doppler venoso de miembros inferiores | G10: 221000
A11: 7 | B11: =COSTEO!F12 -> ALT- Alanina transferasa | C11: =COSTEO!R12 -> 6715
A12: 8 | B12: =COSTEO!F13 -> AST - aspartato transferasa | C12: =COSTEO!R13 -> 6712 | F12: Total a facturar | G12: =SUM(G9:G10) -> 476000
A13: 9 | B13: =COSTEO!F14 -> Bilirrubina total y directa | C13: =COSTEO!R14 -> 8858 | F13: Retención en la fuente 2% | G13: =G12*2% -> 9520
A14: 10 | B14: Perfil lipidico | C14: =COSTEO!R15 -> 22464 | F14: Total a pagar | G14: =G12-G13 -> 466480
A15: 11 | B15: =COSTEO!F18 -> Creatinina | C15: =COSTEO!R18 -> 5783
A16: 12 | B16: =COSTEO!F19 -> Gamma glutamil transferasa | C16: =COSTEO!R19 -> 9239
A17: 13 | B17: =COSTEO!F20 -> Glucosa sérica | C17: =COSTEO!R20 -> 5322
A18: 14 | B18: =COSTEO!F22 -> TSH | C18: =COSTEO!R22 -> 24047
A19: 15 | B19: =COSTEO!F23 -> Anticuerpos de peroxidasa tiroidea (TPO Ab) - Tiroideos AC Microsomales | C19: =COSTEO!R23 -> 34050
A20: 16 | B20: =COSTEO!F24 -> Anticuerpos del receptor de tirotropina (TRAb) | C20: =COSTEO!R24 -> 114270
A21: 17 | B21: =COSTEO!F25 -> Autoanticuerpos de tiroglobulina (Tg Ab) Tiroides AC Tiroglobulinicos | C21: =COSTEO!R25 -> 34500
A22: 18 | B22: =COSTEO!F26 -> CA 19-9 Antígeno de cáncer de tubo digestivo | C22: =COSTEO!R26 -> 38400
A23: 19 | B23: =COSTEO!F27 -> CA-125 - Antígeno de cáncer de ovario | C23: =COSTEO!R27 -> 31500
A24: 20 | B24: =COSTEO!F28 -> Dimero D | C24: =COSTEO!R28 -> 26000
A25: 21 | B25: =COSTEO!F29 -> Homocisteína sérica (HCYSP) | C25: 104976
A26: 22 | B26: =COSTEO!F30 -> Nitrógeno Ureico en Sangre (BUN) | C26: =COSTEO!R30 -> 5520
A27: 23 | B27: =COSTEO!F31 -> CEA (carcinoembrionario Antígeno) | C27: =COSTEO!R31 -> 31141
B28: Total a pagar en Echavarría | C28: =SUM(C4:C27) -> 640794
B31: =COSTEO!F33 -> CA 15-3 Antígeno de cáncer de mama | C31: 33600
B32: =COSTEO!F34 -> Antígeno leucocitario humano B27 (HLA-B27) | C32: 100000
B33: =COSTEO!F35 -> Hemoglobina Glicosilada | C33: 16100
B34: Total a pagar en Idime | C34: =SUM(C31:C33) -> 149700
B36: 3043733052
B49: =COSTEO!F36 -> Doppler arterial miembros inferiores
B50: =COSTEO!F37 -> Doppler venoso de miembros inferiores
B51: =COSTEO!F38 -> Prueba de esfuerzo
B52: =COSTEO!F39 -> Tomografía Axial Computarizada (TAC) Pelvis
B53: =COSTEO!F40 -> Consulta con especialista en Urología
B54: =COSTEO!F41 -> Consulta con Medicina general - entrevista virtual planeación
B55: =COSTEO!F42 -> Consulta con Medicina general - entrevista virtual revisión
B56: =COSTEO!F43 -> Póliza de asistencia médica al viajero - producto visitor por 05 días
...

Sheet  Confirmación de 
B2: Fecha | C2: 45766
B3: Día | C3: Sábado
B4: Hora | C4: 06:00 am
B5: Sede | C5: Domicilio Laureles o Poblado
B6: Cliente | C6: Medical Trip Colombia SAS
B7: Correo | C7: reservasmedical@gmail.com
B8: Teléfono | C8: 315 772 1914
B9: Paciente Nombre | C9: Ruthmilda
B10: Paciente Apeliido | C10: Pietersz
B11: Pasaporte | C11: NY1FDD0K1
B12: Fecha de nacimiento | C12: 18 de abril de 1955.
B13: Servicio | C13: Exámenes de laboratorio cliníco para dos domicilios
B16: Fecha | C16: 45766 | K16: ALOJAMIENTO
B17: Hora | C17: 10:00 am | K17: Check in
B18: Sede | C18: IVS Punto Clave | K18: Check out
B19: Cliente | C19: Medical Trip Colombia SAS | K19: Record localizador
B20: Correo | C20: reservasmedical@gmail.com | K20: Dirección
B21: Teléfono | C21: 315 772 1914 | K21: Tipo de habitación
B22: Paciente Nombre | C22: Ruthmilda | K22: Desayuno
B23: Paciente Apeliido | C23: Pietersz
B24: Pasaporte | C24: NY1FDD0K1
B25: Fecha de nacimiento | C25: 18 de abril de 1955.
B26: Servicio | C26: Tomografía simple Axial Computarizada (TAC) Pelvis
C29: SOLICITUD DE RESERVA
B30: Fecha | C30: 45768
B31: Día | C31: Lunes
B32: Hora | C32: 08:30 am
B33: Sede | C33: Hernan Ocazionez - Poblado
B34: Cliente | C34: Medical Trip Colombia SAS
B35: Correo | C35: reservasmedical@gmail.com
B36: Teléfono | C36: 315 772 1914
B37: País | C37: Curazao
B38: Paciente Nombre | C38: Ruthmilda
B39: Paciente Apeliido | C39: Pietersz
B40: Pasaporte | C40: NY1FDD0K1
B41: Fecha de nacimiento | C41: 18 de abril de 1955.
B42: Servicio | C42: Ecografía de abdomen total
... B54: Servicio | C54: Prueba de esfuerzo
B57: Fecha | C57: 45768
B58: Hora | C58: 03:40 pm
...

Sheet Anterior cancelado - Copia de  
B2: Fecha | C2: 45766
B3: Día | C3: Sábado
B4: Hora | C4: 06:00 am
B5: Sede | C5: Domicilio Laureles o Poblado
B6: Cliente | C6: Medical Trip Colombia SAS
B7: Correo | C7: reservasmedical@gmail.com
B8: Teléfono | C8: 315 772 1914
B9: Paciente Nombre | C9: Ruthmilda
B10: Paciente Apeliido | C10: Pietersz
B11: Pasaporte | C11: NY1FDD0K1
B12: Fecha de nacimiento | C12: 18 de abril de 1955.
B13: Servicio | C13: Exámenes de laboratorio cliníco para dos domicilios
B16: Fecha | C16: 45766 | K16: ALOJAMIENTO
B17: Hora | C17: 10:00 am | K17: Check in
B18: Sede | C18: IVS Punto Clave | K18: Check out
B19: Cliente | C19: Medical Trip Colombia SAS | K19: Record localizador
B20: Correo | C20: reservasmedical@gmail.com | K20: Dirección
B21: Teléfono | C21: 315 772 1914 | K21: Tipo de habitación
B22: Paciente Nombre | C22: Ruthmilda | K22: Desayuno
B23: Paciente Apeliido | C23: Pietersz
B24: Pasaporte | C24: NY1FDD0K1
B25: Fecha de nacimiento | C25: 18 de abril de 1955.
B26: Servicio | C26: Tomografía simple Axial Computarizada (TAC) Pelvis
C29: SOLICITUD DE RESERVA
B30: Fecha | C30: 45768
B31: Día | C31: Lunes
B32: Hora | C32: 08:30 am
B33: Sede | C33: Hernan Ocazionez - Poblado
B34: Cliente | C34: Medical Trip Colombia SAS
B35: Correo | C35: reservasmedical@gmail.com
B36: Teléfono | C36: 315 772 1914
B37: País | C37: Curazao
B38: Paciente Nombre | C38: Ruthmilda
B39: Paciente Apeliido | C39: Pietersz
B40: Pasaporte | C40: NY1FDD0K1
B41: Fecha de nacimiento | C41: 18 de abril de 1955.
B42: Servicio | C42: Ecografía de abdomen total - CANCELADA
... B54: Servicio | C54: Prueba de esfuerzo
B57: Fecha | C57: 45768
B58: Hora | C58: 03:40 pm
...

Sheet Detalle de los servicios
B3: DETALLE DE SERVICIOS | C3: RUTHMILDA | D3: CEDRIC
B4: =COSTEO!F6 -> Ferritina | C4: =COSTEO!O6 -> 17.316017
B5: =COSTEO!F7 -> Hemograma completo | C5: =COSTEO!O7 -> 12.987013
B6: =COSTEO!F8 -> T3 libre | C6: =COSTEO!O8 -> 10.822511
B7: =COSTEO!F9 -> T4 libre | C7: =COSTEO!O9 -> 10.822511
B8: =COSTEO!F10 -> Vitamina D 25 hidroxi | C8: =COSTEO!O10 -> 19.480519
B9: =COSTEO!F11 -> Uroanálisis | C9: =COSTEO!O11 -> 6.4935065
B10: =COSTEO!F32 -> Citología | C10: =COSTEO!O32 -> 12.987013
B11: =COSTEO!F12 -> ALT- Alanina transferasa | C11: =COSTEO!O12 -> 8.6580087
B12: =COSTEO!F13 -> AST - aspartato transferasa | C12: =COSTEO!O13 -> 8.6580087
B13: =COSTEO!F14 -> Bilirrubina total y directa | C13: =COSTEO!O14 -> 9.5238095
B14: =COSTEO!F15 -> Colesterol HDL | C14: =COSTEO!O15 -> 4.3290043
B15: =COSTEO!F16 -> Colesterol LDL | C15: =COSTEO!O16 -> 5.1948052
B16: =COSTEO!F17 -> Colesterol total | C16: =COSTEO!O17 -> 6.4935065
B17: =COSTEO!F18 -> Creatinina | C17: =COSTEO!O18 -> 8.6580087
B18: =COSTEO!F19 -> Gamma glutamil transferasa | C18: =COSTEO!O19 -> 14.718615
B19: =COSTEO!F20 -> Glucosa sérica | C19: =COSTEO!O20 -> 8.6580087
B20: =COSTEO!F35 -> Hemoglobina Glicosilada | C20: =COSTEO!O35 -> 15.151515
B21: =COSTEO!F21 -> Triglicéridos | C21: =COSTEO!O21 -> 4.3290043
B22: =COSTEO!F22 -> TSH | C22: =COSTEO!O22 -> 15.151515
B23: =COSTEO!F5 -> Domicilio | C23: =COSTEO!O5 -> 9.0909091
B24: =COSTEO!F23 -> Anticuerpos de peroxidasa tiroidea (TPO Ab) - Tiroideos AC Microsomales | C24: =COSTEO!O23 -> 22.727273
B25: =COSTEO!F24 -> Anticuerpos del receptor de tirotropina (TRAb) | C25: =COSTEO!O24 -> 29.220779
B26: =COSTEO!F34 -> Antígeno leucocitario humano B27 (HLA-B27) | C26: =COSTEO!O34 -> 37.662338
B27: =COSTEO!F25 -> Autoanticuerpos de tiroglobulina (Tg Ab) Tiroides AC Tiroglobulinicos | C27: =COSTEO!O25 -> 34.632035
B28: =COSTEO!F33 -> CA 15-3 Antígeno de cáncer de mama | C28: =COSTEO!O33 -> 33.766234
B29: =COSTEO!F26 -> CA 19-9 Antígeno de cáncer de tubo digestivo | C29: =COSTEO!O26 -> 32.467532
B30: =COSTEO!F27 -> CA-125 - Antígeno de cáncer de ovario | C30: =COSTEO!O27 -> 25.108225
B31: =COSTEO!F28 -> Dimero D | C31: =COSTEO!O28 -> 12.987013
B32: =COSTEO!F29 -> Homocisteína sérica (HCYSP) | C32: =COSTEO!O29 -> 35.064935
B33: =COSTEO!F30 -> Nitrógeno Ureico en Sangre (BUN) | C33: =COSTEO!O30 -> 8.6580087
B34: =COSTEO!F31 -> CEA (carcinoembrionario Antígeno) | C34: =COSTEO!O31 -> 25.974026
B35: =COSTEO!F36 -> Doppler arterial miembros inferiores | C35: =COSTEO!O36 -> 82.792208
B36: =COSTEO!F37 -> Doppler venoso de miembros inferiores | C36: =COSTEO!O37 -> 71.753247
B37: =COSTEO!F38 -> Prueba de esfuerzo | C37: =COSTEO!O38 -> 77.922078
B38: =COSTEO!F39 -> Tomografía Axial Computarizada (TAC) Pelvis | C38: =COSTEO!O39 -> 71.428571
B39: =COSTEO!F40 -> Consulta con especialista en Urología | C39: =COSTEO!O40 -> 80.808081
B40: =COSTEO!F41 -> Consulta con Medicina general - entrevista virtual planeación | C40: =COSTEO!O41 -> 24.446142
B41: =COSTEO!F42 -> Consulta con Medicina general - entrevista virtual revisión | C41: =COSTEO!O42 -> 24.446142
B42: =COSTEO!F43 -> Póliza de asistencia médica al viajero - producto visitor por 05 días | C42: =COSTEO!O43 -> 10.38961 | D42: =COSTEO!P43 -> 10.38961
...

Sheet Vuelo
F2: 3VK3DY
F3: pietersz
L4: 3VK3DY
B23: 23JOV7
