Workbook

Sheet PASAPORTE DATOS 
A18: Nombre | B18: Robertico | D18: Nombre | G18: Nombre
A19: Nombre | D19: Nombre | G19: Nombre
A20: Apellido | B20: Joseph | D20: Apellido | G20: Nombre
A21: Apellido de casada | D21: Apellido de casada | G21: Apellido
A22: Género: . | B22: Masculino | D22: Género: . | G22: Apellido de casada
A23: Pasaporte | B23: NWC1PL5C3 | D23: Pasaporte | G23: Género: .
A24: Fecha de nacimiento | B24: 28064 | D24: Fecha de nacimiento | G24: Pasaporte
A25: Edad | B25: =2025-1976 -> 49 | D25: Edad | G25: Fecha de nacimiento
A26: Estado civil | D26: Estado civil | G26: Edad
A27: Dirección | B27: Ijsselstraat 6, Suffisant, Wiemstad, Curazao | D27: Dirección | G27: Estado civil
A28: Nacionalidad y domicilio: | D28: Nacionalidad y domicilio: | G28: Dirección
A29: Email: | B29: tico.ras.joseph@gmail.com | D29: Email: | G29: Nacionalidad y domicilio:
A30: Teléfono | D30: Teléfono | G30: Email:
A31: Profesión | D31: Profesión | G31: Teléfono
A32: RH | D32: RH | G32: Profesión
A33: Seguro | D33: Seguro | G33: RH
A34: Peso | B34: 93 kg | D34: Peso | G34: Seguro
A35: Altura | B35: 1,77 metros. | D35: Altura | G35: Peso
A36: Idioma | B36: Español, Holandés. | D36: Idioma | G36: Altura
A37: Estadia: | G37: Idioma
D38: Salud
G39: Salud

Sheet ITINERARIO
D3: ITINERARIO: | F3: 15 - 22 NOVIEMBRE
C4: Dia | D4: Fecha | E4: Hora | F4: Actividad | G4: ACP horas | H4: Traslado cerca | I4: Traslado lejos
D5: 1 | E5: 45976 | F5: SÁBADO
E6: 07:00 pm | F6: Vuelo directo Curazao - Medellín - vía Wingo
E7: 08:00 pm | F7: Traslado aeropuerto - Hotel
E8: 09:00 pm | F8: Alojamiento en el Poblado
D9: 2 | E9: 45977 | F9: DOMINGO - DÍA LIBRE
D10: 3 | E10: 45978 | F10: LUNES FESTIVO NO laboral
D11: 4 | E11: 45979 | F11: MARTES
F12: No desayunar - No tomar agua
B13: HOTEL | C13: ECHAVARRÍA DOMICILIO | D13: ok cotización pendiente pedir domicilio | E13: entre 07:00 am - 08:30 am | F13: Toma de muestras de sangre laboratorio clínico a domicilio en su hotel
F14: Desayuno en el hotel
C15: Yenny | D15: CONFIRMADO | F15: Traslado Hotel - Centro médico | G15: 0.25 | H15: 1
B16: El poblado | C16: CRE | D16: CONFIRMADO | E16: 11:00 am | F16: Resonancia de columna lumbar simple
C17: Yenny | D17: CONFIRMADO | F17: Traslado Centro médico - Hotel | H17: 1
F18: TARDE LIBRE
D19: 5 | E19: 45980 | F19: MIÉRCOLES
E20: 05:30 am | F20: No desayunar - tomar agua - Tennis - ropa cómoda
C21: Yenny | D21: CONFIRMADO | F21: Traslado Hotel - Centro médico | G21: 0.5 | H21: 1
C22: CIMA | D22: PENDIENTE | F22: Ecografía de abdomen total
D23: PENDIENTE | F23: Ecografía transrectal del próstata
D24: PENDIENTE | F24: Electrocardiograma
D25: PENDIENTE | F25: Radiografía de tórax
C26: Yenny | D26: CONFIRMADO | E26: 08:00 am | F26: Traslado Centro médico - Hotel | H26: 1
F27: Desayuno en el hotel
F28: DÍA LIBRE
D29: 6 | E29: 45981 | F29: JUEVES
F30: Desayuno en el hotel
C31: Yenny | D31: CONFIRMADO | E31: 09:30 am | F31: Traslado Hotel - Centro médico | G31: 0.5 | H31: 1
B32: Clinica las vegas | C32: Dr. Juan Diego Arango | D32: SOLICITADO | E32: 10:00AM | F32: Consulta con especialista en UROLOGIA
E33: 11:00 am | F33: Tiempo para almorzar
C34: Yenny | D34: CONFIRMADO | F34: Traslado Centro médico - centro medico | G34: 0.5 | H34: 1
C35: IPS | D35: CONFIRMADO | E35: 12:00 pm | F35: Electromiografía miembros INFERIORES con NCS (Nerve Conduction Studies)
C36: IPS | D36: CONFIRMADO | E36: 12:30 pm | F36: Consulta con especialista en FISIATRÍA
C37: ORVE | D37: CONFIRMADO | E37: 02:00 pm | F37: Consulta con especialista en ORTOPEDIA
B38: Clinica las vegas | D38: solicitado | E38: 03:00 pm | F38: Consulta con especialista en CARDIOLOGIA
F39: Traslado Centro médico - Hotel | H39: 1
D40: 7 | E40: 45982 | F40: VIERNES - DÍA LIBRE
D41: 8 | E41: 45983 | F41: SÁBADO
F42: Desayuno en el hotel
...

Sheet 21102025 COSTEO
Y2: Libro diario contable
C3: PAGOS | M3: 3700 | Q3: PAGOS | V3: ESTADO DE CUENTA | Y3: PAGOS
B4: ACV documentos | C4: Contabilidad | D4: Operativo | E4: Concepto | F4: Proveedor | G4: Valor | H4: Días | I4: Robertico | J4: Acompañante | L4: Robertico | M4: Acompañante | N4: Robertico | O4: Acompañante | Q4: Robertico | R4: Acompañante | S4: Retención en la fuente | T4: Valor pagado | V4: Valor Neto cobrado al cliente | W4: DIFERENCIA | Y4: PROVEEDOR - NOMBRE COMERCIAL | Z4: ID | AA4: Fecha del pago | AB4: Valor del pago | AC4: Forma de pago de donde salió el dinero | AD4: Tipo de movimiento | AE4: Comentarios | AG4: Comentarios
E5: Póliza de asistencia médica al viajero - producto visitor | F5: Colasistencia | G5: 3500 | H5: 6 | I5: =G5*H5 -> 21000 | J5: =G5*H5 -> 21000 | L5: =I5/0.7 -> 30000 | M5: =J5/0.7 -> 30000 | N5: =L5/$H$69 -> 8.1081081 | O5: =M5/$H$69 -> 8.1081081
E6: Sim card física | G6: $6,000 | H6: 1 | I6: =G6*H6 -> 6000 | L6: =I6/0.6 -> 10000 | N6: =L6/$M$3 -> 2.7027027
E7: Recarga de datos de 10 GB | G7: $12,000 | H7: 1 | I7: =G7*H7 -> 12000 | L7: =I7/0.6 -> 20000 | N7: =L7/$M$3 -> 5.4054054
E8: Traslado aeropuerto - hotel - aeropuerto | G8: 151000 | H8: 1 | I8: =G8*H8 -> 151000 | J8: =G8*H8 -> 151000 | L8: =I8/0.99 -> 152525.25 | M8: =J8/0.99 -> 152525.25 | N8: =L8/$M$3 -> 41.223041 | O8: =N8 -> 41.223041
E9: PAQUETE DE CHEQUEO MÉDICO | I9: 1300000 | M9: =J9/0.7 -> 0 | N9: 470
E10: LABORATORIOS CLÍNICOS | M10: =J10/0.7 -> 0
C11: OK | D11: OK | E11: Antígeno de próstata | M11: =J11/0.7 -> 0
C12: OK | D12: OK | E12: Coprológico | M12: =J12/0.7 -> 0
C13: OK | D13: OK | E13: Vitamina D25 | M13: =J13/0.7 -> 0
C14: OK | D14: OK | E14: Vitamina B12 | M14: =J14/0.7 -> 0
E15: Perfil lipídico | M15: =J15/0.7 -> 0
C16: OK | D16: OK | E16: Colesterol HDL | M16: =J16/0.7 -> 0
C17: OK | D17: OK | E17: Colesterol LDL | M17: =J17/0.7 -> 0
C18: OK | D18: OK | E18: Colesterol total | M18: =J18/0.7 -> 0
C19: OK | D19: OK | E19: Triglicéridos | M19: =J19/0.7 -> 0
E20: Perfil Hepático | M20: =J20/0.7 -> 0
C21: OK | D21: OK | E21: ALT- Alanina transferasa | M21: =J21/0.7 -> 0
C22: OK | D22: OK | E22: AST - aspartato transferasa | M22: =J22/0.7 -> 0
C23: OK | D23: OK | E23: Bilirrubina total y directa | M23: =J23/0.7 -> 0
C24: OK | D24: OK | E24: Gama Glutamil transferasa | M24: =J24/0.7 -> 0
E25: Perfil Renal | M25: =J25/0.7 -> 0
C26: OK | D26: OK | E26: Creatinina | M26: =J26/0.7 -> 0
C27: OK | D27: OK | E27: Uroanálisis | M27: =J27/0.7 -> 0
C28: OK | D28: OK | E28: Nitrógeno Ureico en Sangre (BUN) | M28: =J28/0.7 -> 0
E29: Sangre | M29: =J29/0.7 -> 0
C30: OK | D30: OK | E30: Hemograma completo | M30: =J30/0.7 -> 0
C31: OK | D31: OK | E31: Hemoglobina glicosilada | M31: =J31/0.7 -> 0
C32: OK | D32: OK | E32: Ferritina | M32: =J32/0.7 -> 0
C33: OK | D33: OK | E33: Glucosa sérica | M33: =J33/0.7 -> 0
C34: OK | D34: OK | E34: Tipo de sangre | G34: 20000 | H34: 1 | I34: =G34*H34 -> 20000 | L34: =I34/0.6 -> 33333.333 | M34: =J34/0.7 -> 0 | N34: =L34/$H$69 -> 9.009009
C35: OK | D35: OK | E35: Frotis de sangre periférica - (extendido de sangre periférica estudio de morfología) | G35: 45000 | H35: 1 | I35: =G35*H35 -> 45000 | L35: =I35/0.6 -> 75000 | M35: =J35/0.7 -> 0 | N35: =L35/$H$69 -> 20.27027
C36: OK | D36: OK | E36: Test de sicklemia: (Células Falciformes-drepanocitosis) | G36: 40000 | H36: 1 | I36: =G36*H36 -> 40000 | L36: =I36/0.6 -> 66666.667 | M36: =J36/0.7 -> 0 | N36: =L36/$H$69 -> 18.018018
E37: Perfil Tiroideo | M37: =J37/0.7 -> 0
C38: OK | D38: OK | E38: T4 libre | M38: =J38/0.7 -> 0
C39: OK | D39: OK | E39: TSH | M39: =J39/0.7 -> 0
C40: OK | D40: OK | E40: Paratohormona | G40: 116000 | H40: 1 | I40: =G40*H40 -> 116000 | L40: =I40/0.8 -> 145000 | M40: =J40/0.7 -> 0 | N40: =L40/$H$69 -> 39.189189
E41: Enfermedades de transmisión sexual | M41: =J41/0.7 -> 0
...

Sheet CONFIRMACIÓN DE SERVICIOS 
J1: IPS ELECTRODIAGNOSTICOS-ELECTROMIOGRAFIA MIEMBROS INFERIORES
B4: RESONANCIA DE COLUMNA SIMPLE
J21: IPS ELECTRODIAGNOSTICOS-CONSULTA CON FISIATRIA
A36: CONFIRMACIÓN CONSULTA CON ORTOPEDIA
I40: CONFIRMACIÓN CONSULTA CON UROLOGIA
I56: CONFIRMACIÓN CONSULTA CON CARDIOLOGIA

Sheet VUELO
J6: SILLA DE RUEDAS
J7: 60FMVG
J12: 15NOV CUR-MDE//
J13: 22 NOV MDE-CUR 5:07 PM

Sheet DETALLE SERVICIOS
C3: DETALLE DE LOS SERVICIOS
C4: =COSTEO!E4 -> #REF! | D4: =COSTEO!N4 -> #REF! | E4: =COSTEO!O4 -> #REF! | F4: =COSTEO!P4 -> #REF!
C5: ='21102025 COSTEO'!E5 -> Póliza de asistencia médica al viajero - producto visitor | D5: ='21102025 COSTEO'!N5 -> 8.1081081 | E5: ='21102025 COSTEO'!O5 -> 8.1081081 | F5: =COSTEO!P5 -> #REF!
C6: ='21102025 COSTEO'!E6 -> Sim card física | D6: ='21102025 COSTEO'!N6 -> 2.7027027 | E6: ='21102025 COSTEO'!O6 | F6: =COSTEO!P6 -> #REF!
C7: ='21102025 COSTEO'!E7 -> Recarga de datos de 10 GB | D7: ='21102025 COSTEO'!N7 -> 5.4054054 | E7: ='21102025 COSTEO'!O7 | F7: =COSTEO!P7 -> #REF!
C8: ='21102025 COSTEO'!E8 -> Traslado aeropuerto - hotel - aeropuerto | D8: ='21102025 COSTEO'!N8 -> 41.223041 | E8: ='21102025 COSTEO'!O8 -> 41.223041 | F8: =COSTEO!P8 -> #REF!
C9: ='21102025 COSTEO'!E9 -> PAQUETE DE CHEQUEO MÉDICO | D9: ='21102025 COSTEO'!N9 -> 470 | E9: ='21102025 COSTEO'!O9 | F9: =COSTEO!P9 -> #REF!
C10: ='21102025 COSTEO'!E10 -> LABORATORIOS CLÍNICOS | D10: ='21102025 COSTEO'!N10 | E10: ='21102025 COSTEO'!O10 | F10: =COSTEO!P10 -> #REF!
C11: ='21102025 COSTEO'!E11 -> Antígeno de próstata | D11: ='21102025 COSTEO'!N11 | E11: ='21102025 COSTEO'!O11 | F11: =COSTEO!P11 -> #REF!
C12: ='21102025 COSTEO'!E12 -> Coprológico | D12: ='21102025 COSTEO'!N12 | E12: ='21102025 COSTEO'!O12 | F12: =COSTEO!P12 -> #REF!
C13: ='21102025 COSTEO'!E13 -> Vitamina D25 | D13: ='21102025 COSTEO'!N13 | E13: ='21102025 COSTEO'!O13 | F13: =COSTEO!P13 -> #REF!
C14: ='21102025 COSTEO'!E14 -> Vitamina B12 | D14: ='21102025 COSTEO'!N14 | E14: ='21102025 COSTEO'!O14 | F14: =COSTEO!P14 -> #REF!
C15: ='21102025 COSTEO'!E15 -> Perfil lipídico | D15: ='21102025 COSTEO'!N15 | E15: ='21102025 COSTEO'!O15 | F15: =COSTEO!P15 -> #REF!
C16: ='21102025 COSTEO'!E16 -> Colesterol HDL | D16: ='21102025 COSTEO'!N16 | E16: ='21102025 COSTEO'!O16 | F16: =COSTEO!P16 -> #REF!
... C63: ='21102025 COSTEO'!E63 -> Servicios Medical Trip Colombia: Acompañamiento Virtual | D63: ='21102025 COSTEO'!N63 -> 25.604552 | E63: ='21102025 COSTEO'!O63 | F63: =COSTEO!P63 -> #REF!
C64: ='21102025 COSTEO'!E64 -> Servicios Medical Trip Colombia: Acompañamiento presencial | D64: ='21102025 COSTEO'!N64 -> 30.725462
C65: Impuesto bancario 4 * 1000 | D65: ='21102025 COSTEO'!N68 -> 6.2351026 | E65: ='21102025 COSTEO'!O68 -> 0.19994188 | F65: =COSTEO!P67 -> #REF!
C66: TOTAL A PAGAR EN DÓLARES | D66: =SUM(D5:D65) -> 1564.2868 | E66: =SUM(E5:E65) -> 49.531091
C67: =COSTEO!E69 -> #REF!
C68: =COSTEO!E70 -> #REF!
C69: =COSTEO!E71 -> #REF!
C70: =COSTEO!E72 -> #REF!
C71: =COSTEO!E73 -> #REF! | D71: =COSTEO!N73 -> #REF! | E71: =COSTEO!O73 -> #REF! | F71: =COSTEO!P73 -> #REF!
C72: =COSTEO!E74 -> #REF! | D72: =COSTEO!N74 -> #REF! | E72: =COSTEO!O74 -> #REF! | F72: =COSTEO!P74 -> #REF!
C73: =COSTEO!E75 -> #REF! | D73: =COSTEO!N75 -> #REF! | E73: =COSTEO!O75 -> #REF! | F73: =COSTEO!P75 -> #REF!
C74: =COSTEO!E76 -> #REF! | D74: =COSTEO!N76 -> #REF! | E74: =COSTEO!O76 -> #REF! | F74: =COSTEO!P76 -> #REF!
C75: =COSTEO!E77 -> #REF! | D75: =COSTEO!N77 -> #REF! | E75: =COSTEO!O77 -> #REF! | F75: =COSTEO!P77 -> #REF!
C76: =COSTEO!E78 -> #REF! | D76: =COSTEO!N78 -> #REF! | E76: =COSTEO!O78 -> #REF! | F76: =COSTEO!P78 -> #REF!
C77: =COSTEO!E79 -> #REF! | D77: =COSTEO!N79 -> #REF! | E77: =COSTEO!O79 -> #REF! | F77: =COSTEO!P79 -> #REF!
C78: =COSTEO!E80 -> #REF! | D78: =COSTEO!N80 -> #REF! | E78: =COSTEO!O80 -> #REF! | F78: =COSTEO!P80 -> #REF!
C79: =COSTEO!E81 -> #REF! | D79: =COSTEO!N81 -> #REF! | E79: =COSTEO!O81 -> #REF! | F79: =COSTEO!P81 -> #REF!
C80: =COSTEO!E82 -> #REF! | D80: =COSTEO!N82 -> #REF! | E80: =COSTEO!O82 -> #REF! | F80: =COSTEO!P82 -> #REF!
C81: =COSTEO!E83 -> #REF! | D81: =COSTEO!N83 -> #REF! | E81: =COSTEO!O83 -> #REF! | F81: =COSTEO!P83 -> #REF!
C82: =COSTEO!E84 -> #REF! | D82: =COSTEO!N84 -> #REF! | E82: =COSTEO!O84 -> #REF! | F82: =COSTEO!P84 -> #REF!
... C99: =COSTEO!E101 -> #REF! | D99: =COSTEO!N101 -> #REF! | E99: =COSTEO!O101 -> #REF! | F99: =COSTEO!P101 -> #REF!
C100: =COSTEO!E102 -> #REF!
C101: =COSTEO!E103 -> #REF!
C102: =COSTEO!E104 -> #REF!
C103: =COSTEO!E105 -> #REF!
C104: =COSTEO!E106 -> #REF!
...
