Workbook

Sheet Pasaporte - HC
A18: Nombre | B18: Suvienne
A19: Nombre
A20: Apellido | B20: Rosa Lourens
A21: Apellido de casada
A22: Género: . | B22: Femenino
A23: Pasaporte
A24: Fecha de nacimiento | B24: 05 de septiembre 1986
A25: Edad | B25: =2025-1986 -> 39
A26: Estado civil
A27: Dirección
A28: Nacionalidad y domicilio:
A29: Email: | B29: 0
A30: Teléfono
A31: Profesión
A32: RH
A33: Seguro | B33: SVB
A34: Peso
A35: Altura
A36: Idioma | B36: Español, ingles, papiamento, holandes
A37: Estadia: | B37: 21 al 26 de Diciembre

Sheet ITINERARIO
C3: ITINERARIO SUGERIDO: | G3: 21 - 26 DICIEMBRE - 06 DÍAS - 05 NOCHES
G4: 04 PERSONAS: 02 ADULTOS + 02 NIÑOS 12 - 15 AÑOS | H4: ACP horas | I4: Traslados cerca | J4: UBER
F5: 46012 | G5: DOMINGO
C6: Directo PAX | D6: AVIANCA | F6: 02:45 pm | G6: Vuelo Curazao - Medellín
B7: Aeroturex | F7: 03:00 pm | G7: Traslado a aeropuerto - hotel
F8: 04:00 pm | G8: Alojamiento
F9: 46013 | G9: LUNES
G10: NO desayunar - Tomar agua
C11: Yenny | F11: 05:30 am | G11: Traslado Hotel - Centro médico | H11: 0.5 | I11: 1
C12: Cima | E12: 4 pax | G12: Ecografía de abdomen total
C13: Cima | E13: Suvienne | G13: Ecografía de mamas
C14: Cima | E14: 4 pax | G14: Toma de muestras de sangre para laboratorios clínicos
E15: 4 pax | G15: Tiempo para comer
C16: Cima | E16: Suvienne | G16: Citología Cervical
C17: Cima | E17: Suvienne y esposo | G17: Radiografía de tórax
C18: Cima | E18: 4 pax | G18: Electrocardiograma
C19: Yenny | F19: 09:30 am | G19: Traslado Centro médico - Hotel | I19: 1
G20: Desayuno en el hotel
G21: Tiempo para almorzar
C22: Uber | F22: 02:00 pm | G22: Traslado en Uber Hotel - parque del poblado punto de encuentro tour | J22: 1
C23: Aeroturex | E23: 4 pax | F23: 02:30 pm | G23: Tour compartido a la COMUNA TRECE
C24: Uber | F24: 06:00 pm | G24: Traslado en Uber - Parque del poblado - Hotel | J24: 1
F25: 46014 | G25: MARTES
G26: Desayuno en el hotel
F27: 07:30 am | G27: Traslado Hotel - Centro médico | H27: 1 | I27: 1
E28: Esposo e hijo de 12 años | F28: 08:00 am | G28: Consulta con especialista en OFTALMOLOGÍA
E29: Suvienne y hijo 15 años | F29: 09:00 am | G29: Consulta con especialista en GLAUCOMATOLOGO
E30: Suvienne y hijo 15 años | G30: OCT tomografía en caso de ser ordenada por el Glaucomatologo
F31: 10:00 am | G31: Traslado centro médico - centro médico | I31: 1
E32: 4 pax | F32: 10:30 am | G32: Radiografía panorámica dental
E33: Suvienne y esposo | F33: 11:00 am | G33: Consulta con especialista en Medicina Interna
G34: Tiempo para almorzar
E35: 4 pax | F35: 02:00 pm | G35: Consulta con especialista en Odontología
E36: Hijos 12 y 15 años | F36: 04:00 pm | G36: Consulta con especialista en Pediatría
G37: Traslado Centro médico - Hotel | I37: 1
G38: Tiempo para cenar
F39: 05:30 pm | G39: Traslado en Uber Hotel - parque del poblado punto de encuentro tour | J39: 1
F40: 06:00 pm | G40: TOUR DE LUCES por Medellín
F41: 09:00 pm | G41: Traslado en Uber - Parque del poblado - Hotel | J41: 1
F42: 46015 | G42: MIÉRCOLES
...

Sheet COSTEO
AA2: Libro diario contable
C3: PAGOS | O3: 3800 | T3: PAGOS | X3: ESTADO DE CUENTA | AA3: PAGOS
B4: ACV documentos | C4: Contabilidad | D4: Operativo | E4: Concepto | F4: Proveedor | G4: Valor | H4: Días | I4: Suvienne | J4: Esposo | K4: Niño 12 años | L4: Niño 15 años | N4: Comisionable | O4: Suvienne | P4: Esposo | Q4: Niño 12 años | R4: Niño 15 años | U4: RTE FUENTE | V4: Valor pagado | X4: Valor Neto cobrado al cliente | Y4: DIFERENCIA | AA4: PROVEEDOR - NOMBRE COMERCIAL | AB4: ID | AC4: Fecha del pago | AD4: Valor del pago | AE4: Forma de pago de donde salió el dinero | AF4: Tipo de movimiento | AG4: Comentarios
E5: Póliza de asistencia médica al viajero - producto visitor por 04 días adicionales | F5: COLASISTENCIA | G5: 3500 | H5: 4 | I5: =G5*H5 -> 14000 | J5: =G5*H5 -> 14000 | K5: =G5*H5 -> 14000 | L5: =G5*H5 -> 14000 | N5: =I5/0.6 -> 23333.333 | O5: =N5/$O$3 -> 6.1403509 | P5: =N5/$O$3 -> 6.1403509 | Q5: =N5/$O$3 -> 6.1403509 | R5: =N5/$O$3 -> 6.1403509
E6: Sim card física | F6: CLARO | G6: 6000 | H6: 1 | I6: =G6*H6 -> 6000 | N6: =I6/0.6 -> 10000 | O6: =N6/3913 -> 2.555584
E7: Datos 10 Gigas | F7: CLARO | G7: 12000 | H7: 1 | I7: =G7*H7 -> 12000 | N7: =I7/0.6 -> 20000 | O7: =N7/3913 -> 5.1111679
E8: Traslado aeropuerto - hotel - aeropuerto en MINIVAN | F8: TAXI VAN | G8: 250000 | H8: 2 | I8: =G8*H8 -> 500000 | N8: =I8/0.9 -> 555555.56 | O8: =N8/$H$73 -> 146.19883
E9: Recargo por trayecto a la madrugada de regreso | F9: TAXI VAN | G9: 25000 | H9: 1 | I9: =G9*H9 -> 25000 | N9: =I9/0.9 -> 27777.778 | O9: =N9/$H$73 -> 7.3099415
E10: CITY TOUR compartido grupal | F10: AEROTUREX | G10: 71500 | H10: 1 | I10: =G10*H10 -> 71500 | J10: =G10*H10 -> 71500 | K10: =G10*H10 -> 71500 | L10: =G10*H10 -> 71500 | N10: =I10/0.85 -> 84117.647 | O10: =N10/$H$73 -> 22.136223 | P10: =N10/$O$3 -> 22.136223 | Q10: =N10/$O$3 -> 22.136223 | R10: =N10/$O$3 -> 22.136223
E11: GUATAPÉ tour grupal | F11: AEROTUREX | G11: 140000 | H11: 1 | I11: =G11*H11 -> 140000 | J11: =G11*H11 -> 140000 | K11: =G11*H11 -> 140000 | L11: =G11*H11 -> 140000 | N11: =I11/0.85 -> 164705.88 | O11: =N11/$H$73 -> 43.343653 | P11: =N11/$O$3 -> 43.343653 | Q11: =N11/$O$3 -> 43.343653 | R11: =N11/$O$3 -> 43.343653
E12: TOUR DE LUCES por Medellín | F12: AEROTUREX | G12: 130000 | H12: 1 | I12: =G12*H12 -> 130000 | J12: =G12*H12 -> 130000 | K12: =G12*H12 -> 130000 | L12: =G12*H12 -> 130000 | N12: =I12/0.9 -> 144444.44 | O12: =N12/$H$73 -> 38.011696 | P12: =N12/$O$3 -> 38.011696 | Q12: =N12/$O$3 -> 38.011696 | R12: =N12/$O$3 -> 38.011696
E13: 08 traslados en Uber Hotel - punto de encuentro - hotel | F13: UBER | G13: 20000 | H13: 8 | I13: =G13*H13 -> 160000 | N13: =I13/0.8 -> 200000 | O13: =N13/$H$73 -> 52.631579
E14: PAQUETE DE CHEQUEO MÉDICO | I14: 1350000 | J14: 1300000 | K14: 1100000 | L14: 1100000 | O14: 485 | P14: 470 | Q14: 430 | R14: 430
E15: Citología cervical | F15: CIMA | J15: No | K15: No | L15: No | P15: No | Q15: No | R15: No
E16: Antígeno de próstata | F16: CIMA | I16: No | K16: No | L16: No | O16: No | Q16: No | R16: No
E17: Coprológico | F17: CIMA
E18: Vitamina D25 | F18: CIMA
E19: Vitamina B12 | F19: CIMA
E20: Perfil lipídico
E21: Colesterol HDL | F21: CIMA
E22: Colesterol LDL | F22: CIMA
E23: Colesterol total | F23: CIMA
E24: Triglicéridos | F24: CIMA
E25: Perfil Hepático
E26: ALT- Alanina transferasa | F26: CIMA
E27: AST - aspartato transferasa | F27: CIMA
E28: Bilirrubina total y directa | F28: CIMA | K28: No | L28: No | Q28: No | R28: No
E29: Gama Glutamil transferasa | F29: CIMA | K29: No | L29: No | Q29: No | R29: No
E30: Perfil Renal
E31: Creatinina | F31: CIMA
E32: Uroanálisis | F32: CIMA
E33: Nitrógeno Ureico en Sangre (BUN) | F33: CIMA | K33: No | L33: No | Q33: No | R33: No
E34: Sangre
E35: Hemograma completo | F35: CIMA
E36: Hemoglobina glicosilada | F36: CIMA
E37: Ferritina | F37: CIMA
E38: Glucosa sérica | F38: CIMA
E39: Perfil Tiroideo
E40: T4 total | F40: CIMA
E41: TSH | F41: CIMA
...

Sheet DETALLE DE LOS SERVICIOS
B2: DETALLE DE LOS SERVICIOS
B3: =COSTEO!E4 -> Concepto | C3: =COSTEO!O4 -> Suvienne | D3: =COSTEO!P4 -> Esposo | E3: =COSTEO!Q4 -> Niño 12 años | F3: =COSTEO!R4 -> Niño 15 años
B4: =COSTEO!E5 -> Póliza de asistencia médica al viajero - producto visitor por 04 días adicionales | C4: =COSTEO!O5 -> 6.1403509 | D4: =COSTEO!P5 -> 6.1403509 | E4: =COSTEO!Q5 -> 6.1403509 | F4: =COSTEO!R5 -> 6.1403509
B5: =COSTEO!E6 -> Sim card física | C5: =COSTEO!O6 -> 2.555584 | D5: =COSTEO!P6 | E5: =COSTEO!Q6 | F5: =COSTEO!R6
B6: =COSTEO!E7 -> Datos 10 Gigas | C6: =COSTEO!O7 -> 5.1111679
B7: =COSTEO!E8 -> Traslado aeropuerto - hotel - aeropuerto en MINIVAN | C7: =COSTEO!O8 -> 146.19883 | D7: =COSTEO!P8 | E7: =COSTEO!Q8 | F7: =COSTEO!R8
B8: =COSTEO!E9 -> Recargo por trayecto a la madrugada de regreso | C8: =COSTEO!O9 -> 7.3099415 | D8: =COSTEO!P9 | E8: =COSTEO!Q9 | F8: =COSTEO!R9
B9: =COSTEO!E10 -> CITY TOUR compartido grupal | C9: =COSTEO!O10 -> 22.136223 | D9: =COSTEO!P10 -> 22.136223 | E9: =COSTEO!Q10 -> 22.136223 | F9: =COSTEO!R10 -> 22.136223
B10: =COSTEO!E11 -> GUATAPÉ tour grupal | C10: =COSTEO!O11 -> 43.343653 | D10: =COSTEO!P11 -> 43.343653 | E10: =COSTEO!Q11 -> 43.343653 | F10: =COSTEO!R11 -> 43.343653
B11: =COSTEO!E12 -> TOUR DE LUCES por Medellín | C11: =COSTEO!O12 -> 38.011696 | D11: =COSTEO!P12 -> 38.011696 | E11: =COSTEO!Q12 -> 38.011696 | F11: =COSTEO!R12 -> 38.011696
B12: =COSTEO!E13 -> 08 traslados en Uber Hotel - punto de encuentro - hotel | C12: =COSTEO!O13 -> 52.631579 | D12: =COSTEO!P13 | E12: =COSTEO!Q13 | F12: =COSTEO!R13
B13: =COSTEO!E14 -> PAQUETE DE CHEQUEO MÉDICO | C13: =COSTEO!O14 -> 485 | D13: =COSTEO!P14 -> 470 | E13: =COSTEO!Q14 -> 430 | F13: =COSTEO!R14 -> 430
B14: =COSTEO!E15 -> Citología cervical | C14: =COSTEO!O15 | D14: =COSTEO!P15 -> No | E14: =COSTEO!Q15 -> No | F14: =COSTEO!R15 -> No
B15: =COSTEO!E16 -> Antígeno de próstata | C15: =COSTEO!O16 -> No | D15: =COSTEO!P16 | E15: =COSTEO!Q16 -> No | F15: =COSTEO!R16 -> No
B16: =COSTEO!E17 -> Coprológico | C16: =COSTEO!O17 | D16: =COSTEO!P17 | E16: =COSTEO!Q17 | F16: =COSTEO!R17
B17: =COSTEO!E18 -> Vitamina D25 | C17: =COSTEO!O18 | D17: =COSTEO!P18 | E17: =COSTEO!Q18 | F17: =COSTEO!R18
B18: =COSTEO!E19 -> Vitamina B12 | C18: =COSTEO!O19 | D18: =COSTEO!P19 | E18: =COSTEO!Q19 | F18: =COSTEO!R19
... B67: =COSTEO!E68 -> Medical Trip Servicios de acompañamiento y logística | C67: =COSTEO!O68 -> 26.315789 | D67: =COSTEO!P68 -> 26.315789 | E67: =COSTEO!Q68 | F67: =COSTEO!R68
B68: Impuesto bancario en Colombia 4 * 1000 | C68: =COSTEO!O72 -> 4.6967077 | D68: =COSTEO!P72 -> 3.4895003 | E68: =COSTEO!Q72 -> 2.9330547 | F68: =COSTEO!R72 -> 2.473822
B69: TOTAL A PAGAR EN DÓLARES | C69: =SUM(C4:C68) -> 1179.1242 | D69: =SUM(D4:D68) -> 876.35967 | E69: =SUM(E4:E68) -> 736.06343 | F69: =SUM(F4:F68) -> 621.05311
B70: =COSTEO!E71
B71: =COSTEO!E72
B72: =COSTEO!E73
B73: =COSTEO!E74
B74: =COSTEO!E75 | C74: =COSTEO!O75 | D74: =COSTEO!P75 | E74: =COSTEO!Q75 | F74: =COSTEO!R75
B75: =COSTEO!E76 | C75: =COSTEO!O76 | D75: =COSTEO!P76 | E75: =COSTEO!Q76 | F75: =COSTEO!R76
B76: =COSTEO!E77 | C76: =COSTEO!O77 | D76: =COSTEO!P77 | E76: =COSTEO!Q77 | F76: =COSTEO!R77
B77: =COSTEO!E78 | C77: =COSTEO!O78 | D77: =COSTEO!P78 | E77: =COSTEO!Q78 | F77: =COSTEO!R78
B78: =COSTEO!E79 | C78: =COSTEO!O79 | D78: =COSTEO!P79 | E78: =COSTEO!Q79 | F78: =COSTEO!R79
B79: =COSTEO!E80 | C79: =COSTEO!O80 | D79: =COSTEO!P80 | E79: =COSTEO!Q80 | F79: =COSTEO!R80
B80: =COSTEO!E81 | C80: =COSTEO!O81 | D80: =COSTEO!P81 | E80: =COSTEO!Q81 | F80: =COSTEO!R81
B81: =COSTEO!E82 | C81: =COSTEO!O82 | D81: =COSTEO!P82 | E81: =COSTEO!Q82 | F81: =COSTEO!R82
B82: =COSTEO!E83 | C82: =COSTEO!O83 | D82: =COSTEO!P83 | E82: =COSTEO!Q83 | F82: =COSTEO!R83
B83: =COSTEO!E84 | C83: =COSTEO!O84 | D83: =COSTEO!P84 | E83: =COSTEO!Q84 | F83: =COSTEO!R84
C84: =COSTEO!O85 | D84: =COSTEO!P85 | E84: =COSTEO!Q85 | F84: =COSTEO!R85
C85: =COSTEO!O86 | D85: =COSTEO!P86 | E85: =COSTEO!Q86 | F85: =COSTEO!R86
C86: =COSTEO!O87 | D86: =COSTEO!P87 | E86: =COSTEO!Q87 | F86: =COSTEO!R87
C87: =COSTEO!O88 | D87: =COSTEO!P88 | E87: =COSTEO!Q88 | F87: =COSTEO!R88
C88: =COSTEO!O89 | D88: =COSTEO!P89 | E88: =COSTEO!Q89 | F88: =COSTEO!R89
C89: =COSTEO!O90 | D89: =COSTEO!P90 | E89: =COSTEO!Q90 | F89: =COSTEO!R90
...

Sheet VUELO
