Workbook

Sheet Pasaporte - HC
H1: Nombre | I1: Mahalia
H2: Nombre
H3: Apellido | I3: Henson
H4: Apellido de casada
H5: Género: . | I5: Femenino
H6: Pasaporte | I6: NYB4C1960
H7: Fecha de nacimiento | I7: 26647
H8: Edad | I8: 53 años
H9: Estado civil
H10: Dirección | I10: Guana weg 14, Buena vista
H11: Nacionalidad y domicilio: | I11: Curazao, Países bajos
H12: Email: | I12: hailahenson@gmail.com
H13: Teléfono | I13: =59995177466 -> 59995177466
H14: Profesión | I14: Contabilidad
H15: RH
H16: Seguro | I16: SVB
H17: Peso | I17: 75kg
H18: Altura | I18: 1.60 m
H19: Idioma | I19: Papiamento, Holandes, inglés y Español
H21: Salud
H22: Estadia | I22: 04 de octubre
H27: Nombre | I27: Shaimarie Eufemia
H28: Nombre
H29: Apellido | I29: Job
H30: Apellido de casada
H31: Género: . | I31: Femenino
H32: Pasaporte | I32: NP63RD418
H33: Fecha de nacimiento | I33: 32705
H34: Edad | I34: 36 años
H35: Estado civil
H36: Dirección | I36: Steenen koraal 105
H37: Nacionalidad y domicilio: | I37: Willemstad, Curazao
H38: Email: | I38: shaimarieshai8907@gmail.com
H39: Teléfono | I39: =59995177466 -> 59995177466
H40: Profesión | I40: Contable
H41: RH | I41: O+
H42: Seguro | I42: SVB
H43: Peso | I43: 82,7 kg
H44: Altura | I44: 1.61 M
H45: Idioma | I45: Inglés, español, neerlandés, papiamento
...

Sheet DETALLE DE SERVICIOS
C3: DETALLE DE LOS SERVICIOS
C4: Concepto | D4: Mahaila | E4: Shaimarie
B5: =COSTEO!D5 -> M - S | C5: =COSTEO!E5 -> Póliza de asistencia médica al viajero - producto visitor por 06 días | D5: =COSTEO!M5 -> 9.2105263 | E5: =COSTEO!N5 -> 9.2105263
B6: =COSTEO!D6 -> M - S | C6: =COSTEO!E6 -> Sim card física | D6: =COSTEO!M6 -> 2.6315789 | E6: =COSTEO!N6 -> 2.6315789
B7: =COSTEO!D7 -> M - S | C7: =COSTEO!E7 -> Recarga 10 gigas de datos | D7: =COSTEO!M7 -> 4.2105263 | E7: =COSTEO!N7 -> 4.2105263
B8: =COSTEO!D8 -> M - S | C8: =COSTEO!E8 -> Traslado aeropuerto - hotel - aeropuerto en CARRO | D8: =COSTEO!M8 -> 40.138224 | E8: =COSTEO!N8 -> 40.138224
B9: =COSTEO!D9 | C9: =COSTEO!E9 -> Paquete de chequeo médico | D9: =COSTEO!M9 -> 485 | E9: =COSTEO!N9 -> 485
B10: =COSTEO!D10 -> M - S | C10: =COSTEO!E10 -> Citología cervical | D10: =COSTEO!M10 | E10: =COSTEO!N10
B11: =COSTEO!D11 -> M - S | C11: =COSTEO!E11 -> Domicilio | D11: =COSTEO!M11 | E11: =COSTEO!N11
B12: =COSTEO!D12 -> M - S | C12: =COSTEO!E12 -> Coprológico | D12: =COSTEO!M12 | E12: =COSTEO!N12
B13: =COSTEO!D13 -> M - S | C13: =COSTEO!E13 -> Vitamina D25 | D13: =COSTEO!M13 | E13: =COSTEO!N13
B14: =COSTEO!D14 -> M - S | C14: =COSTEO!E14 -> Vitamina B12 | D14: =COSTEO!M14 | E14: =COSTEO!N14
B15: =COSTEO!D15 -> M - S | C15: =COSTEO!E15 -> Perfil lipídico | D15: =COSTEO!M15 | E15: =COSTEO!N15
B16: =COSTEO!D16 -> M - S | C16: =COSTEO!E16 -> Colesterol HDL | D16: =COSTEO!M16 | E16: =COSTEO!N16
... B76: =COSTEO!D76 -> S | C76: =COSTEO!E76 -> Tomografía de tórax | D76: =COSTEO!M76 | E76: =COSTEO!N76 -> 77.192982
B77: =COSTEO!D79 | C77: =COSTEO!E79 -> ORDEN ESPECIALISTAS | D77: =COSTEO!M79 | E77: =COSTEO!N79
B78: =COSTEO!D80 -> M | C78: =COSTEO!E80 -> Consulta con especialista en REUMATOLOGÍA | D78: =COSTEO!M80 -> 82.236842 | E78: =COSTEO!N80
B79: =COSTEO!D81 -> S | C79: =COSTEO!E81 -> Consulta con especialista en NEUMOLOGÍA | D79: =COSTEO!M81 | E79: =COSTEO!N81 -> 82.236842
B80: =COSTEO!D82 -> S | C80: =COSTEO!E82 -> Consulta con especialista en ALERGÓLOGO | D80: =COSTEO!M82 | E80: =COSTEO!N82 -> 82.236842
B81: =COSTEO!D83 -> S | C81: =COSTEO!E83 -> Consulta con especialista en ODONTOLOGÍA | D81: =COSTEO!M83 | E81: =COSTEO!N83 -> 0
B82: =COSTEO!D84 -> S | C82: =COSTEO!E84 -> Consulta con especialista en GINECOLOGÍA - Incluye ecografía transvaginal | D82: =COSTEO!M84 | E82: =COSTEO!N84 -> 102.33918
B83: =COSTEO!D85 -> M - S | C83: =COSTEO!E85 -> 05 Traslados hotel - clínica por trayecto | D83: =COSTEO!M85 -> 32.894737 | E83: =COSTEO!N85 -> 32.894737
B84: =COSTEO!D86 -> M - S | C84: =COSTEO!E86 -> Medical Trip Colombia SAS - Acompañamiento virtual | D84: =COSTEO!M86 -> 34.626039 | E84: =COSTEO!N86 -> 34.626039
B85: =COSTEO!D87 -> M - S | C85: =COSTEO!E87 -> Acompañamiento presencial en español para citas y exámenes | D85: =COSTEO!M87 -> 79.778393 | E85: =COSTEO!N87 -> 79.778393
B86: M - S | C86: Impuesto bancario 4 * 1000 | D86: =COSTEO!M91 -> 5.2343391 | E86: =COSTEO!N91 -> 6.195545
C87: TOTAL A PAGAR | D87: =SUM(D5:D86) -> 1313.6577 | E87: =SUM(E5:E86) -> 1554.7843

Sheet COSTEO
X2: Libro diario contable
C3: PAGOS | M3: 3800 | P3: PAGOS | U3: ESTADO DE CUENTA | X3: PAGOS
B4: ACV documentos | C4: Contabilidad | D4: Operativo | E4: Concepto | F4: Proveedor | G4: Valor | H4: Días | I4: Mahaila | J4: Shaimarie | L4: Comisionable | M4: Mahaila | N4: Shaimarie | P4: Mahaila | Q4: Shaimarie | R4: RTE FUENTE | S4: Valor pagado | U4: Valor Neto cobrado al cliente | V4: DIFERENCIA | X4: PROVEEDOR - NOMBRE COMERCIAL | Y4: ID | Z4: Fecha del pago | AA4: Valor del pago | AB4: Forma de pago de donde salió el dinero | AC4: Tipo de movimiento | AD4: Comentarios | AF4: Valor del pago | AG4: Forma de pago de donde salió el dinero | AH4: Tipo de movimiento | AI4: Comentarios
D5: M - S | E5: Póliza de asistencia médica al viajero - producto visitor por 06 días | F5: Colasistencia | G5: 3500 | H5: 6 | I5: =G5*H5 -> 21000 | J5: =G5*H5 -> 21000 | L5: =I5/0.6 -> 35000 | M5: =L5/$M$3 -> 9.2105263 | N5: =L5/$M$3 -> 9.2105263
D6: M - S | E6: Sim card física | F6: Claro | G6: 6000 | H6: 1 | I6: =G6*H6 -> 6000 | J6: =G6*H6 -> 6000 | L6: =I6/0.6 -> 10000 | M6: =L6/$M$3 -> 2.6315789 | N6: =L6/$M$3 -> 2.6315789
D7: M - S | E7: Recarga 10 gigas de datos | F7: Claro | G7: 12000 | H7: 1 | I7: =G7*H7 -> 12000 | J7: =G7*H7 -> 12000 | L7: =I7/0.75 -> 16000 | M7: =L7/$M$3 -> 4.2105263 | N7: =L7/$M$3 -> 4.2105263
D8: M - S | E8: Traslado aeropuerto - hotel - aeropuerto en CARRO | F8: Aeroturex | G8: 151000 | H8: 2 | I8: =G8*H8/2 -> 151000 | J8: =H8*I8/2 -> 151000 | L8: =I8/0.99 -> 152525.25 | M8: =L8/$H$93 -> 40.138224 | N8: =L8/$M$3 -> 40.138224
E9: Paquete de chequeo médico | H9: 0 | I9: 1350000 | J9: 1350000 | M9: 485 | N9: 485
D10: M - S | E10: Citología cervical | F10: CIMA
D11: M - S | E11: Domicilio | F11: Echavarria
D12: M - S | E12: Coprológico | F12: Echavarria
D13: M - S | E13: Vitamina D25 | F13: Echavarria
D14: M - S | E14: Vitamina B12 | F14: Echavarria
D15: M - S | E15: Perfil lipídico
D16: M - S | E16: Colesterol HDL | F16: Echavarria
D17: M - S | E17: Colesterol LDL | F17: Echavarria
D18: M - S | E18: Colesterol total | F18: Echavarria
D19: M - S | E19: Triglicéridos | F19: Echavarria
D20: M - S | E20: Perfil Hepático
D21: M - S | E21: ALT- Alanina transferasa | F21: Echavarria
D22: M - S | E22: AST - aspartato transferasa | F22: Echavarria
D23: M - S | E23: Bilirrubina total y directa | F23: Echavarria
D24: M - S | E24: Gama Glutamil transferasa | F24: Echavarria
D25: M - S | E25: Perfil Renal
D26: M - S | E26: Creatinina | F26: Echavarria
D27: M - S | E27: Uroanálisis | F27: Echavarria
D28: M - S | E28: Nitrógeno Ureico en Sangre (BUN) | F28: Echavarria
D29: M - S | E29: Sangre
D30: M - S | E30: Hemograma completo | F30: Echavarria
D31: M - S | E31: Hemoglobina glicosilada | F31: Echavarria | AF31: 1000000 | AG31: JENNY BANCOLOMBIA | AH31: TRANSFERENCIA
D32: M - S | E32: Ferritina | F32: Echavarria
D33: M - S | E33: Glucosa sérica | F33: Echavarria
D34: M - S | E34: Perfil Tiroideo
D35: M - S | E35: T4 total | F35: Echavarria
D36: M - S | E36: TSH | F36: Echavarria | AF36: 540000 | AG36: JENNY BANCOLOMBIA | AH36: TRANSFERENCIA
D37: M - S | E37: Enfermedades de transmisión sexual | AF37: 280000 | AG37: JENNY BANCOLOMBIA | AH37: TRANSFERENCIA
D38: M - S | E38: VDRL | F38: Echavarria
D39: M - S | E39: VIH 1 Y 2, Anticuerpos | F39: Echavarria
D40: M - S | E40: Imágenes diagnósticas
D41: M | E41: Radiografía de tórax | F41: CIMA | P41: 64400
...

Sheet ITINERARIO
C3: ITINERARIO:
C4: Dia | D4: Fecha | E4: Hora | F4: Actividad | G4: ACP horas | H4: Traslado cerca | I4: Traslado lejos
D5: 1 | E5: 45934 | F5: SÁBADO - LLEGADA
F6: Vuelo Curazao - Medellín
F7: Traslado a aeropuerto - hotel
F8: Alojamiento
D9: 2 | E9: 45935 | F9: DOMINGO
F10: DÍA LIBRE
D11: 3 | E11: 45936 | F11: LUNES
F12: No desayunar
B13: Domicilio en el hotel | C13: Echavarría | D13: M - S | E13: 07 - 09 am | F13: Toma de muestras de sangre laboratorio clínico en hotel
F14: Tiempo para desayunar
E15: 10:00 am | F15: Traslado Hotel - Centro médico | G15: 0.7 | H15: 1
B16: Tesoro Torre 2 | C16: Imágenes y especialistas | D16: S | E16: 10:30 am | F16: Radiografía panorámica dental
B17: Tesoro Torre 2 | C17: Alta Estética dental | D17: S | E17: 11:00 am | F17: Cita con especialista en odontología | J17: Blanqueamiento y diseño de sonrisa
F18: Tiempo para almorzar | J18: llamada odontólogo
B19: Tesoro Torre 2 | C19: Univherse | D19: S | E19: 02:00 pm | F19: Cita con especialista en Ginecología | J19: Diseño de sonrisa e implantes ya hablaron con alfonso
B20: Tesoro Torre 2 | C20: Univherse | D20: S | F20: Ecografía transvaginal
E21: 03:00 pm | F21: Traslado Centro médico - Hotel | H21: 1
D22: 4 | E22: 45937 | F22: MARTES
F23: No desayunar
E24: 05:45 am | F24: Traslado Hotel - Centro médico | G24: 1 | H24: 1
B25: Ciudad del rio | C25: CIMA | D25: M - S | E25: 06:00 am | F25: Ecografía de abdomen total
B26: Ciudad del rio | C26: CIMA | D26: S | F26: Ecografía de mama
B27: Ciudad del rio | C27: CIMA | D27: M - S | E27: 06:30 am | F27: Citología cervical
B28: Ciudad del rio | C28: CIMA | D28: M - S | F28: Citología Papanicolaou
B29: Ciudad del rio | C29: CIMA | D29: M | E29: 07:00 am | F29: Mamografía
B30: Ciudad del rio | C30: CIMA | D30: M | F30: Radiografía de tórax
B31: Ciudad del rio | C31: CIMA | D31: M | E31: 08:00 am | F31: Espirometría
B32: Ciudad del rio | C32: CIMA | D32: M - S | E32: 08:30 am | F32: Electrocardiograma
B33: Ciudad del rio | C33: CIMA | D33: M | F33: Ecocardiografía
B34: Ciudad del rio | C34: CIMA | D34: M | F34: Prueba de esfuerzo
E35: 10:00 am | F35: Tiempo para comer algo ligero
E36: 10:30 am | F36: Traslado Centro médico - centro médico | H36: 1
B37: Punto clave | C37: IVS | D37: S | E37: 11:30 am | F37: Tomografía de tórax
E38: 12:30 pm | F38: Traslado Centro médico - Hotel | H38: 1
F39: TARDE LIBRE
D40: 5 | E40: 45938 | F40: MIÉRCOLES
F41: Desayuno en el hotel
E42: 09:00 am | F42: Traslado Hotel - Centro médico | G42: 1 | I42: 1
...

Sheet HOTEL
N1: APARTAMENTOS ESTELAR
N2: =2872668/8 -> 359083.5 | O2: NETA
C13: X NOCHE | F13: 07 NOCHES
C14: 400000 | D14: 6 | E14: =C14*D14 -> 2400000 | F14: 4-5-6-7-8-9 | G14: =E14/4000 -> 600
C15: 490000 | D15: 2 | E15: =C15*D15 -> 980000 | F15: 11 - 12 | G15: =E15/4000 -> 245
C16: TOTAL COP | E16: =SUM(E14:E15) -> 3380000 | F16: TOTAL USD | G16: =SUM(G14:G15) -> 845 | H16: =G16/8 -> 105.625
F17: CAMBIO $4.000

Sheet Vuelo
