Workbook

Sheet PASAPORTE
E1: Nombre | F1: Elyhaila
E2: Nombre
E3: Apellido | F3: Delando
E4: Apellido de casada
E5: Género: . | F5: Femenino
E6: Pasaporte | F6: NR2CB5R76
E7: Fecha de nacimiento | F7: 05 de junio 1982
E8: Edad | F8: 43 años
E9: Estado civil | F9: casada
E10: Dirección | F10: Loodsduinseweg 37A, 2571AA
E11: Nacionalidad y domicilio: | F11: Paises bajos
E12: Email: | F12: lady_lala22@hotmail.com
E13: Teléfono | F13: 31619422895
E14: Profesión | F14: Enfermera
E15: RH | F15: O+
E16: Seguro | F16: SVB
E17: Peso | F17: 91 KG
E18: Altura | F18: 1,70 m
E19: Idioma | F19: Holandés, español, y poco inglés
E20: Estadia | F20: Posiblemente a comienzos de agosto
E21: Salud

Sheet ITINERARIO
B1: ITINERARIO:
D2: Dia | E2: Hora | F2: Actividad | G2: ACP horas | H2: Traslados cerca | I2: Traslados lejos
D3: 1 | E3: 45878 | F3: SÁBADO
E4: 07:00 pm | F4: Vuelo Curazao - Medellín
E5: 08:00 pm | F5: Traslado a aeropuerto - hotel
E6: 09:00 pm | F6: Alojamiento
D7: 2 | E7: 45879 | F7: DOMINGO
E8: 07:00 am | F8: Desayuno en el hotel
E9: 08:00 am | F9: Traslado hotel - centro médico | G9: 0.5 | H9: 1
C10: IVS | E10: 09:00 am | F10: Tomografía de cabeza
F11: Tomografía de cuello
F12: Tomografía de tórax
E13: 10:00 am | F13: Traslado - Centro médico - Hotel | H13: 1
D14: 3 | E14: 45880 | F14: LUNES
F15: No desayunar
E16: 05:30 am | F16: Traslado hotel - centro médico | G16: 0.75 | H16: 1
E17: 06:00 am | F17: Toma de muestras de sangre laboratorio clínico
E18: 07:00 am | F18: Ecografía de abdomen total
F19: ='01-07-25-COSTEO'!E45 -> Ecografía de tiroides y paratiroides
F20: ='01-07-25-COSTEO'!E34 -> Ecografía de mama
E21: 08:00 am | F21: Tiempo para desayunar
F22: Traslado centro médico - centro médico | H22: 1
D23: Cedimed | E23: 09:00 am | F23: Electrocardiograma
E24: 10:00 am | F24: Cita con especialista en Dermatología
F25: Biopsia de cuero cabelludo
E26: 12:00 pm | F26: Traslado - Centro médico - Hotel | H26: 1
F27: Tiempo para almorzar - tarde libre
D28: 4 | E28: 45881 | F28: MARTES
F29: Desayuno en el hotel
F30: Traslado hotel - centro médico | G30: 0.25 | I30: 1
C31: HPTU | E31: 10:00 am | F31: Consulta con especialista en Medicina Interna
E32: 11:00 am | F32: Consulta con especialista en Reumatología
F33: Traslado centro médico - centro médico | I33: 1
D34: 5 | E34: 45882 | F34: MIÉRCOLES
F35: Desayuno en el hotel
E36: 09:30 am | F36: Traslado hotel - aeropuerto
E37: 01:45 pm | F37: Vuelo internacional Curazao - Medellín
F38: PENDIENTE CITA CONTROL DERMATÓLOGO | G38: =SUM(G3:G37) -> 1.5 | H38: =SUM(H3:H37) -> 5 | I38: =SUM(I3:I37) -> 2

Sheet 08-07-25-COSTEO
Y2: Libro diario contable | AG2: Factura electrónica
C3: PAGOS | Q3: PAGOS | V3: ESTADO DE CUENTA | Y3: PAGOS | AG3: FACTURA
B4: ACV documentos | C4: Contabilidad | D4: Operativo | E4: Concepto | F4: Proveedor | G4: Valor | H4: Días | L4: Comisionable | S4: Retención en la fuente | T4: Valor pagado | V4: Valor Neto cobrado al cliente | W4: DIFERENCIA | Y4: PROVEEDOR - NOMBRE COMERCIAL | Z4: ID | AA4: Fecha del pago | AB4: Valor del pago | AC4: Forma de pago de donde salió el dinero | AD4: Tipo de movimiento | AE4: Comentarios | AG4: Fecha de la factura | AH4: FACTURA O CUENTA COBRO | AI4: VALOR REAL DE LA FACTURA | AJ4: CONCEPTO
E5: Póliza de asistencia médica al viajero - producto visitor por 08 días | F5: Colasistencia | G5: 3500 | H5: 5 | I5: =G5*H5 -> 17500 | L5: =I5/0.6 -> 29166.667 | N5: =L5/$H$45 -> 7.4786325 | V5: =I5+J5 -> 17500 | W5: =V5-T5 -> 17500
E6: Sim card física | F6: Claro | G6: 6000 | H6: 1 | I6: =G6*H6 -> 6000 | L6: =I6/0.6 -> 10000 | N6: =L6/$H$45 -> 2.5641026 | V6: =I6+J6 -> 6000 | W6: =V6-T6 -> 6000
E7: Navegación de 10 GB | F7: Claro | G7: 12000 | H7: 1 | I7: =G7*H7 -> 12000 | L7: =I7/0.6 -> 20000 | N7: =L7/$H$45 -> 5.1282051 | V7: =I7+J7 -> 12000 | W7: =V7-T7 -> 12000
E8: El Poblado- Alojamiento una habitación con una cama King con desayuno para 1 o 2 personas | F8: BH El Poblado | G8: 395000 | H8: 4 | I8: =G8*H8 -> 1580000 | L8: 1660000 | N8: =L8/3800 -> 436.84211
E9: Traslado aeropuerto - hotel-aeropuerto | F9: AEROTUREX | G9: 151000 | H9: 2 | I9: =G9*H9 -> 302000 | L9: =I9/0.97 -> 311340.21 | N9: =L9/$H$45 -> 79.830822
D10: ok | E10: PAQUETE DE CHEQUEO MÉDICO
D11: ok | E11: Ecografía de mama | F11: Hernan Ocazionez | G11: 100000 | H11: 1 | I11: =G11*H11 -> 100000 | L11: =I11/0.6 -> 166666.67 | N11: =L11/$H$45 -> 42.735043
D12: ok | E12: Ecografía de abdomen total | F12: Hernan Ocazionez | G12: 140000 | H12: 1 | I12: =G12*H12 -> 140000 | L12: =I12/0.6 -> 233333.33 | N12: =L12/$H$45 -> 59.82906
D13: ok | E13: Electrocardiograma | F13: Incare | G13: 65000 | H13: 1 | I13: =G13*H13 -> 65000 | L13: =I13/0.6 -> 108333.33 | N13: =L13/$H$45 -> 27.777778 | Q13: 42500 | S13: =Q13*2% -> 850 | T13: =Q13-S13 -> 41650
D14: ok | E14: EXÁMENES DE CHEQUEO MÉDICO PERSONALIZADO
C15: 1 | D15: ok | E15: Anticuerpos Nucleares ANA | F15: Echavarria | G15: 43000 | H15: 1 | I15: =G15*H15 -> 43000 | L15: =I15/0.6 -> 71666.667 | N15: =L15/$H$45 -> 18.376068
C16: 2 | D16: ok | E16: Citoplasma de neutrófilos, anticuerpos totales [c-ANCA o p-ANCA] | F16: Echavarria | G16: 100000 | H16: 1 | I16: =G16*H16 -> 100000 | L16: =I16/0.6 -> 166666.67 | N16: =L16/$H$45 -> 42.735043 | Q16: 52500
C17: 3 | D17: ok | E17: Factor reumatoideo semiautomatizado o automatizado | F17: Echavarria | G17: 50000 | H17: 1 | I17: =G17*H17 -> 50000 | L17: =I17/0.6 -> 83333.333 | N17: =L17/$H$45 -> 21.367521 | Q17: 28000
C18: 4 | D18: ok | E18: Complemento Sérico C3 Cuantitativo por nefelometría | F18: Echavarria | G18: 30000 | H18: 1 | I18: =G18*H18 -> 30000 | L18: =I18/0.6 -> 50000 | N18: =L18/$H$45 -> 12.820513
C19: 5 | D19: ok | E19: Complemento Sérico C4 Cuantitativo por nefelometría | F19: Echavarria | G19: 35000 | H19: 1 | I19: =G19*H19 -> 35000 | L19: =I19/0.6 -> 58333.333 | N19: =L19/$H$45 -> 14.957265
C20: 6 | D20: ok | E20: Homocisteína sérica (HCYSP) | F20: Echavarria | G20: 108000 | H20: 1 | I20: =G20*H20 -> 108000 | L20: =I20/0.7 -> 154285.71 | N20: =L20/$H$45 -> 39.56044
C21: 7 | D21: ok | E21: Paratohormona | F21: Echavarria | G21: 116000 | H21: 1 | I21: =G21*H21 -> 116000 | L21: =I21/0.7 -> 165714.29 | N21: =L21/$H$45 -> 42.490842
D22: ok | E22: Ecografía de tiroides y paratiroides | F22: Hernan Ocazionez | G22: 100000 | H22: 1 | I22: =G22*H22 -> 100000 | L22: =I22/0.7 -> 142857.14 | N22: =L22/$H$45 -> 36.630037
C23: ok | D23: ok | E23: Tomografía computarizada de CUELLO. | F23: IVS | G23: 280000 | H23: 1 | I23: =G23*H23 -> 280000 | L23: =I23/0.8 -> 350000 | N23: =L23/$H$45 -> 89.74359 | Q23: 195140
C24: ok | D24: ok | E24: Tomografía computarizada de CABEZA. | F24: IVS | G24: 280000 | H24: 1 | I24: =G24*H24 -> 280000 | L24: =I24/0.8 -> 350000 | N24: =L24/$H$45 -> 89.74359 | Q24: 195140
C25: ok | D25: ok | E25: Tomografía computarizada de TÓRAX | F25: IVS | G25: 280000 | H25: 1 | I25: =G25*H25 -> 280000 | L25: =I25/0.8 -> 350000 | N25: =L25/$H$45 -> 89.74359 | Q25: 195140
D26: ok | E26: ESPECIALISTA
D27: ok | E27: Cita con especialista en REUMATOLOGÍA | F27: HPTU | G27: 300000 | H27: 1 | I27: =G27*H27 -> 300000 | L27: =I27/0.95 -> 315789.47 | N27: =L27/$H$45 -> 80.97166
D28: ok | E28: Cita con especialista en MEDICINA INTERNA | F28: HPTU | G28: 300000 | H28: 1 | I28: =G28*H28 -> 300000 | L28: =I28/0.95 -> 315789.47 | N28: =L28/$H$45 -> 80.97166 | Q28: cop296,000
E29: Cita con especialista en DERMATOLOGÍA | G29: 280000 | H29: 1 | I29: =G29*H29 -> 280000 | L29: =I29/0.95 -> 294736.84 | N29: =L29/$H$45 -> 75.573549 | Q29: 260000
D30: ok | E30: Biopsia de cuello cabelludo puede variar, lo determina el especialista | G30: 500000 | H30: 1 | I30: =G30*H30 -> 500000 | L30: =I30/0.9 -> 555555.56 | N30: =L30/$H$45 -> 142.45014 | Q30: 300.000 - 500.000
D31: ok | E31: Estudio de patología | G31: 110000 | H31: 1 | I31: =G31*H31 -> 110000 | L31: =I31/0.85 -> 129411.76 | N31: =L31/$H$45 -> 33.182504 | Q31: 110000
D32: OPCIONALES | E32: EXÁMENES OPCIONALES
C33: 1 | D33: OPCIONALES | E33: CA 19-9 Antígeno de cáncer de tubo digestivo | F33: Echavarria | G33: 57000 | H33: 1 | I33: =G33*H33 -> 57000 | L33: =I33/0.6 -> 95000 | N33: =L33/$H$45 -> 24.358974
C34: 3 | D34: OPCIONALES | E34: CEA (carcinoembrionario Antígeno) | F34: Echavarria | G34: 60000 | H34: 1 | I34: =G34*H34 -> 60000 | L34: =I34/0.6 -> 100000 | N34: =L34/$H$45 -> 25.641026
E35: 5 Traslados hotel - clínica por trayecto cortos | F35: Yenny Roberto | G35: 35000 | H35: 5 | I35: =G35*H35 -> 175000 | L35: =I35/0.95 -> 184210.53 | N35: =L35/$H$45 -> 47.233468
E36: 2 Traslados hotel - clínica por trayecto largos a HPTU | F36: Yenny Roberto | G36: 60000 | H36: 2 | I36: =G36*H36 -> 120000 | L36: =I36/0.95 -> 126315.79 | N36: =L36/$H$45 -> 32.388664
E37: Medical Trip Colombia SAS - Acompañamiento virtual permanente en ESPAÑOL | F37: Dayana | G37: 150000 | H37: 1 | I37: =G37*H37 -> 150000 | L37: =I37 -> 150000 | N37: =L37/$H$45 -> 38.461538
E38: Acompañamiento presencial en español para citas y exámenes | F38: Yenny Roberto | G38: 180000 | H38: 1.5 | I38: =G38*H38 -> 270000 | L38: =I38 -> 270000 | N38: =L38/$H$45 -> 69.230769
E39: Caja menor | F39: Yenny Roberto | G39: 20000 | H39: 1 | I39: =G39*H39 -> 20000
H40: Total neto | I40: =SUM(I5:I39) -> 5986500
H41: 0.15 | I41: =I40/0.847 -> 7067886.7 | N41: =SUM(N5:N40) -> 1810.8182
...

Sheet 08-07-25 Detalles de los servic
B3: DETALLE DE LOS SERVICIOS | C3: DÓLARES
B4: ='01-07-25-COSTEO'!E5 -> Póliza de asistencia médica al viajero - producto visitor por 08 días | C4: ='01-07-25-COSTEO'!N5 -> 7.4786325
B5: ='01-07-25-COSTEO'!E6 -> Sim card física | C5: ='01-07-25-COSTEO'!N6 -> 2.5641026
B6: ='01-07-25-COSTEO'!E7 -> Navegación de 10 GB | C6: ='01-07-25-COSTEO'!N7 -> 5.1282051
B7: ='01-07-25-COSTEO'!E8 -> El Poblado- Alojamiento una habitación con una cama King con desayuno para 1 o 2 personas | C7: ='01-07-25-COSTEO'!N8 -> 436.84211
B8: ='01-07-25-COSTEO'!E9 -> Traslado aeropuerto - hotel-aeropuerto | C8: ='01-07-25-COSTEO'!N9 -> 79.830822
B9: ='01-07-25-COSTEO'!E34 -> Ecografía de mama | C9: ='01-07-25-COSTEO'!N34 -> 42.735043
B10: ='01-07-25-COSTEO'!E35 -> Ecografía de abdomen total | C10: ='01-07-25-COSTEO'!N35 -> 59.82906
B11: ='01-07-25-COSTEO'!E36 -> Electrocardiograma | C11: ='01-07-25-COSTEO'!N36 -> 27.777778
B12: ='01-07-25-COSTEO'!E37 -> EXÁMENES DE CHEQUEO MÉDICO PERSONALIZADO | C12: ='01-07-25-COSTEO'!N37
B13: ='01-07-25-COSTEO'!E38 -> Anticuerpos Nucleares ANA | C13: ='01-07-25-COSTEO'!N38 -> 18.376068
B14: ='01-07-25-COSTEO'!E39 -> Citoplasma de neutrófilos, anticuerpos totales [c-ANCA o p-ANCA] | C14: ='01-07-25-COSTEO'!N39 -> 42.735043
B15: ='01-07-25-COSTEO'!E40 -> Factor reumatoideo semiautomatizado o automatizado | C15: ='01-07-25-COSTEO'!N40 -> 21.367521
B16: ='01-07-25-COSTEO'!E41 -> Complemento Sérico C3 Cuantitativo por nefelometría | C16: ='01-07-25-COSTEO'!N41 -> 12.820513
B17: ='01-07-25-COSTEO'!E42 -> Complemento Sérico C4 Cuantitativo por nefelometría | C17: ='01-07-25-COSTEO'!N42 -> 14.957265
B18: ='01-07-25-COSTEO'!E43 -> Homocisteína sérica (HCYSP) | C18: ='01-07-25-COSTEO'!N43 -> 39.56044
B19: ='01-07-25-COSTEO'!E44 -> Paratohormona | C19: ='01-07-25-COSTEO'!N44 -> 42.490842
B20: ='01-07-25-COSTEO'!E45 -> Ecografía de tiroides y paratiroides | C20: ='01-07-25-COSTEO'!N45 -> 36.630037
... B31: ='01-07-25-COSTEO'!E56 -> CA 19-9 Antígeno de cáncer de tubo digestivo | C31: ='01-07-25-COSTEO'!N56 -> 24.358974
B32: ='01-07-25-COSTEO'!E58 -> CEA (carcinoembrionario Antígeno) | C32: ='01-07-25-COSTEO'!N58 -> 25.641026
B33: ='01-07-25-COSTEO'!E63 -> 5 Traslados hotel - clínica por trayecto cortos | C33: ='01-07-25-COSTEO'!N63 -> 47.233468
B34: ='01-07-25-COSTEO'!E64 -> 2 Traslados hotel - clínica por trayecto largos a HPTU | C34: ='01-07-25-COSTEO'!N64 -> 32.388664
B35: ='01-07-25-COSTEO'!E65 -> Medical Trip Colombia SAS - Acompañamiento virtual permanente en ESPAÑOL | C35: ='01-07-25-COSTEO'!N65 -> 38.461538
B36: ='01-07-25-COSTEO'!E66 -> Acompañamiento presencial en español para citas y exámenes | C36: ='01-07-25-COSTEO'!N66 -> 69.230769
B37: ='01-07-25-COSTEO'!H70 -> 4 * 1000 | C37: 9
B38: ='01-07-25-COSTEO'!H71 -> Transferencia nacional | C38: 3.85
B39: Total | C39: =SUM(C4:C38) -> 1823.6682

Sheet CONFIRMACIÓN

Sheet VUELO
B2: no es el tiquete, tome un pantallazo de la web

Sheet 01-07-25-COSTEO
Y2: Libro diario contable | AG2: Factura electrónica
C3: PAGOS | Q3: PAGOS | V3: ESTADO DE CUENTA | Y3: PAGOS | AG3: FACTURA
B4: ACV documentos | C4: Contabilidad | D4: Operativo | E4: Concepto | F4: Proveedor | G4: Valor | H4: Días | L4: Comisionable | S4: Retención en la fuente | T4: Valor pagado | V4: Valor Neto cobrado al cliente | W4: DIFERENCIA | Y4: PROVEEDOR - NOMBRE COMERCIAL | Z4: ID | AA4: Fecha del pago | AB4: Valor del pago | AC4: Forma de pago de donde salió el dinero | AD4: Tipo de movimiento | AE4: Comentarios | AG4: Fecha de la factura | AH4: FACTURA O CUENTA COBRO | AI4: VALOR REAL DE LA FACTURA | AJ4: CONCEPTO
E5: Póliza de asistencia médica al viajero - producto visitor por 08 días | F5: Colasistencia | G5: 3500 | H5: 5 | I5: =G5*H5 -> 17500 | L5: =I5/0.6 -> 29166.667 | N5: =L5/$H$73 -> 7.4786325 | V5: =I5+J5 -> 17500 | W5: =V5-T5 -> 17500
E6: Sim card física | F6: Claro | G6: 6000 | H6: 1 | I6: =G6*H6 -> 6000 | L6: =I6/0.6 -> 10000 | N6: =L6/$H$73 -> 2.5641026 | V6: =I6+J6 -> 6000 | W6: =V6-T6 -> 6000
E7: Navegación de 10 GB | F7: Claro | G7: 12000 | H7: 1 | I7: =G7*H7 -> 12000 | L7: =I7/0.6 -> 20000 | N7: =L7/$H$73 -> 5.1282051 | V7: =I7+J7 -> 12000 | W7: =V7-T7 -> 12000
E8: El Poblado- Alojamiento una habitación con una cama King con desayuno para 1 o 2 personas | F8: BH El Poblado | G8: 395000 | H8: 4 | I8: =G8*H8 -> 1580000 | L8: 1660000 | N8: =L8/3800 -> 436.84211
E9: Traslado aeropuerto - hotel-aeropuerto | F9: AEROTUREX | G9: 151000 | H9: 2 | I9: =G9*H9 -> 302000 | L9: =I9/0.97 -> 311340.21 | N9: =L9/$H$73 -> 79.830822
D10: ok | E10: PAQUETE DE CHEQUEO MÉDICO
C11: 1 | D11: ok | E11: ALT- Alanina transferasa | F11: Echavarria | G11: 20000 | H11: 1 | I11: =G11*H11 -> 20000 | L11: =I11/0.6 -> 33333.333 | N11: =L11/$H$73 -> 8.5470085
C12: 2 | D12: ok | E12: AST - aspartato transferasa | F12: Echavarria | G12: 20000 | H12: 1 | I12: =G12*H12 -> 20000 | L12: =I12/0.6 -> 33333.333 | N12: =L12/$H$73 -> 8.5470085
C13: 3 | D13: ok | E13: Bilirrubina total y directa | F13: Echavarria | G13: 22000 | H13: 1 | I13: =G13*H13 -> 22000 | L13: =I13/0.6 -> 36666.667 | N13: =L13/$H$73 -> 9.4017094
C14: 4 | D14: ok | E14: Colesterol HDL | F14: Echavarria | G14: 10000 | H14: 1 | I14: =G14*H14 -> 10000 | L14: =I14/0.6 -> 16666.667 | N14: =L14/$H$73 -> 4.2735043
C15: 5 | D15: ok | E15: Colesterol LDL | F15: Echavarria | G15: 12000 | H15: 1 | I15: =G15*H15 -> 12000 | L15: =I15/0.6 -> 20000 | N15: =L15/$H$73 -> 5.1282051
C16: 6 | D16: ok | E16: Colesterol total | F16: Echavarria | G16: 15000 | H16: 1 | I16: =G16*H16 -> 15000 | L16: =I16/0.6 -> 25000 | N16: =L16/$H$73 -> 6.4102564
C17: 7 | D17: ok | E17: Creatinina | F17: Echavarria | G17: 15000 | H17: 1 | I17: =G17*H17 -> 15000 | L17: =I17/0.6 -> 25000 | N17: =L17/$H$73 -> 6.4102564
C18: 8 | D18: ok | E18: Coprológico | F18: Echavarria | G18: 22000 | H18: 1 | I18: =G18*H18 -> 22000 | L18: =I18/0.6 -> 36666.667 | N18: =L18/$H$73 -> 9.4017094
C19: 9 | D19: ok | E19: Ferritina | F19: Echavarria | G19: 50000 | H19: 1 | I19: =G19*H19 -> 50000 | L19: =I19/0.6 -> 83333.333 | N19: =L19/$H$73 -> 21.367521
C20: 10 | D20: ok | E20: Gamma glutamil transferasa | F20: Echavarria | G20: 22000 | H20: 1 | I20: =G20*H20 -> 22000 | L20: =I20/0.6 -> 36666.667 | N20: =L20/$H$73 -> 9.4017094
C21: 11 | D21: ok | E21: Glucosa sérica | F21: Echavarria | G21: 15000 | H21: 1 | I21: =G21*H21 -> 15000 | L21: =I21/0.6 -> 25000 | N21: =L21/$H$73 -> 6.4102564
C22: 12 | D22: ok | E22: Hemoglobina Glicosilada | F22: Echavarria | G22: 45000 | H22: 1 | I22: =G22*H22 -> 45000 | L22: =I22/0.6 -> 75000 | N22: =L22/$H$73 -> 19.230769
... C27: 17 | D27: ok | E27: Triglicéridos | F27: Echavarria | G27: 10000 | H27: 1 | I27: =G27*H27 -> 10000 | L27: =I27/0.6 -> 16666.667 | N27: =L27/$H$73 -> 4.2735043
B28: =530/7 -> 75.714286 | C28: 18 | D28: ok | E28: TSH | F28: Echavarria | G28: 37000 | H28: 1 | I28: =G28*H28 -> 37000 | L28: =I28/0.6 -> 61666.667 | N28: =L28/$H$73 -> 15.811966
C29: 19 | D29: ok | E29: Uroanálisis | F29: Echavarria | G29: 17000 | H29: 1 | I29: =G29*H29 -> 17000 | L29: =I29/0.6 -> 28333.333 | N29: =L29/$H$73 -> 7.2649573
C30: 20 | D30: ok | E30: VDRL | F30: Echavarria | G30: 20000 | H30: 1 | I30: =G30*H30 -> 20000 | L30: =I30/0.6 -> 33333.333 | N30: =L30/$H$73 -> 8.5470085
C31: 21 | D31: ok | E31: VIH 1 Y 2, Anticuerpos | F31: Echavarria | G31: 50000 | H31: 1 | I31: =G31*H31 -> 50000 | L31: =I31/0.6 -> 83333.333 | N31: =L31/$H$73 -> 21.367521
C32: 22 | D32: ok | E32: Vitamina D25 | F32: Echavarria | G32: 65000 | H32: 1 | I32: =G32*H32 -> 65000 | L32: =I32/0.6 -> 108333.33 | N32: =L32/$H$73 -> 27.777778
C33: tambien es lab | D33: ok | E33: Citología | F33: Echavarria | G33: 20000 | H33: 1 | I33: =G33*H33 -> 20000 | L33: =I33/0.6 -> 33333.333 | N33: =L33/$H$73 -> 8.5470085 | Q33: 35000 | R33: 35000 | S33: 0 | T33: =Q33+R33-S33 -> 70000 | V33: =I33+J33 -> 20000 | W33: =V33-R33-Q33 -> -50000
D34: ok | E34: Ecografía de mama | F34: Hernan Ocazionez | G34: 100000 | H34: 1 | I34: =G34*H34 -> 100000 | L34: =I34/0.6 -> 166666.67 | N34: =L34/$H$73 -> 42.735043
D35: ok | E35: Ecografía de abdomen total | F35: Hernan Ocazionez | G35: 140000 | H35: 1 | I35: =G35*H35 -> 140000 | L35: =I35/0.6 -> 233333.33 | N35: =L35/$H$73 -> 59.82906
D36: ok | E36: Electrocardiograma | F36: Incare | G36: 65000 | H36: 1 | I36: =G36*H36 -> 65000 | L36: =I36/0.6 -> 108333.33 | N36: =L36/$H$73 -> 27.777778 | Q36: 42500 | S36: =Q36*2% -> 850 | T36: =Q36-S36 -> 41650
D37: ok | E37: EXÁMENES DE CHEQUEO MÉDICO PERSONALIZADO
C38: 1 | D38: ok | E38: Anticuerpos Nucleares ANA | F38: Echavarria | G38: 43000 | H38: 1 | I38: =G38*H38 -> 43000 | L38: =I38/0.6 -> 71666.667 | N38: =L38/$H$73 -> 18.376068
C39: 2 | D39: ok | E39: Citoplasma de neutrófilos, anticuerpos totales [c-ANCA o p-ANCA] | F39: Echavarria | G39: 100000 | H39: 1 | I39: =G39*H39 -> 100000 | L39: =I39/0.6 -> 166666.67 | N39: =L39/$H$73 -> 42.735043 | Q39: 52500
C40: 3 | D40: ok | E40: Factor reumatoideo semiautomatizado o automatizado | F40: Echavarria | G40: 50000 | H40: 1 | I40: =G40*H40 -> 50000 | L40: =I40/0.6 -> 83333.333 | N40: =L40/$H$73 -> 21.367521 | Q40: 28000
C41: 4 | D41: ok | E41: Complemento Sérico C3 Cuantitativo por nefelometría | F41: Echavarria | G41: 30000 | H41: 1 | I41: =G41*H41 -> 30000 | L41: =I41/0.6 -> 50000 | N41: =L41/$H$73 -> 12.820513
C42: 5 | D42: ok | E42: Complemento Sérico C4 Cuantitativo por nefelometría | F42: Echavarria | G42: 35000 | H42: 1 | I42: =G42*H42 -> 35000 | L42: =I42/0.6 -> 58333.333 | N42: =L42/$H$73 -> 14.957265
C43: 6 | D43: ok | E43: Homocisteína sérica (HCYSP) | F43: Echavarria | G43: 108000 | H43: 1 | I43: =G43*H43 -> 108000 | L43: =I43/0.7 -> 154285.71 | N43: =L43/$H$73 -> 39.56044
C44: 7 | D44: ok | E44: Paratohormona | F44: Echavarria | G44: 116000 | H44: 1 | I44: =G44*H44 -> 116000 | L44: =I44/0.7 -> 165714.29 | N44: =L44/$H$73 -> 42.490842
D45: ok | E45: Ecografía de tiroides y paratiroides | F45: Hernan Ocazionez | G45: 100000 | H45: 1 | I45: =G45*H45 -> 100000 | L45: =I45/0.7 -> 142857.14 | N45: =L45/$H$73 -> 36.630037
...

Sheet 01-07-25 Detalle de los servici
B3: DETALLE DE LOS SERVICIOS | C3: DÓLARES
B4: ='01-07-25-COSTEO'!E5 -> Póliza de asistencia médica al viajero - producto visitor por 08 días | C4: ='01-07-25-COSTEO'!N5 -> 7.4786325
B5: ='01-07-25-COSTEO'!E6 -> Sim card física | C5: ='01-07-25-COSTEO'!N6 -> 2.5641026
B6: ='01-07-25-COSTEO'!E7 -> Navegación de 10 GB | C6: ='01-07-25-COSTEO'!N7 -> 5.1282051
B7: ='01-07-25-COSTEO'!E8 -> El Poblado- Alojamiento una habitación con una cama King con desayuno para 1 o 2 personas | C7: ='01-07-25-COSTEO'!N8 -> 436.84211
B8: ='01-07-25-COSTEO'!E9 -> Traslado aeropuerto - hotel-aeropuerto | C8: ='01-07-25-COSTEO'!N9 -> 79.830822
B9: ='01-07-25-COSTEO'!E11 -> ALT- Alanina transferasa | C9: ='01-07-25-COSTEO'!N11 -> 8.5470085
B10: ='01-07-25-COSTEO'!E12 -> AST - aspartato transferasa | C10: ='01-07-25-COSTEO'!N12 -> 8.5470085
B11: ='01-07-25-COSTEO'!E13 -> Bilirrubina total y directa | C11: ='01-07-25-COSTEO'!N13 -> 9.4017094
B12: ='01-07-25-COSTEO'!E14 -> Colesterol HDL | C12: ='01-07-25-COSTEO'!N14 -> 4.2735043
B13: ='01-07-25-COSTEO'!E15 -> Colesterol LDL | C13: ='01-07-25-COSTEO'!N15 -> 5.1282051
B14: ='01-07-25-COSTEO'!E16 -> Colesterol total | C14: ='01-07-25-COSTEO'!N16 -> 6.4102564
B15: ='01-07-25-COSTEO'!E17 -> Creatinina | C15: ='01-07-25-COSTEO'!N17 -> 6.4102564
B16: ='01-07-25-COSTEO'!E18 -> Coprológico | C16: ='01-07-25-COSTEO'!N18 -> 9.4017094
B17: ='01-07-25-COSTEO'!E19 -> Ferritina | C17: ='01-07-25-COSTEO'!N19 -> 21.367521
B18: ='01-07-25-COSTEO'!E20 -> Gamma glutamil transferasa | C18: ='01-07-25-COSTEO'!N20 -> 9.4017094
B19: ='01-07-25-COSTEO'!E21 -> Glucosa sérica | C19: ='01-07-25-COSTEO'!N21 -> 6.4102564
B20: ='01-07-25-COSTEO'!E22 -> Hemoglobina Glicosilada | C20: ='01-07-25-COSTEO'!N22 -> 19.230769
... B64: ='01-07-25-COSTEO'!E66 -> Acompañamiento presencial en español para citas y exámenes | C64: ='01-07-25-COSTEO'!N66 -> 69.230769
B65: ='01-07-25-COSTEO'!H70 -> 4 * 1000 | C65: 9
B66: ='01-07-25-COSTEO'!H71 -> Transferencia nacional | C66: 3.85
B67: Total | C67: =SUM(C4:C66) -> 2295.8904

Sheet CARPETA - ARCHIVO
B3: ARCHIVO DIGITAL | C3: LABORATORIOS CLÍNICOS | D3: ARCHIVO DIGITAL | E3: IMÁGENES DIAGNÓSTICAS | F3: ARCHIVO DIGITAL | G3: ESPECIALISTAS | I3: ARCHIVO DIGITAL | J3: LABORATORIOS CLÍNICOS | K3: ARCHIVO DIGITAL | L3: IMÁGENES DIAGNÓSTICAS
C4: ='01-07-25-COSTEO'!E11 -> ALT- Alanina transferasa | E4: Radiografía de tórax | G4: PROSTODONCISTA | J4: ='01-07-25-COSTEO'!E11 -> ALT- Alanina transferasa | L4: =E14
C5: ='01-07-25-COSTEO'!E12 -> AST - aspartato transferasa | E5: Mamografía | G5: INTERNISTA | J5: ='01-07-25-COSTEO'!E12 -> AST - aspartato transferasa
C6: ='01-07-25-COSTEO'!E13 -> Bilirrubina total y directa | E6: Ecografía de abdomen total | G6: FISIATRÍA | J6: ='01-07-25-COSTEO'!E13 -> Bilirrubina total y directa
C7: ='01-07-25-COSTEO'!E14 -> Colesterol HDL | E7: Electrocardiograma | J7: ='01-07-25-COSTEO'!E14 -> Colesterol HDL
C8: ='01-07-25-COSTEO'!E15 -> Colesterol LDL | E8: Ecografía de tiroides y paratiroides | J8: ='01-07-25-COSTEO'!E15 -> Colesterol LDL
C9: ='01-07-25-COSTEO'!E16 -> Colesterol total | E9: Ecografía uterina transvaginal | J9: ='01-07-25-COSTEO'!E16 -> Colesterol total
C10: ='01-07-25-COSTEO'!E17 -> Creatinina | E10: Ecografía del corazón - ecocardiografía | J10: ='01-07-25-COSTEO'!E17 -> Creatinina
C11: ='01-07-25-COSTEO'!E18 -> Coprológico | E11: Tomografía computarizada de CUELLO. | J11: ='01-07-25-COSTEO'!E18 -> Coprológico
C12: ='01-07-25-COSTEO'!E19 -> Ferritina | J12: ='01-07-25-COSTEO'!E19 -> Ferritina
C13: ='01-07-25-COSTEO'!E20 -> Gamma glutamil transferasa | J13: ='01-07-25-COSTEO'!E20 -> Gamma glutamil transferasa
C14: ='01-07-25-COSTEO'!E21 -> Glucosa sérica | J14: ='01-07-25-COSTEO'!E21 -> Glucosa sérica
C15: ='01-07-25-COSTEO'!E22 -> Hemoglobina Glicosilada | J15: ='01-07-25-COSTEO'!E22 -> Hemoglobina Glicosilada
C16: ='01-07-25-COSTEO'!E23 -> Hemograma completo | J16: ='01-07-25-COSTEO'!E23 -> Hemograma completo
C17: ='01-07-25-COSTEO'!E24 -> Nitrógeno Ureico en Sangre (BUN) | J17: ='01-07-25-COSTEO'!E24 -> Nitrógeno Ureico en Sangre (BUN)
C18: ='01-07-25-COSTEO'!E25 -> T3 libre | J18: ='01-07-25-COSTEO'!E25 -> T3 libre
C19: ='01-07-25-COSTEO'!E26 -> T4 libre | J19: ='01-07-25-COSTEO'!E26 -> T4 libre
C20: ='01-07-25-COSTEO'!E27 -> Triglicéridos | J20: ='01-07-25-COSTEO'!E27 -> Triglicéridos
C21: ='01-07-25-COSTEO'!E28 -> TSH | J21: ='01-07-25-COSTEO'!E28 -> TSH
C22: ='01-07-25-COSTEO'!E29 -> Uroanálisis | J22: ='01-07-25-COSTEO'!E29 -> Uroanálisis
C23: ='01-07-25-COSTEO'!E30 -> VDRL | J23: ='01-07-25-COSTEO'!E30 -> VDRL
... C26: ='01-07-25-COSTEO'!E33 -> Citología | J26: ='01-07-25-COSTEO'!E33 -> Citología
C27: ='01-07-25-COSTEO'!E60 -> Anticuerpos del receptor de tirotropina (TRAb)
C28: ='01-07-25-COSTEO'!E61 -> Autoanticuerpos de tiroglobulina (Tg Ab)
C29: ='01-07-25-COSTEO'!E62 -> Ionograma: calcio - sodio - fósforo - potasio
C30: ='01-07-25-COSTEO'!E43 -> Homocisteína sérica (HCYSP)
C31: ='01-07-25-COSTEO'!E44 -> Paratohormona
C32: ='01-07-25-COSTEO'!E59 -> Anticuerpos de peroxidasa tiroidea (TPO Ab)
C33: ='01-07-25-COSTEO'!E56 -> CA 19-9 Antígeno de cáncer de tubo digestivo
C34: ='01-07-25-COSTEO'!E57 -> CA-125 - Antígeno de cáncer de ovario
C35: ='01-07-25-COSTEO'!E58 -> CEA (carcinoembrionario Antígeno)
C54: ='01-07-25-COSTEO'!E68
C55: ='01-07-25-COSTEO'!E69
C56: ='01-07-25-COSTEO'!E70
C57: ='01-07-25-COSTEO'!E71
C58: ='01-07-25-COSTEO'!E72
