Workbook

Sheet Pasaporte - HC
A15: Nombre | C15: Rainer | E15: Nombre | F15: Natifa
A16: Nombre | E16: Nombre
A17: Apellido | C17: Inecia | E17: Apellido | F17: Francisca
A18: Apellido de casada | E18: Apellido de casada
A19: Género: . | C19: Masculino | E19: Género: . | F19: Femenino
A20: Pasaporte | C20: NWP2J35K1 | E20: Pasaporte | F20: NX7J77K53
A21: Fecha de nacimiento | C21: 32190 | E21: Fecha de nacimiento | F21: 30 Agost 1990
A22: Edad | C22: 37 | E22: Edad | F22: 34
A23: Estado civil | C23: En una Relación | E23: Estado civil | F23: En una Relación
A24: Dirección | E24: Dirección
A25: Nacionalidad y domicilio: | C25: Burgemeestar Augustijnstraat 32, Países Bajos | E25: Nacionalidad y domicilio: | F25: Burgemeestar Augustijnstraat 32, Países Bajos
A26: Email: | C26: rainer.inecia88@gmail.com | E26: Email: | F26: ncfrancisca@gmail.com
A27: Teléfono | C27: 31682221015 | E27: Teléfono | F27: =+31610674497 -> 31610674497
A28: Profesión | C28: Obstetra | E28: Profesión | F28: Obstetra
A29: RH | E29: RH
A30: Seguro | C30: Silveren Kruis | E30: Seguro | F30: Silveren Kruis
A31: Peso | C31: 108 | E31: Peso
A32: Altura | C32: 1.67 | E32: Altura
A33: Idioma | C33: holandés, español, papiamento, inglés | E33: Idioma | F33: Idiomas: holandés, español, papiamento, inglés
A35: Salud | C35: Chequeo general para descartar causas de síntomas de larga duración como: dolor de estómago, dolor al defecar con hemorroides, ronquidos intensos nocturnos que requieren un dispositivo para la apnea del sueño. Aún no tiene PSA, presenta algunas alteraciones visuales y necesita evaluar su alto riesgo cardiovascular e iniciar el proceso de pérdida de peso mientras aprende a comer saludablemente. Además, es necesario descartar hipertrigliceridemia en un examen previo confuso. | E35: Salud | F35: Chequeo general para descartar causas de síntomas de larga duración, como: dolores de cabeza 4 veces por semana, problemas de refracción visual. Se despierta con dolor de cabeza. Toma medicamentos constantemente. Sensación de vómito, dolor en las rodillas y taquicardia. Orina con frecuencia. Presenta inflamación y ha tomado antibióticos para estos episodios debido a la presencia de sangre en su orina. Lleva una vida sedentaria, presenta bruxismo con picaduras y probablemente prediabetes.

Sheet ITINERARIO
B3: ITINERARIO:
B4: Dia | C4: Fecha | D4: Hora | E4: Actividad | F4: ACP horas | G4: Traslado cerca | H4: Traslado lejos
C5: DIA 01 | D5: 45889 | E5: MIÉRCOLES
E6: Vuelo Curazao - Medellín
E7: Traslado a aeropuerto - hotel
E8: Alojamiento
C9: DIA 02 | D9: 45890 | E9: JUEVES
E10: No desayunar
D11: 06:00 am | E11: Traslado Hotel - centro médico | F11: 1.1 | G11: 1
A12: MISMA SEDE | B12: IVS | C12: EL | D12: 07:00 am | E12: Tomografía de abdomen total
A13: MISMA SEDE | B13: IVS | C13: ELLA | E13: Tomografía de cabeza
A14: MISMA SEDE | B14: IVS | C14: ELLA | E14: Tomografía de abdomen y pelvis
A15: MISMA SEDE | E15: Radiografía de tórax
A16: MISMA SEDE | E16: Ecografía de mama
E17: Tiempo para desayunar
E18: Traslado centro médico - centro médico | G18: 1
B19: SAN DIEGO | C19: ELLA | E19: Consulta con especialista en Oftalmología
B20: SAN DIEGO | C20: EL | E20: Consulta con especialista en Oftalmología
E21: Traslado centro médico - hotel | G21: 1
E22: TARDE LIBRE
C23: DIA 03 | D23: 45891 | E23: VIERNES
E24: No desayunar
E25: Traslado Hotel - centro médico | F25: 1.1 | G25: 1
A26: El Tesoro | B26: Synlab | C26: ELLA Y EL | D26: 07:00 am | E26: Toma de muestras de sangre laboratorio clínico
A27: El Tesoro | B27: Synlab | C27: ELLA | E27: Citología cervical
E28: Tiempo para desayunar
A29: El Tesoro | B29: Incare | C29: ELLA Y EL | E29: Electrocardiograma
A30: El Tesoro | B30: Incare | C30: ELLA Y EL | E30: Ecocardiograma
A31: El Tesoro | B31: Incare | C31: ELLA Y EL | E31: Prueba de esfuerzo
E32: Tiempo para almorzar
A33: El Tesoro | B33: Univershe | C33: ELLA | E33: Citología transvaginal
A34: El Tesoro | B34: Univershe | C34: ELLA | E34: Cita con especialista en Ginecología
D35: 02:00 pm | E35: Traslado centro médico - hotel
E36: TARDE LIBRE | G36: 1
C37: DIA 04 | D37: 45892 | E37: SÁBADO
E38: No desayunar
E39: Traslado Hotel - centro médico | F39: 0.5 | G39: 1
B40: Las Américas | C40: EL | D40: 07:00 am | E40: Endoscopia con biopsia
E41: Traslado centro médico - hotel | G41: 1
E42: Tiempo para desayunar y descansar
...

Sheet COSTEO
Y2: Libro diario contable | AG2: Factura electrónica
C3: PAGOS | Q3: PAGOS | V3: ESTADO DE CUENTA | Y3: PAGOS | AG3: FACTURA
B4: ACV documentos | C4: Contabilidad | D4: Operativo | E4: Concepto | G4: Valor | H4: Días | I4: ELLA | J4: EL | L4: ELLA | M4: EL | N4: ELLA | O4: EL | S4: Retención en la fuente | T4: Valor pagado | V4: Valor Neto cobrado al cliente | W4: DIFERENCIA | Y4: PROVEEDOR - NOMBRE COMERCIAL | Z4: ID | AA4: Fecha del pago | AB4: Valor del pago | AC4: Forma de pago de donde salió el dinero | AD4: Tipo de movimiento | AE4: Comentarios | AG4: Fecha de la factura | AH4: FACTURA O CUENTA COBRO | AI4: VALOR REAL DE LA FACTURA | AJ4: CONCEPTO | AL4: CONCEPTO
E5: Póliza de asistencia médica al viajero - producto visitor por 11 días | G5: 3500 | H5: 11 | I5: =G5*H5 -> 38500 | J5: =G5*H5 -> 38500 | L5: =I5/0.7 -> 55000 | M5: =J5/0.7 -> 55000 | N5: =L5/$H$95 -> 14.473684 | O5: =M5/$H$95 -> 14.473684
E6: Sim card física | G6: 6000 | H6: 1 | I6: =G6*H6 -> 6000 | J6: =G6*H6 -> 6000 | L6: =I6/0.6 -> 10000 | M6: =J6/0.6 -> 10000 | N6: =L6/$H$95 -> 2.6315789 | O6: =M6/$H$95 -> 2.6315789
E7: Recarga de datos de 10 GB | G7: 12000 | H7: 1 | I7: =G7*H7 -> 12000 | J7: =G7*H7 -> 12000 | L7: =I7/0.6 -> 20000 | M7: =J7/0.6 -> 20000 | N7: =L7/$H$95 -> 5.2631579 | O7: =M7/$H$95 -> 5.2631579
E8: Traslado aeropuerto - hotel - aeropuerto | G8: 151000 | H8: 2 | I8: =G8*H8/2 -> 151000 | J8: =G8*H8/2 -> 151000 | L8: =I8/0.95 -> 158947.37 | M8: =J8/0.95 -> 158947.37 | N8: =L8/$H$95 -> 41.828255 | O8: =M8/$H$95 -> 41.828255
E9: PAQUETE DE CHEQUEO MÉDICO | I9: 1450000 | J9: 1400000 | N9: 450 | O9: 450
E10: LABORATORIOS CLÍNICOS
B11: ok | D11: EL | E11: Antígeno de próstata | I11: No
B12: ok | D12: EL | E12: Coprológico
B13: ok | D13: X | E13: Citología cervical | J13: No
B14: ok | D14: EL | E14: Vitamina D25
B15: ok | D15: EL | E15: Vitamina B12
B16: ok | D16: EL | E16: Perfil lipídico
B17: ok | D17: EL | E17: Colesterol HDL
B18: ok | D18: EL | E18: Colesterol LDL
B19: ok | D19: EL | E19: Colesterol total
B20: ok | D20: EL | E20: Triglicéridos
B21: ok | D21: EL | E21: Perfil Hepático
B22: ok | D22: EL | E22: ALT- Alanina transferasa
B23: ok | D23: EL | E23: AST - aspartato transferasa
B24: ok | D24: EL | E24: Bilirrubina total y directa
B25: ok | D25: EL | E25: Gama Glutamil transferasa
... B42: ok | D42: EL | E42: Radiografía de tórax
B43: ok | D43: X | E43: Ecografía de mamas | J43: No
B44: X | C44: X | D44: X | E44: Ecografía de abdomen total | I44: No | J44: No | N44: No | O44: No
B45: ok | D45: EL | E45: Electrocardiograma
B46: X | C46: X | D46: X | E46: Cita con especialista en MEDICINA INTERNA | I46: No | J46: No | N46: No | O46: No
E47: ORDENES MÉDICAS
E48: LABORATORIOS CLÍNICOS
B49: ok | C49: ELLA | E49: AMH hormona antimulleriana | G49: 150000 | H49: 1 | I49: =G49*H49 -> 150000 | J49: No | L49: =I49/0.6 -> 250000 | M49: No | N49: =L49/$H$95 -> 65.789474 | O49: No
B50: ok | C50: ELLA | E50: Estradiol total | G50: 36000 | H50: 1 | I50: =G50*H50 -> 36000 | J50: No | L50: =I50/0.6 -> 60000 | M50: No | N50: =L50/$H$95 -> 15.789474 | O50: No
B51: ok | C51: ELLA | E51: FSH Hormona foliculoestimulante | G51: 39000 | H51: 1 | I51: =G51*H51 -> 39000 | J51: No | L51: =I51/0.6 -> 65000 | M51: No | N51: =L51/$H$95 -> 17.105263 | O51: No
B52: ok | C52: ELLA | E52: LH Hormona Luteinizante | G52: 38000 | H52: 1 | I52: =G52*H52 -> 38000 | J52: No | L52: =I52/0.6 -> 63333.333 | M52: No | N52: =L52/$H$95 -> 16.666667 | O52: No
B53: ok | C53: ELLA | E53: Prolactina | G53: 35000 | H53: 1 | I53: =G53*H53 -> 35000 | J53: No | L53: =I53/0.6 -> 58333.333 | M53: No | N53: =L53/$H$95 -> 15.350877 | O53: No
B54: ok | C54: ELLA | E54: Testosterona total | G54: 42000 | H54: 1 | I54: =G54*H54 -> 42000 | J54: No | L54: =I54/0.6 -> 70000 | M54: No | N54: =L54/$H$95 -> 18.421053 | O54: No
B55: ok | C55: ELLA | E55: Androstenediona | G55: 40000 | H55: 1 | I55: =G55*H55 -> 40000 | J55: No | L55: =I55/0.6 -> 66666.667 | M55: No | N55: =L55/$H$95 -> 17.54386 | O55: No
B56: ok | C56: ELLA | E56: Hormona Dehidroepiandrosterona-Sulfato (DHEA-S) | G56: 40000 | H56: 1 | I56: =G56*H56 -> 40000 | J56: No | L56: =I56/0.6 -> 66666.667 | M56: No | N56: =L56/$H$95 -> 17.54386 | O56: No
B57: ok | C57: ELLA | E57: Hidroxiprogesterona (17 OHP) | G57: 70000 | H57: 1 | I57: =G57*H57 -> 70000 | J57: No | L57: =I57/0.6 -> 116666.67 | M57: No | N57: =L57/$H$95 -> 30.701754 | O57: No
...

Sheet Detalle de los servicios
B4: DETALLE DE SERVICIOS | C4: Natifa | D4: Rainer
B5: =COSTEO!E5 -> Póliza de asistencia médica al viajero - producto visitor por 11 días | C5: =COSTEO!N5 -> 14.473684 | D5: =COSTEO!O5 -> 14.473684
B6: =COSTEO!E6 -> Sim card física | C6: =COSTEO!N6 -> 2.6315789 | D6: =COSTEO!O6 -> 2.6315789
B7: =COSTEO!E7 -> Recarga de datos de 10 GB | C7: =COSTEO!N7 -> 5.2631579 | D7: =COSTEO!O7 -> 5.2631579
B8: =COSTEO!E8 -> Traslado aeropuerto - hotel - aeropuerto | C8: =COSTEO!N8 -> 41.828255 | D8: =COSTEO!O8 -> 41.828255
B9: =COSTEO!E9 -> PAQUETE DE CHEQUEO MÉDICO | C9: =COSTEO!N9 -> 450 | D9: =COSTEO!O9 -> 450
B10: =COSTEO!E10 -> LABORATORIOS CLÍNICOS | C10: =COSTEO!N10 | D10: =COSTEO!O10
B11: =COSTEO!E11 -> Antígeno de próstata | C11: =COSTEO!N11 | D11: =COSTEO!O11
B12: =COSTEO!E12 -> Coprológico | C12: =COSTEO!N12 | D12: =COSTEO!O12
B13: =COSTEO!E13 -> Citología cervical | C13: =COSTEO!N13 | D13: =COSTEO!O13
B14: =COSTEO!E14 -> Vitamina D25 | C14: =COSTEO!N14 | D14: =COSTEO!O14
B15: =COSTEO!E15 -> Vitamina B12 | C15: =COSTEO!N15 | D15: =COSTEO!O15
B16: =COSTEO!E16 -> Perfil lipídico | C16: =COSTEO!N16 | D16: =COSTEO!O16
... B46: =COSTEO!E46 -> Cita con especialista en MEDICINA INTERNA | C46: =COSTEO!N46 -> No | D46: =COSTEO!O46 -> No
B47: =COSTEO!E47 -> ORDENES MÉDICAS | C47: =COSTEO!F47 | D47: =COSTEO!G47
B48: =COSTEO!E48 -> LABORATORIOS CLÍNICOS | C48: =COSTEO!F48 | D48: =COSTEO!G48
B49: =COSTEO!E49 -> AMH hormona antimulleriana | C49: =COSTEO!N49 -> 65.789474 | D49: =COSTEO!O49 -> No | F49: PERFIL HORMONAL
B50: =COSTEO!E50 -> Estradiol total | C50: =COSTEO!N50 -> 15.789474 | D50: =COSTEO!O50 -> No | F50: =B50 -> Estradiol total | G50: =C50 -> 15.789474
B51: =COSTEO!E51 -> FSH Hormona foliculoestimulante | C51: =COSTEO!N51 -> 17.105263 | D51: =COSTEO!O51 -> No | F51: =B51 -> FSH Hormona foliculoestimulante | G51: =C51 -> 17.105263
B52: =COSTEO!E52 -> LH Hormona Luteinizante | C52: =COSTEO!N52 -> 16.666667 | D52: =COSTEO!O52 -> No | F52: =B52 -> LH Hormona Luteinizante | G52: =C52 -> 16.666667
B53: =COSTEO!E53 -> Prolactina | C53: =COSTEO!N53 -> 15.350877 | D53: =COSTEO!O53 -> No | F53: =B53 -> Prolactina | G53: =C53 -> 15.350877
B54: =COSTEO!E54 -> Testosterona total | C54: =COSTEO!N54 -> 18.421053 | D54: =COSTEO!O54 -> No | F54: Progesterona | G54: =C54 -> 18.421053
B55: =COSTEO!E55 -> Androstenediona | C55: =COSTEO!N55 -> 17.54386 | D55: =COSTEO!O55 -> No | F55: TOTAL | G55: =SUM(G50:G54) -> 83.333333
B56: =COSTEO!E56 -> Hormona Dehidroepiandrosterona-Sulfato (DHEA-S) | C56: =COSTEO!N56 -> 17.54386 | D56: =COSTEO!O56 -> No
B57: =COSTEO!E57 -> Hidroxiprogesterona (17 OHP) | C57: =COSTEO!N57 -> 30.701754 | D57: =COSTEO!O57 -> No
B58: =COSTEO!E58 -> G6PD (glucosa-6-fosfato deshidrogenasa) Prueba cualitativa | C58: =COSTEO!N58 -> 18.421053 | D58: =COSTEO!O58 -> 18.421053
B59: =COSTEO!E59 -> G6PD (glucosa-6-fosfato deshidrogenasa) Prueba cuantitativa | C59: =COSTEO!N59 -> 26.315789 | D59: =COSTEO!O59 -> 26.315789
B60: =COSTEO!E60 -> Frotis de sangre periférica - (extendido de sangre periférica estudio de morfología) | C60: =COSTEO!N60 -> 19.736842 | D60: =COSTEO!O60 -> No
B61: =COSTEO!E61 -> Test de sicklemia: (Células Falciformes-drepanocitosis) | C61: =COSTEO!N61 -> 17.54386 | D61: =COSTEO!O61 -> No
B62: =COSTEO!E62 -> Insulina Pre y post glucosa | C62: =COSTEO!N62 -> 26.315789 | D62: =COSTEO!O62 -> No
B63: =COSTEO!E63 -> Curva de glucosa. | C63: =COSTEO!N63 -> 26.315789 | D63: =COSTEO!O63 -> No
B64: =COSTEO!E64 -> Paratohormona | C64: =COSTEO!N64 -> No | D64: =COSTEO!O64 -> 50.877193
B65: =COSTEO!E65 -> Homocisteína | C65: =COSTEO!N65 -> 47.368421 | D65: =COSTEO!O65 -> 47.368421
B66: =COSTEO!E66 -> IMÁGENES DIAGNÓSTICAS | C66: =COSTEO!F66 | D66: =COSTEO!G66
B67: =COSTEO!E67 -> Esofagoduoendoscopia | C67: =COSTEO!N67 -> No | D67: =COSTEO!O67 -> 131.57895
B68: =COSTEO!E68 -> Una biopsia para la endoscopia | C68: =COSTEO!N68 -> No | D68: =COSTEO!O68 -> 38.304094
B69: =COSTEO!E69 -> Ecocardiografía | C69: =COSTEO!N69 -> 120.30075 | D69: =COSTEO!O69 -> 120.30075
B70: =COSTEO!E70 -> Prueba de esfuerzo | C70: =COSTEO!N70 -> 97.744361 | D70: =COSTEO!O70 -> 97.744361
B71: =COSTEO!E71 -> Tomografía de abdomen total | C71: =COSTEO!N71 -> No | D71: =COSTEO!O71 -> 98.245614
B72: =COSTEO!E72 -> Tomografía de cabeza | C72: =COSTEO!N72 -> 102.33918 | D72: =COSTEO!O72 -> No
...

Sheet Vuelo
