Workbook

Sheet PASAPORTE DATOS 
A18: Nombre | B18: SHANELLA | D18: Nombre
A19: Nombre | B19: CICILIA | D19: Nombre
A20: Apellido | B20: VERGINIE | D20: Apellido
D21: Apellido de casada
A22: Género: . | B22: FEMENINO | D22: Género: .
A23: Pasaporte | B23: NU8P4K6F3 | D23: Pasaporte
A24: Fecha de nacimiento | B24: 24000 | D24: Fecha de nacimiento
A25: Edad | B25: 60 | D25: Edad
A26: Estado civil | D26: Estado civil
A27: Dirección | D27: Dirección
A28: Nacionalidad y domicilio: | D28: Nacionalidad y domicilio:
A29: Email: | B29: miss_bonifacio@hotmail.com | D29: Email:
A30: Teléfono | B30: 599 9 5158952 | D30: Teléfono
A31: Profesión | D31: Profesión
A32: RH | B32: O + | D32: RH
A33: Seguro | D33: Seguro
A34: Peso | B34: 82 kg | D34: Peso
A35: Altura | B35: 1.65 | D35: Altura
A36: Idioma | B36: Español. Ingles, Holandes, Papiamento | D36: Idioma
A37: Estadia: | D37: Estadia:
A38: Salud | D38: Salud
B39: Paciente femenina de 60 años que consulta para un chequeo general y una segunda opinión por dolor muscular y neuropático en la región lumbar y la pierna izquierda, desde la región lumbar hasta la fosa poplítea. Presenta diplopía concomitante, por lo que se debe evaluar para descartar otras afecciones. Busca mejorar su salud y su movilidad para desempeñarse mejor como enfermera y cuidadora.

Sheet CARPETA - ARCHIVO
A2: SHANELLA
A3: ARCHIVO DIGITAL | B3: LABORATORIOS CLÍNICOS | C3: ARCHIVO DIGITAL | D3: IMÁGENES DIAGNÓSTICAS | E3: ARCHIVO DIGITAL | F3: ESPECIALISTAS

Sheet ITINERARIO
B3: ITINERARIO:
B4: Dia | D4: Fecha | E4: Hora | F4: Actividad | G4: ACP horas | H4: Traslado cerca | I4: Traslado lejos
D5: 1 | E5: 45986 | F5: MARTES
F6: Vuelo Curazao - Medellín
F7: Traslado a aeropuerto - hotel
F8: Alojamiento
D9: 2 | E9: 45987 | F9: MIÉRCOLES
F10: Tiempo para desayunar
E11: 07:00 am | F11: Traslado Hotel - Centro médico | G11: 1 | H11: 1
A12: El Tesoro | B12: Imágenes y Especialistas | C12: Sin cita | D12: Dea | E12: 07:30 am | F12: Cita panorámica Dental
A13: El Tesoro | B13: Alta Estética Dental | C13: CANCELADA | D13: Dea | E13: 08:00 am | F13: Cita con Odontología
A14: El Tesoro | B14: Oftalmólogos El Tesoro | C14: Pendiente | D14: Shanella | F14: Cita con Oftalmología
F15: Tiempo para almorzar ligero
E16: 01:00 pm | F16: Traslado Centro médico - centro médico | H16: 1
A17: El Poblado | B17: CRE - Medialfa | C17: CANCELADA | D17: Shanella | E17: 01:40 pm | F17: Resonancia de columna lumbar sin sedación - resonador abierto
F18: Traslado Centro médico - Hotel | H18: 1
D19: 3 | E19: 45988 | F19: JUEVES
F20: No desayunar
E21: 05:30 am | F21: Traslado Hotel - Centro médico | G21: 0.5 | H21: 1
A22: Ciudad del río | B22: Cima | C22: Pendiente | D22: Shanella | F22: Toma de muestras de sangre laboratorio clínico
B23: Cima | D23: Shanella | F23: Ecografía de abdomen total
B24: Cima | D24: Shanella | F24: Citología
B25: Cima | D25: Shanella | F25: Ecografía de mama
B26: Cima | D26: Shanella | F26: Radiografía de tórax
B27: Cima | D27: Shanella | F27: Radiografía de pie derecho
B28: Cima | D28: Shanella | F28: Radiografía de pie izquierdo
B29: Cima | D29: Shanella | F29: Electrocardiograma
E30: 08:30 am | F30: Traslado Centro médico - Hotel | H30: 1
F31: Día libre
A32: El Tesoro | B32: Alta Estética Dental | C32: Pendiente | F32: Cita con Odontología
D33: 4 | E33: 45989 | F33: VIERNES - día libre
F34: Mañana libre
F35: Tiempo para almorzar
F36: Traslado Hotel - Centro médico | G36: 0.5 | H36: 1
A37: Clínica Las Vegas | B37: ORVÉ | C37: Pendiente | D37: Shanella | E37: Tarde | F37: Cita con especialista en Ortopedia de Columna
A38: Clínica Las Vegas | C38: Pendiente | D38: Shanella | F38: Cita con especialista en Medicina Interna
F39: Traslado Centro médico - Hotel | H39: 1
D40: 5 | E40: 45990 | F40: SÁBADO - Día libre
D41: 6 | E41: 45991 | F41: DOMINGO - Día libre
D42: 7 | E42: 45992 | F42: LUNES - Día libre
...

Sheet RVA249-1 -1-COSTEO
Z2: Libro diario contable
D3: PAGOS | R3: PAGOS | W3: ESTADO DE CUENTA | Z3: PAGOS
B4: SHANELLA | C4: DEA | D4: Contabilidad | E4: Operativo | F4: CONCEPTO | G4: Proveedor | H4: Valor | I4: Días | J4: SHANELLA | K4: DEA | M4: SHANELLA | N4: DEA | O4: SHANELLA | P4: DEA | R4: SHANELLA | S4: DEA | T4: Retención en la fuente | U4: Valor pagado | W4: Valor Neto cobrado al cliente | X4: DIFERENCIA | Z4: PROVEEDOR - NOMBRE COMERCIAL | AA4: ID | AB4: Fecha del pago | AC4: Valor del pago | AD4: Forma de pago de donde salió el dinero | AE4: Tipo de movimiento | AF4: Comentarios
B5: SHANELLA | C5: DEA | F5: Póliza de asistencia médica al viajero - producto visitor por 06 días | G5: Colasistencia | H5: 3500 | I5: 6 | J5: =H5*I5 -> 21000 | K5: =H5*I5 -> 21000 | M5: =J5/0.7 -> 30000 | N5: =K5/0.7 -> 30000 | O5: =M5/$I$70 -> 8.1081081 | P5: =N5/$I$70 -> 8.1081081
F6: Sim card física | H6: 7000 | I6: 0 | J6: =H6*I6 -> 0 | M6: =J6/0.7 -> 0 | O6: =M6/$I$70 -> 0
F7: Recarga 10 gigas de datos | H7: 12000 | I7: 0 | J7: =H7*I7 -> 0 | M7: =J7/0.7 -> 0 | O7: =M7/$I$70 -> 0
F8: Traslado aeropuerto - hotel - aeropuerto en CARRO | H8: 151000 | I8: 0 | J8: =H8*I8 -> 0 | M8: =J8/0.95 -> 0 | O8: =M8/$I$70 -> 0
F9: PAQUETE DE CHEQUEO MÉDICO - Servicios incluidos color azul | J9: 1350000 | K9: 1350000 | O9: 485 | P9: 485
F10: LABORATORIOS CLÍNICOS
B11: SHANELLA | C11: DEA | F11: Citología
B12: SHANELLA | C12: DEA | F12: Coprológico
B13: SHANELLA | C13: DEA | F13: Vitamina D25
B14: SHANELLA | C14: DEA | F14: Vitamina B12
F15: Perfil lipídico
B16: SHANELLA | C16: DEA | F16: Colesterol HDL
B17: SHANELLA | C17: DEA | F17: Colesterol LDL
B18: SHANELLA | C18: DEA | F18: Colesterol total
B19: SHANELLA | C19: DEA | F19: Triglicéridos
F20: Perfil Hepático
B21: SHANELLA | C21: DEA | F21: ALT- Alanina transferasa
B22: SHANELLA | C22: DEA | F22: AST - aspartato transferasa
B23: SHANELLA | C23: DEA | F23: Bilirrubina total y directa
B24: SHANELLA | C24: DEA | F24: Gama Glutamil transferasa
F25: Perfil Renal
B26: SHANELLA | C26: DEA | F26: Creatinina
B27: SHANELLA | F27: e-GFR | H27: 10000 | I27: 1 | J27: =H27*I27 -> 10000 | K27: No | M27: =J27/0.6 -> 16666.667 | N27: No | O27: =M27/$I$70 -> 4.5045045 | P27: No
B28: SHANELLA | C28: DEA | F28: Uroanálisis
B29: SHANELLA | C29: DEA | F29: Nitrógeno Ureico en Sangre (BUN)
F30: Sangre
B31: SHANELLA | C31: DEA | F31: Hemograma completo
B32: SHANELLA | C32: DEA | F32: Hemoglobina glicosilada
B33: SHANELLA | C33: DEA | F33: Ferritina
B34: SHANELLA | C34: DEA | F34: Glucosa sérica
F35: Perfil Tiroideo
B36: SHANELLA | C36: DEA | F36: T4 libre
B37: SHANELLA | C37: DEA | F37: TSH
B38: SHANELLA | F38: Paratohormona | H38: 116000 | I38: 1 | J38: =H38*I38 -> 116000 | K38: No | M38: =J38/0.8 -> 145000 | N38: No | O38: =M38/$I$70 -> 39.189189 | P38: No
F39: Enfermedades de transmisión sexual
B40: SHANELLA | C40: DEA | F40: VDRL serología
B41: SHANELLA | C41: DEA | F41: VIH 1 Y 2, Anticuerpos
...

Sheet RVA249-1 -2-COSTEO
Z2: Libro diario contable
D3: PAGOS | R3: PAGOS | W3: ESTADO DE CUENTA | Z3: PAGOS
B4: SHANELLA | C4: DEA | D4: Contabilidad | E4: Operativo | F4: CONCEPTO | G4: Proveedor | H4: Valor | I4: Días | J4: SHANELLA | K4: DEA | M4: SHANELLA | N4: DEA | O4: SHANELLA | P4: DEA | R4: SHANELLA | S4: DEA | T4: Retención en la fuente | U4: Valor pagado | W4: Valor Neto cobrado al cliente | X4: DIFERENCIA | Z4: PROVEEDOR - NOMBRE COMERCIAL | AA4: ID | AB4: Fecha del pago | AC4: Valor del pago | AD4: Forma de pago de donde salió el dinero | AE4: Tipo de movimiento | AF4: Comentarios
B5: SHANELLA | C5: DEA | F5: Póliza de asistencia médica al viajero - producto visitor por 06 días | G5: Colasistencia | H5: 3500 | I5: 6 | J5: =H5*I5 -> 21000 | K5: =H5*I5 -> 21000 | M5: =J5/0.7 -> 30000 | N5: =K5/0.7 -> 30000 | O5: =M5/$I$67 -> 8.1081081 | P5: =N5/$I$67 -> 8.1081081
F6: Sim card física | H6: 7000 | I6: 0 | J6: =H6*I6 -> 0 | M6: =J6/0.7 -> 0 | O6: =M6/$I$67 -> 0
F7: Recarga 10 gigas de datos | H7: 12000 | I7: 0 | J7: =H7*I7 -> 0 | M7: =J7/0.7 -> 0 | O7: =M7/$I$67 -> 0
F8: Traslado aeropuerto - hotel - aeropuerto en CARRO | H8: 151000 | I8: 0 | J8: =H8*I8 -> 0 | M8: =J8/0.95 -> 0 | O8: =M8/$I$67 -> 0
F9: PAQUETE DE CHEQUEO MÉDICO - Servicios incluidos color azul | J9: 965000 | O9: 485
F10: LABORATORIOS CLÍNICOS
B11: SHANELLA | F11: Citología
B12: SHANELLA | F12: Coprológico
B13: SHANELLA | F13: Vitamina D25
B14: SHANELLA | F14: Vitamina B12
F15: Perfil lipídico
B16: SHANELLA | F16: Colesterol HDL
B17: SHANELLA | F17: Colesterol LDL
B18: SHANELLA | F18: Colesterol total
B19: SHANELLA | F19: Triglicéridos
F20: Perfil Hepático
B21: SHANELLA | F21: ALT- Alanina transferasa
B22: SHANELLA | F22: AST - aspartato transferasa
B23: SHANELLA | F23: Bilirrubina total y directa
B24: SHANELLA | F24: Gama Glutamil transferasa
F25: Perfil Renal
B26: SHANELLA | F26: Creatinina
B27: SHANELLA | F27: e-GFR | H27: 10000 | I27: 1 | J27: =H27*I27 -> 10000 | K27: No | M27: =J27/0.6 -> 16666.667 | N27: No | O27: =M27/$I$67 -> 4.5045045 | P27: No
B28: SHANELLA | F28: Uroanálisis
B29: SHANELLA | F29: Nitrógeno Ureico en Sangre (BUN)
F30: Sangre
B31: SHANELLA | F31: Hemograma completo
B32: SHANELLA | F32: Hemoglobina glicosilada
B33: SHANELLA | F33: Ferritina
B34: SHANELLA | F34: Glucosa sérica
F35: Perfil Tiroideo
B36: SHANELLA | F36: T4 libre
B37: SHANELLA | F37: TSH
B38: SHANELLA | F38: Paratohormona | H38: 116000 | I38: 1 | J38: =H38*I38 -> 116000 | K38: No | M38: =J38/0.8 -> 145000 | N38: No | O38: =M38/$I$67 -> 39.189189 | P38: No
F39: Enfermedades de transmisión sexual
B40: SHANELLA | F40: VDRL serología
B41: SHANELLA | F41: VIH 1 Y 2, Anticuerpos
...

Sheet DETALLE SERVICIOS
B3: Paquete de chequeo médico
B4: Servicios Médical Trip Colombia, no se puede retirar de la cotización
B5: Servicios para decidir sí los desea realizar o no
B7: DETALLE DE LOS SERVICIOS
B8: ='RVA249-1 -1-COSTEO'!F4 -> CONCEPTO | C8: ='RVA249-1 -1-COSTEO'!O4 -> SHANELLA | D8: ='RVA249-1 -1-COSTEO'!P4 -> DEA
B9: ='RVA249-1 -1-COSTEO'!F9 -> PAQUETE DE CHEQUEO MÉDICO - Servicios incluidos color azul | C9: ='RVA249-1 -1-COSTEO'!O9 -> 485
B10: ='RVA249-1 -1-COSTEO'!F10 -> LABORATORIOS CLÍNICOS | C10: ='RVA249-1 -1-COSTEO'!O10 | D10: ='RVA249-1 -1-COSTEO'!P10
B11: ='RVA249-1 -1-COSTEO'!F11 -> Citología | C11: ='RVA249-1 -1-COSTEO'!O11 | D11: ='RVA249-1 -1-COSTEO'!P11
B12: ='RVA249-1 -1-COSTEO'!F12 -> Coprológico | C12: ='RVA249-1 -1-COSTEO'!O12 | D12: ='RVA249-1 -1-COSTEO'!P12
B13: ='RVA249-1 -1-COSTEO'!F13 -> Vitamina D25 | C13: ='RVA249-1 -1-COSTEO'!O13 | D13: ='RVA249-1 -1-COSTEO'!P13
B14: ='RVA249-1 -1-COSTEO'!F14 -> Vitamina B12 | C14: ='RVA249-1 -1-COSTEO'!O14 | D14: ='RVA249-1 -1-COSTEO'!P14
B15: ='RVA249-1 -1-COSTEO'!F15 -> Perfil lipídico | C15: ='RVA249-1 -1-COSTEO'!O15 | D15: ='RVA249-1 -1-COSTEO'!P15
B16: ='RVA249-1 -1-COSTEO'!F16 -> Colesterol HDL | C16: ='RVA249-1 -1-COSTEO'!O16 | D16: ='RVA249-1 -1-COSTEO'!P16
B17: ='RVA249-1 -1-COSTEO'!F17 -> Colesterol LDL | C17: ='RVA249-1 -1-COSTEO'!O17 | D17: ='RVA249-1 -1-COSTEO'!P17
B18: ='RVA249-1 -1-COSTEO'!F18 -> Colesterol total | C18: ='RVA249-1 -1-COSTEO'!O18 | D18: ='RVA249-1 -1-COSTEO'!P18
B19: ='RVA249-1 -1-COSTEO'!F19 -> Triglicéridos | C19: ='RVA249-1 -1-COSTEO'!O19 | D19: ='RVA249-1 -1-COSTEO'!P19
B20: ='RVA249-1 -1-COSTEO'!F20 -> Perfil Hepático | C20: ='RVA249-1 -1-COSTEO'!O20 | D20: ='RVA249-1 -1-COSTEO'!P20
B21: ='RVA249-1 -1-COSTEO'!F21 -> ALT- Alanina transferasa | C21: ='RVA249-1 -1-COSTEO'!O21 | D21: ='RVA249-1 -1-COSTEO'!P21
... B64: ='RVA249-1 -1-COSTEO'!F64 -> Servicios Medical Trip Colombia: Póliza al viajero por dos días - Acompañamiento Virtual y presencial | C64: ='RVA249-1 -1-COSTEO'!O64 | D64: ='RVA249-1 -1-COSTEO'!P64
B65: ='RVA249-1 -1-COSTEO'!F5 -> Póliza de asistencia médica al viajero - producto visitor por 06 días | C65: ='RVA249-1 -1-COSTEO'!O5 -> 8.1081081 | D65: ='RVA249-1 -1-COSTEO'!P5 -> 8.1081081
B66: ='RVA249-1 -1-COSTEO'!F65 -> Servicios Medical Trip Colombia: Acompañamiento Virtual y presencial servicios adicionales al chequeo médico | C66: ='RVA249-1 -1-COSTEO'!O65 -> 27.027027 | D66: No
B67: Impuesto bancario 4 * 1000 | C67: 2 | D67: ='RVA249-1 -1-COSTEO'!P66
B68: TOTAL A PAGAR EN DÓLARES | C68: =SUM(C9:C67) -> 1235.4866 | D68: =SUM(D9:D67) -> 30.630631

Sheet CONFIRMACIÓN PAX 1

Sheet VUELO
