Workbook

Sheet PASAPORTE DATOS 
A18: Nombre | B18: HERMELINE | D18: Nombre | G18: Nombre
A19: Nombre | D19: Nombre | G19: Nombre
A20: Apellido | B20: BAZUR | D20: Apellido | G20: Nombre
A21: Apellido de casada | D21: Apellido de casada | G21: Apellido
A22: Género: . | B22: Femenino | D22: Género: . | G22: Apellido de casada
A23: Pasaporte | B23: NMFD9P7R5 | D23: Pasaporte | G23: Género: .
A24: Fecha de nacimiento | B24: 19 de julio 1973 | D24: Fecha de nacimiento | G24: Pasaporte
A25: Edad | B25: 52 | D25: Edad | G25: Fecha de nacimiento
A26: Estado civil | B26: Soltera | D26: Estado civil | G26: Edad
A27: Dirección | B27: R.Kaya Epidendrum 35, Curazao | D27: Dirección | G27: Estado civil
A28: Nacionalidad y domicilio: | B28: Curazao | D28: Nacionalidad y domicilio: | G28: Dirección
A29: Email: | B29: Thinktwice34@hotmail.com | D29: Email: | G29: Nacionalidad y domicilio:
A30: Teléfono | B30: 599 9 5209836 | D30: Teléfono | G30: Email:
A31: Profesión | D31: Profesión | G31: Teléfono
A32: RH | B32: O + | D32: RH | G32: Profesión
A33: Seguro | B33: SVB | D33: Seguro | G33: RH
A34: Peso | D34: Peso | G34: Seguro
A35: Altura | D35: Altura | G35: Peso
A36: Idioma | B36: Español, Inglés, Francés y Papiamento | D36: Idioma | G36: Altura
A37: Estadia: | G37: Idioma
D38: Salud
G39: Salud

Sheet ITINERARIO
B3: ITINERARIO:
B4: Dia | C4: Fecha | D4: Hora | E4: Actividad | F4: ACP horas | G4: Traslado cerca | H4: Traslado lejos
C5: 1
E6: Vuelo Curazao - Medellín
E7: Traslado a aeropuerto - hotel
E8: Alojamiento
E11: No desayunar
E12: Traslado Hotel - Centro médico | F12: 0.5 | G12: 1
E13: Toma de muestras de sangre laboratorio clínico
E14: Ecografía de abdomen total
E15: Citología
E16: Mamografía
E17: Radiografía de tórax
E18: Radiografía pie derecho e izquierdo
E19: Electrocardiograma
E20: Traslado Centro médico - Hotel | G20: 1
E21: Día libre
E25: Desayuno en el hotel
E26: Traslado hotel - aeropuerto
E27: Vuelo internacional Curazao - Medellín
F28: =SUM(F5:F27) -> 0.5 | G28: =SUM(G5:G27) -> 2 | H28: =SUM(H5:H27) -> 0

Sheet COSTEO
Y2: Libro diario contable | AG2: Factura electrónica
C3: PAGOS | Q3: PAGOS | V3: ESTADO DE CUENTA | Y3: PAGOS | AG3: FACTURA
B4: ACV documentos | C4: Contabilidad | D4: Operativo | E4: Concepto | F4: Proveedor | G4: Valor | H4: Días | I4: HERMELINE | J4: PAX 2 | L4: HERMELINE | M4: PAX 2 | N4: HERMELINE | O4: PAX 2 | S4: Retención en la fuente | T4: Valor pagado | V4: Valor Neto cobrado al cliente | W4: DIFERENCIA | Y4: PROVEEDOR - NOMBRE COMERCIAL | Z4: ID | AA4: Fecha del pago | AB4: Valor del pago | AC4: Forma de pago de donde salió el dinero | AD4: Tipo de movimiento | AE4: Comentarios | AG4: Fecha de la factura | AH4: FACTURA O CUENTA COBRO | AI4: VALOR REAL DE LA FACTURA | AJ4: CONCEPTO | AL4: CONCEPTO
E5: Póliza de asistencia médica al viajero - producto visitor por 07 días | F5: Colasistencia | I5: =G5*H5 -> 0 | J5: =G5*H5 -> 0 | L5: =I5/0.7 -> 0 | M5: =J5/0.7 -> 0 | N5: =L5/$H$72 -> 0 | O5: =M5/$H$72 -> 0
E6: PAQUETE DE CHEQUEO MÉDICO | I6: 1300000 | N6: 485
E7: LABORATORIOS CLÍNICOS
D8: ok | E8: Citología cervical
E9: Coprológico
D10: ok | E10: Vitamina D25
D11: ok | E11: Vitamina B12
E12: Perfil lipídico
D13: ok | E13: Colesterol HDL
D14: ok | E14: Colesterol LDL
D15: ok | E15: Colesterol total
D16: ok | E16: Triglicéridos
E17: Perfil Hepático
D18: ok | E18: ALT- Alanina transferasa
D19: ok | E19: AST - aspartato transferasa
E20: Bilirrubina total y directa
E21: Gama Glutamil transferasa
E22: Perfil Renal
D23: ok | E23: Creatinina
D24: ok | E24: e-GFR | G24: 10000 | H24: 1 | I24: =G24*H24 -> 10000 | L24: =I24/0.6 -> 16666.667 | N24: =L24/$H$72 -> 4.3859649
D25: ok | E25: Uroanálisis
E26: Nitrógeno Ureico en Sangre (BUN)
E27: Sangre
D28: ok | E28: Hemograma completo
D29: ok | E29: Hemoglobina glicosilada
D30: ok | E30: Ferritina
D31: ok | E31: Glucosa sérica
D32: ok | E32: Frotis de sangre periférica - (extendido de sangre periférica estudio de morfología) | G32: 45000 | H32: 1 | I32: =G32*H32 -> 45000 | L32: =I32/0.6 -> 75000 | N32: =L32/$H$72 -> 19.736842
D33: ok | E33: Test de sicklemia: (Células Falciformes-drepanocitosis) | G33: 40000 | H33: 1 | I33: =G33*H33 -> 40000 | L33: =I33/0.6 -> 66666.667 | N33: =L33/$H$72 -> 17.54386
E34: Perfil Tiroideo
D35: ok | E35: T4 libre
D36: ok | E36: TSH
D37: ok | E37: Paratohormona | G37: 116000 | H37: 1 | I37: =G37*H37 -> 116000 | L37: =I37/0.8 -> 145000 | N37: =L37/$H$72 -> 38.157895
E38: Enfermedades de transmisión sexual
D39: ok | E39: VDRL
D40: ok | E40: VIH 1 Y 2, Anticuerpos
E41: Minerales
...

Sheet DETALLE SERVICIOS
C4: DETALLE DE LOS SERVICIOS
C5: CONCEPTO | D5: =COSTEO!N4 -> HERMELINE | E5: =COSTEO!O4 -> PAX 2
C6: =COSTEO!E6 -> PAQUETE DE CHEQUEO MÉDICO | D6: =COSTEO!N6 -> 485 | E6: =COSTEO!O7
C7: =COSTEO!E7 -> LABORATORIOS CLÍNICOS | D7: =COSTEO!N7 | E7: =COSTEO!O8
C8: =COSTEO!E8 -> Citología cervical | D8: =COSTEO!N8 | E8: =COSTEO!O9
C9: =COSTEO!E9 -> Coprológico | D9: =COSTEO!N9 | E9: =COSTEO!O10
C10: =COSTEO!E10 -> Vitamina D25 | D10: =COSTEO!N10 | E10: =COSTEO!O11
C11: =COSTEO!E11 -> Vitamina B12 | D11: =COSTEO!N11 | E11: =COSTEO!O12
C12: =COSTEO!E12 -> Perfil lipídico | D12: =COSTEO!N12 | E12: =COSTEO!O13
C13: =COSTEO!E13 -> Colesterol HDL | D13: =COSTEO!N13 | E13: =COSTEO!O14
C14: =COSTEO!E14 -> Colesterol LDL | D14: =COSTEO!N14 | E14: =COSTEO!O15
C15: =COSTEO!E15 -> Colesterol total | D15: =COSTEO!N15 | E15: =COSTEO!O16
C16: =COSTEO!E16 -> Triglicéridos | D16: =COSTEO!N16 | E16: =COSTEO!O17
C17: =COSTEO!E17 -> Perfil Hepático | D17: =COSTEO!N17 | E17: =COSTEO!O18
... C60: =COSTEO!E60 -> Consulta con VIRTUAL DE CONTROL DR Marcos Yepes | D60: =COSTEO!N60 -> 83.102493 | E60: =COSTEO!O61
C61: =COSTEO!E61 -> Consulta con VIRTUAL DE NUTRICIÓN Y PSICO NUTRICIÓN | D61: =COSTEO!N61 -> 149.58449
C62: =COSTEO!E62 -> Consulta con GLACOMATOLOGO Incluye exámen de Optometría | D62: =COSTEO!N62 -> No | E62: =COSTEO!O62 -> 81.871345
C63: =COSTEO!E63 -> Tomografía de coherencia óptica (OCT): | D63: =COSTEO!N63 -> No | E63: =COSTEO!O63 -> 114.55108
C64: =COSTEO!E64 -> Tarros para + orina uroanalisis y fecal | D64: =COSTEO!N64 -> 3.5087719 | E64: =COSTEO!O65
C65: =COSTEO!E65 -> 04 Traslados hotel - clínica por trayecto Cortos - cerca adicionales | D65: =COSTEO!N65 -> 44.32133 | E65: =COSTEO!O66
C66: =COSTEO!E66 -> Servicios Medical Trip Colombia: Acompañamiento Virtual | D66: =COSTEO!N66 -> 24.930748
C67: =COSTEO!E67 -> Servicios Medical Trip Colombia: Acompañamiento presencial | D67: =COSTEO!N67 -> 24.930748 | E67: =COSTEO!O67 -> 10
C68: 4 * 1000 Impuesto bancario en Colombia | D68: =COSTEO!N71 -> 6.4697368 | E68: =COSTEO!O71 -> 0.82573099
C69: TOTAL A PAGAR EN DÓLARES AMERICANOS | D69: =SUM(D6:D68) -> 1623.9682 | E69: =SUM(E6:E68) -> 207.24816
C70: =COSTEO!E70
C71: =COSTEO!E71
C72: =COSTEO!E72 | D72: =COSTEO!N73 | E72: =COSTEO!O73
C73: =COSTEO!E73 | D73: =COSTEO!N74 | E73: =COSTEO!O74
C74: =COSTEO!E74 | D74: =COSTEO!N75 | E74: =COSTEO!O75
C75: =COSTEO!E75 -> EXÁMENES OPCIONALES DE LABORATORIO CLÍNICO | E75: =COSTEO!O76
C76: =COSTEO!E76 -> CA 19-9 Antígeno de cáncer de tubo digestivo | D76: 18
C77: =COSTEO!E77 -> CA-125 - Antígeno de cáncer de ovario | D77: 25
C78: =COSTEO!E78 -> CEA (carcinoembrionario Antígeno) | D78: 20
C79: =COSTEO!E79 -> AFP (Alfa fetoproteína) | D79: 18
C80: =COSTEO!E80 | D80: =COSTEO!N81 | E80: =COSTEO!O81
C81: =COSTEO!E81 | D81: =COSTEO!N82 | E81: =COSTEO!O82
C82: =COSTEO!E82 | D82: =COSTEO!N83 | E82: =COSTEO!O83
C83: =COSTEO!E83 | D83: =COSTEO!N84 | E83: =COSTEO!O84
C84: =COSTEO!E84 | D84: =COSTEO!N85 | E84: =COSTEO!O85
C85: =COSTEO!E85 | D85: =COSTEO!N86 | E85: =COSTEO!O86
...

Sheet CONFIRMACIÓN PAX 1

Sheet VUELO

Sheet CARPETA - ARCHIVO
A3: ARCHIVO DIGITAL | B3: LABORATORIOS CLÍNICOS | C3: ARCHIVO DIGITAL | D3: IMÁGENES DIAGNÓSTICAS | E3: ARCHIVO DIGITAL | F3: ESPECIALISTAS
