Workbook

Sheet PASAPORTES
A19: Nombre 1 | B19: REEMY | C19: Pasaporte | D19: NU8RDD5P0 | G19: Nombre 1 | H19: ANTHONY | M19: NO VIAJO
A20: Nombre 2 | B20: BREDLEY | C20: Fecha de nacimiento | D20: 27917 | G20: Nombre 2 | H20: LORETO | M20: Nombre 1 | N20: WILLET | O20: Pasaporte | P20: NY2CD34L2
A21: Apellido | B21: POPPEN | C21: Edad | D21: =2025-1976 -> 49 | G21: Apellido | H21: BRAAFHART | M21: Nombre 2 | O21: Fecha de nacimiento | P21: 27427
A22: País | B22: Curazao | G22: País | H22: CURAZAO | M22: Apellido | N22: PETERNELLA | O22: Edad | P22: 50
A23: Email: | B23: r.poppen@gmail.com | G23: Pasaporte | H23: NY5KHJH23 | M23: País | N23: Curazao
A24: Teléfono | B24: 59995230179 | G24: Fecha de nacimiento | H24: 22625 | M24: Email: | N24: aulinepeternella@gmail.com
G25: Edad | H25: 63 | M25: Teléfono | N25: 59995652026
G26: Email: | H26: langetpouwpouw@gmail.com
G27: Teléfono | H27: 599 9 521 0899
G28: Peso | H28: 87
G29: Altura | H29: 174
G30: Padre | H30: General Maduro
G31: Madre | H31: Fallecida
A45: Nombre 1 | B45: RAISON | C45: Pasaporte | D45: NUK8RP3R5 | G45: Nombre 1 | I45: Pasaporte
A46: Nombre 2 | B46: MARCELO | C46: Fecha de nacimiento | D46: 30332 | G46: Nombre 2 | I46: Fecha de nacimiento
A47: Apellido | B47: GURIBALDI | C47: Edad | D47: 42 | G47: Apellido | I47: Edad
A48: País | B48: Curazao | G48: País
A49: Email: | B49: raisonguribaldi@gmail.com | G49: Email:
A50: Teléfono | B50: 59995183047 | G50: Teléfono

Sheet CARPETA - ARCHIVO
A3: ANTHONY | G3: REEMY
A4: ARCHIVO DIGITAL | B4: LABORATORIOS CLÍNICOS | C4: ARCHIVO DIGITAL | D4: IMÁGENES DIAGNÓSTICAS | E4: ARCHIVO DIGITAL | F4: Especialista | G4: ARCHIVO DIGITAL | H4: IMÁGENES DIAGNÓSTICAS | I4: ARCHIVO DIGITAL | J4: Especialista
A5: ok | B5: Antígeno de próstata | C5: ok | D5: Tomografía de abdomen y pélvis | E5: ok | F5: Cardiologo | G5: ok | H5: Procedimiento de flasma de rodillas | I5: ok | J5: Especialista en Músculo esquelético
A6: ok | B6: Coprológico | C6: ok | D6: Radiografía de tórax | E6: ok | F6: Gastroenterologo
A7: ok | B7: Vitamina D25 | C7: ok | D7: Ecocardiografía | E7: ok | F7: Neurologo
A8: ok | B8: Vitamina B12 | C8: ok | D8: Prueba de esfuerzo | E8: ok | F8: Fisiatra
B9: Perfil lipídico | C9: ok | D9: Electrocardiograma | E9: ok | F9: Urologo
A10: ok | B10: Colesterol HDL | C10: ok | D10: Ecografía prostática Trasrectal | E10: ok | F10: Medico Funcional
A11: ok | B11: Colesterol LDL | C11: ok | D11: Esofagogastroduodenoscopia preferiblemente bajo sedación
A12: ok | B12: Colesterol total | C12: ok | D12: Electromiografía y velocidad de conducción nerviosa de los músculos faciales y nervios faciales
A13: ok | B13: Triglicéridos | C13: ok | D13: Resultado de Biopsia
B14: Perfil Hepático
A15: ok | B15: ALT- Alanina transferasa
A16: ok | B16: AST - aspartato transferasa
A17: ok | B17: Bilirrubina total y directa
A18: ok | B18: Gamma glutamil transferasa
B19: Perfil Renal
A20: ok | B20: Creatinina
A21: ok | B21: Uroanálisis
A22: ok | B22: Nitrógeno Ureico en Sangre (BUN)
B23: Sangre
A24: ok | B24: Hemograma completo
A25: ok | B25: Ferritina
A26: ok | B26: Glucosa sérica
B27: Perfil Tiroideo
A28: ok | B28: T4 total
A29: ok | B29: TSH
B30: Enfermedades de transmisión sexual
A31: ok | B31: VDRL
A32: ok | B32: VIH 1 Y 2, Anticuerpos
A33: ok | B33: Hemoglobina Glicosilada
A34: ok | B34: Ionograma: calcio - sodio - fósforo - potasio
A35: ok | B35: Homocisteína
A36: ok | B36: Parathormona
A37: ok | B37: HEPATITIS A ANTICUERPOS TOTALES SEMIAUTOMATIZADO O AUTOMATIZADO
A38: ok | B38: HEPATITIS B ANTICUERPOS CENTRAL TOTALES [ANTI-CORE HBC] SEMIAUTOMATIZADO O AUTOMAT1
A39: ok | B39: HEPATITIS B ANTICUERPOS S [ANTI-HBS] SEMIAUTOMATIZADO O AUTOMATIZADO
A40: ok | B40: HEPATITIS B ANTÍGENO DE SUPERFICIE [AG HBS]
A41: ok | B41: HEPATITIS C, ANTICUERPO [ANTI-HVC]

Sheet ITINERARIO
C4: ITINERARIO:
D5: 1 | E5: 45878 | F5: SÁBADO | G5: ACP REEMY | H5: TRASLADOS REEMY | I5: ACP ANTHONY | J5: TRASLADOS ANTHONY CERCA | K5: TRASLADOS ANTHONY LEJOS
E6: 07:00 pm | F6: Llegada vuelo internacional Curazao - Medellín
B7: TAXI VAN | C7: confirmada | F7: Traslado aeropuerto - hotel Minivan
B8: Hotel Novelty | C8: confirmada | F8: Alojamiento
D9: 2 | E9: 45879 | F9: DOMINGO
F10: NO DESAYUNAR
B11: AEROTUREX | C11: confirmada | E11: 09:00 am | F11: Traslado hotel - clínica | I11: 0.5 | J11: 1
A12: Calle 80 | B12: IVS | C12: confirmada | D12: Anthony | E12: 10:00 am | F12: Tomografía de abdomen y pélvis
A13: Calle 80 | B13: IVS | C13: confirmada | D13: Anthony | E13: 10:30 am | F13: Radiografía de tórax
B14: AEROTUREX | C14: confirmada | E14: 11:00 am | F14: Traslado clínica - clínica | J14: 1
F15: Desayuno en el hotel
F16: DÍA LIBRE
D17: 3 | E17: 45880 | F17: LUNES
E18: 06:00 am | F18: Comer fruta - jugo - caldo comida ligera
B19: AEROTUREX | C19: confirmada | E19: 09:00 am | F19: Traslado hotel - clínica | I19: 0.5 | J19: 1
A20: Las Vegas | B20: Incare | C20: confirmada | D20: Anthony | E20: 09:30 am | F20: Ecocardiografía
A21: Las Vegas | B21: Incare | C21: confirmada | D21: Anthony | E21: 09:45 am | F21: Prueba de esfuerzo
A22: Las Vegas | B22: Incare | C22: confirmada | D22: Anthony | E22: 11:00 am | F22: Electrocardiograma
A23: Las Vegas | B23: Incare | C23: confirmada | D23: Anthony | E23: 11:30 am | F23: Consulta con especialista en CARDIOLOGÍA
F24: Toma de muestras de sangre para laboratorios
B25: Carolina | E25: 01:20 pm | F25: Traslado clínica - hotel | J25: 1
F26: TARDE LIBRE
D27: 4 | E27: 45881 | F27: MARTES
F28: NO DESAYUNAR - NO AGUA
B29: Yenny | C29: Confirmado | D29: Anthony | E29: 08:00 am | F29: Traslado hotel - clínica | I29: 0.5 | J29: 1
A30: Las Vegas | B30: Echavarria | C30: Confirmado | D30: Anthony | E30: 08:30 am | F30: Toma de muestras de sangre para laboratorios
C31: Confirmado | D31: Anthony | F31: Traslado centro médico - centro médico
A32: Calle 80 las américas | B32: Unidad Gastroenterológica | C32: Confirmado | D32: Anthony | E32: 10:00 am | F32: Endoscopia con sedación
B33: Yenny | C33: Confirmado | D33: Anthony | E33: 11:00 am | F33: Traslado clínica hotel | J33: 1
D34: Anthony | E34: 11:30 am | F34: Tiempo para comer
D35: Anthony | F35: No comer nada más
D36: Anthony | F36: Tiempo para descansar
D37: Anthony | E37: 02:00 pm | F37: Tiempo para hacer limpieza con enema
B38: Yenny | C38: Confirmado | D38: Reemy | E38: 01:30 pm | F38: Traslado hotel - clínica | G38: 0.5 | H38: 1
A39: Poblado sector Patio Bonito | B39: Resonancia especializada Cra 46 #7-211 | C39: confirmado | D39: Reemy | E39: 02:20 pm | F39: Resonancia de dos rodillas
B40: Yenny | C40: Confirmado | D40: Reemy | E40: 03:30 pm | F40: Traslado clínica hotel | H40: 1
D41: Anthony | E41: 05:00 pm | F41: Traslado hotel - clínica
B42: Las Vegas | C42: Confirmado | D42: Anthony | E42: 05:30 pm | F42: Ecografía prostática
D43: Anthony | E43: 06:30 pm | F43: Traslado clínica hotel
...

Sheet PROXIMO VIAJE

Sheet RVA011-7-COSTEO
AC3: Libro diario contable
C4: PAGOS | P4: 3800 | T4: PAGOS | Z4: ESTADO DE CUENTA | AC4: PAGOS
B5: ACV documentos | C5: Contabilidad | D5: Operativo | E5: Concepto | F5: Proveedor | G5: Valor | H5: Días | I5: Empresa | J5: Reemy | K5: Anthony | L5: Raison | N5: Comisionable | O5: Empresa | P5: Reemy | Q5: Anthony | R5: Raison | T5: Reemy | U5: Anthony | W5: Retención en la fuente | X5: Valor pagado | Z5: Valor Neto cobrado al cliente | AA5: DIFERENCIA | AC5: PROVEEDOR - NOMBRE COMERCIAL | AD5: ID | AE5: Fecha del pago | AF5: Valor del pago | AG5: Forma de pago de donde salió el dinero | AH5: Tipo de movimiento | AI5: Comentarios
B6: e-mail | C6: Facturado | D6: Comprado | E6: Compra de 50 bolsos | G6: =((38500+(38500*19%))) -> 45815 | H6: 50 | I6: =G6*H6 -> 2290750 | N6: =I6 -> 2290750 | O6: =N6/$P$4 -> 602.82895
B7: e-mail | C7: Facturado | D7: Confirmado | E7: Costo de envío de los bolsos desde Bogotá a Medellín | G7: 70000 | H7: 1 | I7: =G7*H7 -> 70000 | N7: =I7/0.8 -> 87500 | O7: =N7/$P$4 -> 23.026316
C8: Facturado | D8: Confirmado | E8: Medical Trip Colombia - servicios de cotización , compra de los bolsos | G8: 200000 | H8: 1 | I8: =G8*H8 -> 200000 | N8: =I8/0.8 -> 250000 | O8: =N8/$P$4 -> 65.789474
B9: e-mail | C9: DSM 125 | D9: Emitido | E9: Tres tiquetes aéreo vía wingo en tarifa economica full | F9: Copa Airlines | H9: 1 | J9: 2842060 | K9: 2842060 | L9: 2842060 | N9: 2842060 | P9: 680 | Q9: 680 | R9: 680
B10: e-mail | C10: DSM 125 | D10: Confirmado | E10: Tarifa administrativa emisión de tiquetes | F10: Copa Airlines | H10: 1 | J10: 139400 | K10: 139400 | L10: 139400 | N10: 139400 | P10: 40 | Q10: 40 | R10: 40
B11: e-mail | C11: DSM 126 | D11: Emitido | E11: Cambio de nombre del pasajero | F11: Wingo | H11: 1 | K11: =100*4170 -> 417000 | N11: =K11 -> 417000 | Q11: 100
B12: e-mail | C12: Facturado | D12: Emitido | E12: Póliza de asistencia médica al viajero | F12: Colasistencia | G12: 3500 | H12: 8 | J12: =G12*H12 -> 28000 | K12: =G12*H12 -> 28000 | L12: =G12*H12 -> 28000 | N12: =J12/0.45 -> 62222.222 | P12: =N12/$P$4 -> 16.374269 | Q12: =N12/$P$4 -> 16.374269 | R12: =N12/$P$4 -> 16.374269 | T12: =2450*8 -> 19600 | U12: =2450*8 -> 19600 | V12: =2450*8 -> 19600 | W12: 0 | X12: =T12+U12+V12 -> 58800 | Z12: =J12+K12+L12 -> 84000 | AA12: =Z12-T12-U12-V12 -> 25200 | AC12: COLASISTENCIA | AE12: 45875 | AF12: 1265000 | AG12: JURIDICA BANCOLOMBIA | AH12: TRANSFERENCIA
C13: DSM | D13: Comprada | E13: Sim card física | F13: Claro | G13: 6000 | H13: 1 | K13: =G13*H13 -> 6000 | L13: =G13*H13 -> 6000 | N13: =K13/0.4 -> 15000 | Q13: =N13/$P$4 -> 3.9473684 | R13: =N13/$P$4 -> 3.9473684 | U13: 5000 | V13: 5000 | W13: 0 | X13: =T13+U13+V13 -> 10000 | Z13: =K13+L13 -> 12000 | AA13: =Z13-T13-U13-V13 -> 2000 | AC13: YENNY ROBERTO
B14: e-mail | C14: Facturado | D14: Recargada | E14: Recarga de 10 gigas de datos | F14: Claro | G14: 12000 | H14: 1 | J14: =G14*H14 -> 12000 | K14: =G14*H14 -> 12000 | L14: =G14*H14 -> 12000 | N14: =J14/0.4 -> 30000 | P14: =N14/$P$4 -> 7.8947368 | Q14: =N14/$P$4 -> 7.8947368 | R14: =N14/$P$4 -> 7.8947368 | T14: 12000 | U14: 12000 | V14: 12000 | W14: 0 | X14: =T14+U14+V14 -> 36000 | Z14: =J14+K14+L14 -> 36000 | AA14: =Z14-T14-U14-V14 -> 0 | AC14: CLARO | AE14: 44782 | AF14: 36000 | AG14: JURIDICA BANCOLOMBIA | AH14: PSE
B15: REVISAR SALDO A FAVOR | C15: Facturado | D15: Confirmado | E15: Traslado aeropuerto - hotel - aeropuerto en MINIVAN | F15: Taxi van | G15: 305000 | H15: 2 | J15: =G15*H15 -> 610000 | N15: =J15/0.9 -> 677777.78 | P15: =(N15/$P$4)/3 -> 59.454191 | Q15: =P15 -> 59.454191 | R15: =P15 -> 59.454191 | T15: 480000 | W15: 0 | X15: =T15+U15+V15 -> 480000 | Z15: =J15+K15+L15 -> 610000 | AA15: =Z15-T15-U15-V15 -> 130000 | AC15: TAXIVAN | AE15: 44782 | AF15: 240000 | AG15: JURIDICA BANCOLOMBIA | AH15: TRANSFERENCIA
B16: e-mail | C16: Facturado | D16: reserva: NOV4267/NCT2025 | E16: Alojamiento en suite Deluxe Reemy Poppen | F16: Novelty | G16: 434596.82 | H16: 7 | J16: =G16*H16 -> 3042177.8 | N16: =J16 -> 3042177.8 | P16: =N16/$P$4 -> 800.57309 | T16: =N16 -> 3042177.8 | U16: =N17 -> 2682931.4 | V16: =N18 -> 2682885.2 | W16: =(T16+U16+V16)*3.5% -> 294279.8 | X16: =(T16+U16+V16)-W16 -> 8113714.6 | AC16: TAXIVAN | AE16: 45884 | AF16: 220000 | AG16: JURIDICA BANCOLOMBIA | AH16: TRANSFERENCIA
B17: e-mail | C17: Facturado | D17: reserva: NOV4264/NCT2025 | E17: Habitación Individual para una persona Anthony | F17: Novelty | G17: 383275.92 | H17: 7 | K17: =G17*H17 -> 2682931.4 | N17: =K17 -> 2682931.4 | Q17: =N17/$P$4 -> 706.03458 | AC17: NOVELTY SUITES | AF17: 7700000 | AG17: JURIDICA BANCOLOMBIA | AH17: TRANSFERENCIA
B18: e-mail | C18: Facturado | D18: reserva: NOV4266/NCT2025 | E18: Habitación Individual para una persona Raison Guribaldi | F18: Novelty | G18: 383269.32 | H18: 7 | L18: =G18*H18 -> 2682885.2 | N18: =L18 -> 2682885.2 | R18: =N18/$P$4 -> 706.02243 | AC18: NOVELTY SUITES | AE18: RTE RVA011-5 | AF18: 459221 | AG18: SALDO A FAVOR 45.506
E19: PAQUETE DE CHEQUEO MÉDICO | K19: 1200000 | N19: =K19/0.7 -> 1714285.7 | Q19: 450
B20: Archivado | C20: DMS | D20: Confirmado | E20: Entrevista con médico funcional virtual | F20: Marcos Yepes | U20: 150000 | W20: =U20*2% -> 3000 | X20: =U20-W20 -> 147000 | AC20: MARCOS YEPES | AE20: 45868 | AF20: 144000 | AG20: YENNY CAMBIO DOLARES | AH20: DEPOSITO EN BANCO
D21: NO | E21: Domicilio | F21: Echavarria | U21: 624498 | W21: 0 | X21: =U21-W21 -> 624498 | AC21: ECHAVRRIA | AE21: 44782 | AF21: 624498 | AG21: JURIDICA BANCOLOMBIA | AH21: TRANSFERENCIA
B22: e-mail | C22: Facturado | D22: Confirmado | E22: Antígeno de próstata | F22: Echavarria
B23: e-mail | C23: Facturado | D23: Confirmado | E23: Coprológico | F23: Echavarria
B24: e-mail | C24: Facturado | D24: Confirmado | E24: Vitamina D25 | F24: Echavarria
B25: e-mail | C25: Facturado | D25: Confirmado | E25: Vitamina B12 | F25: Echavarria
E26: Perfil lipídico
B27: e-mail | C27: Facturado | D27: Confirmado | E27: Colesterol HDL | F27: Echavarria
B28: e-mail | C28: Facturado | D28: Confirmado | E28: Colesterol LDL | F28: Echavarria
B29: e-mail | C29: Facturado | D29: Confirmado | E29: Colesterol total | F29: Echavarria
B30: e-mail | C30: Facturado | D30: Confirmado | E30: Triglicéridos | F30: Echavarria
E31: Perfil Hepático
B32: e-mail | C32: Facturado | D32: Confirmado | E32: ALT- Alanina transferasa | F32: Echavarria
B33: e-mail | C33: Facturado | D33: Confirmado | E33: AST - aspartato transferasa | F33: Echavarria
B34: e-mail | C34: Facturado | D34: Confirmado | E34: Bilirrubina total y directa | F34: Echavarria
B35: e-mail | C35: Facturado | D35: Confirmado | E35: Gamma glutamil transferasa | F35: Echavarria
E36: Perfil Renal
B37: e-mail | C37: Facturado | D37: Confirmado | E37: Creatinina | F37: Echavarria
B38: e-mail | C38: Facturado | D38: Confirmado | E38: Uroanálisis | F38: Echavarria
B39: e-mail | C39: Facturado | D39: Confirmado | E39: Nitrógeno Ureico en Sangre (BUN) | F39: Echavarria
E40: Sangre
B41: e-mail | C41: Facturado | D41: Confirmado | E41: Hemograma completo | F41: Echavarria
B42: e-mail | C42: Facturado | D42: Confirmado | E42: Ferritina | F42: Echavarria
...

Sheet RVA011-8-COSTEO
U3: Libro diario contable
C4: PAGOS | L4: 3800 | N4: PAGOS | R4: ESTADO DE CUENTA | U4: PAGOS
B5: ACV documentos | C5: Contabilidad | D5: Operativo | E5: Concepto | F5: Proveedor | G5: Valor | H5: Días | I5: Reemy | K5: Comisionable | L5: Reemy | N5: Reemy | O5: Retención en la fuente | P5: Valor pagado | R5: Valor Neto cobrado al cliente | S5: DIFERENCIA | U5: PROVEEDOR - NOMBRE COMERCIAL | V5: ID | W5: Fecha del pago | X5: Valor del pago | Y5: Forma de pago de donde salió el dinero | Z5: Tipo de movimiento | AA5: Comentarios
D6: Confirmado | E6: Aplicación de Plasma en dos rodillas con traslados | G6: 1600000 | H6: 2 | I6: =G6*H6 -> 3200000 | K6: =I6/0.8878 -> 3604415.4 | L6: =K6/$L$4 -> 948.53037 | N6: =2480000/0.98 -> 2530612.2 | O6: =N6*2% -> 50612.245 | P6: =N6-O6 -> 2480000 | R6: =I6 -> 3200000 | S6: =R6-N6 -> 669387.76 | U6: DR. JUAN CAMILO SOTO | W6: 45883 | X6: 2480000 | Y6: JENNY BANCOLOMBIA | Z6: TRANSFERENCIA
D7: Confirmado | E7: Servicios de aplicación de inyección + Medicamentos | G7: 100000 | H7: 1 | I7: =G7*H7 -> 100000 | K7: 100000 | L7: =K7/$L$4 -> 26.315789
D8: Confirmado | E8: Servicios de enfermería 12 horas + fajas | G8: 226000 | H8: 1 | I8: =G8*H8 -> 226000 | K8: 230000 | L8: =K8/$L$4 -> 60.526316
E9: Productos Millicent | G9: 215000 | H9: 1 | I9: =G9*H9 -> 215000 | K9: =I9/0.9 -> 238888.89 | L9: =K9/$L$4 -> 62.865497
D10: Confirmado | E10: Medicamento amiga | G10: 100000 | H10: 1 | I10: =G10*H10 -> 100000 | K10: 150000 | L10: =K10/$L$4 -> 39.473684
K11: TOTAL A PAGAR | L11: =SUM(L6:L10) -> 1137.7117
E14: Saldo a favor
E15: ='RVA011-7-COSTEO'!E77 -> Resonancia de rodilla simple rodilla derecha | F15: ='RVA011-7-COSTEO'!P77 -> 280.70175
E16: ='RVA011-7-COSTEO'!E78 -> Resonancia de rodilla simple rodilla izquierda | F16: ='RVA011-7-COSTEO'!P78 -> 280.70175
F17: =SUM(F15:F16) -> 561.40351
E19: Liquidación | F19: 45884
D20: RVA011-8 | E20: Servicios | F20: =L11 -> 1137.7117
D21: RVA011-7 | E21: Saldo a favor servicios | F21: =F17 -> 561.40351
D22: RVA011-7 | E22: Valor mayor pagado | F22: 64
E23: Saldo por pagar | F23: =F20-F21-F22 -> 512.30815
E25: ANTHONY | F25: 45884
E26: Tour Comuna trece | F26: 79000
E27: Traslados hotel-parque-hotel | F27: 50000
E28: Saldo por pagar en pesos | F28: =SUM(F26:F27) -> 129000
E29: USD en dólares | F29: =F28/3800 -> 33.947368

Sheet DETALLE DE LOS SERVICIOS
B3: Concepto | C3: Empresa | D3: Reemy | E3: Anthony | F3: Raison
B4: Compra de 50 bolsos | C4: 602.82895
B5: Costo de envío de los bolsos desde Bogotá a Medellín | C5: 23.026316
B6: Medical Trip Colombia - servicios de cotización , compra de los bolsos | C6: 65.789474
B7: Tres tiquetes aéreo vía wingo en tarifa economica full | D7: 680 | E7: 680 | F7: 680
B8: Tarifa administrativa emisión de tiquetes | D8: 40 | E8: 40 | F8: 40
B9: Cambio de nombre del pasajero | E9: 100
B10: Póliza de asistencia médica al viajero | D10: 16.374269 | E10: 16.374269 | F10: 16.374269
B11: Sim card física | E11: 3.5087719 | F11: 3.5087719
B12: Recarga de 10 gigas de datos | D12: 7.8947368 | E12: 7.8947368 | F12: 7.8947368
B13: Traslado aeropuerto - hotel - aeropuerto en MINIVAN | D13: 59.454191 | E13: 59.454191 | F13: 59.454191
B14: Alojamiento en suite Deluxe Reemy Poppen | D14: 800.57309
B15: Habitación Individual para una persona Willet Peternella | E15: 706.03458
B16: Habitación Individual para una persona Raison Guribaldi | F16: 706.02243
B17: PAQUETE DE CHEQUEO MÉDICO | E17: 450
B18: Entrevista con médico funcional virtual
B19: Domicilio
B20: Antígeno de próstata
B21: Coprológico
B22: Vitamina D25
B23: Vitamina B12
B24: Perfil lipídico
B25: Colesterol HDL
B26: Colesterol LDL
B27: Colesterol total
B28: Triglicéridos
B29: Perfil Hepático
... B51: ESTUDIOS PERSONALIZADOS
B52: Hemoglobina Glicosilada | E52: 21.929825
B53: Ionograma: calcio - sodio - fósforo - potasio | E53: 48.245614
B54: Homocisteína | E54: 37.894737
B55: Parathormona | E55: 50.877193
B56: HEPATITIS A ANTICUERPOS TOTALES SEMIAUTOMATIZADO O AUTOMATIZADO | E56: 26.315789
B57: HEPATITIS B ANTICUERPOS CENTRAL TOTALES [ANTI-CORE HBC] SEMIAUTOMATIZADO O AUTOMAT1 | E57: 37.280702
B58: HEPATITIS B ANTICUERPOS S [ANTI-HBS] SEMIAUTOMATIZADO O AUTOMATIZADO | E58: 28.508772
B59: HEPATITIS B ANTÍGENO DE SUPERFICIE [AG HBS] | E59: 32.894737
B60: HEPATITIS C, ANTICUERPO [ANTI-HVC] | E60: 35.087719
B61: G6PD (glucosa-6-fosfato deshidrogenasa) Prueba cualitativa | E61: 21.929825
B62: G6PD (glucosa-6-fosfato deshidrogenasa) Prueba cuantitativa | E62: 21.929825
B63: Ecografía de próstata transrectal | E63: 75.18797
...

Sheet CONFIRMACIÓN DE SERVICIOS
A1: Medialfa
B2: TAC ABDOMEN Y PELVIS
N5: 3145355801 | O5: ANTHONY
N6: 3145354536 | O6: RAISON
O7: REEMY
B21: RX TÓRAX
B43: ECOCARDIOGRAFÍA | H43: PRUEBA DE ESFUERZO | L43: ELECTROCARDIOGRAMA
B63: ECOGRAFÍA PROSTÁTICA
B90: CARDIOLOGÍA
B107: ENDOSCOPIA

Sheet Hoja 26
B3: Concepto | C3: Empresa | D3: Reemy | E3: Anthony | F3: Raison
B4: Compra de 50 bolsos | C4: 602.82895
B5: Costo de envío de los bolsos desde Bogotá a Medellín | C5: 23.026316
B6: Medical Trip Colombia - servicios de cotización , compra de los bolsos | C6: 65.789474
B7: Tres tiquetes aéreo vía wingo en tarifa economica full | D7: 680 | E7: 680 | F7: 680
B8: Tarifa administrativa emisión de tiquetes | D8: 40 | E8: 40 | F8: 40
B9: Cambio de nombre del pasajero | E9: 100
B10: Póliza de asistencia médica al viajero | D10: 16.374269 | E10: 16.374269 | F10: 16.374269
B11: Sim card física | D11: 3.5087719 | E11: 3.5087719 | F11: 3.5087719
B12: Recarga de 10 gigas de datos | D12: 7.8947368 | E12: 7.8947368 | F12: 7.8947368
B13: Traslado aeropuerto - hotel - aeropuerto en MINIVAN | D13: 59.454191 | E13: 59.454191 | F13: 59.454191
B14: Alojamiento en suite Deluxe Reemy Poppen | D14: 800.57309
B15: Habitación Individual para una persona Willet Peternella | E15: 706.03458
B16: Habitación Individual para una persona Raison Guribaldi | F16: 706.02243
B17: PAQUETE DE CHEQUEO MÉDICO | E17: 450
B18: Entrevista con médico funcional virtual
B19: Domicilio
B20: Antígeno de próstata
B21: Coprológico
B22: Vitamina D25
B23: Vitamina B12
B24: Perfil lipídico
B25: Colesterol HDL
B26: Colesterol LDL
B27: Colesterol total
B28: Triglicéridos
B29: Perfil Hepático
... B51: ÓRDENES MÉDICAS
B52: Hemoglobina Glicosilada | E52: 21.929825
B53: Ionograma: calcio - sodio - fósforo - potasio | E53: 48.245614
B54: Homocisteína | E54: 37.894737
B55: Parathormona | E55: 50.877193
B56: HEPATITIS A ANTICUERPOS TOTALES SEMIAUTOMATIZADO O AUTOMATIZADO | E56: 26.315789
B57: HEPATITIS B ANTICUERPOS CENTRAL TOTALES [ANTI-CORE HBC] SEMIAUTOMATIZADO O AUTOMAT1 | E57: 37.280702
B58: HEPATITIS B ANTICUERPOS S [ANTI-HBS] SEMIAUTOMATIZADO O AUTOMATIZADO | E58: 28.508772
B59: HEPATITIS B ANTÍGENO DE SUPERFICIE [AG HBS] | E59: 32.894737
B60: HEPATITIS C, ANTICUERPO [ANTI-HVC] | E60: 35.087719
B61: G6PD (glucosa-6-fosfato deshidrogenasa) Prueba cualitativa | E61: 21.929825
B62: G6PD (glucosa-6-fosfato deshidrogenasa) Prueba cuantitativa | E62: 21.929825
B63: Ecografía de próstata transrectal | E63: 75.18797
...

Sheet HOTEL
G13: 492432
G14: =G13*19% -> 93562.08
G15: =G13-G14 -> 398869.92
C19: Reemy | D19: Raison | E19: Anthony | I19: Anthony
C20: Tarifa con Iva comisionable | D20: Tarifa con Iva comisionable | E20: Tarifa con Iva comisionable | I20: Tarifa con Iva comisionable | O20: =SUM('RVA011-7-COSTEO'!Q16:Q100) -> 11294.247 | P20: =SUM('RVA011-7-COSTEO'!R16:R100) -> 3788.6726
C21: 3755775 | D21: 3312261 | E21: 3312204 | G21: 353250.57 | H21: =G21*7 -> 2472754 | I21: 3312204 | K21: IVA 19 % | O21: =#REF!/$H$24 -> #REF! | P21: =K21/$H$24 -> #VALUE!
B22: IVA | C22: =C21*19% -> 713597.25 | D22: =D21*19% -> 629329.59 | E22: =E21*19% -> 629318.76 | G22: 48900 | H22: =G22*7 -> 342300 | I22: 342300 | J22: =I22*9% -> 30807 | K22: IVA 19 % | O22: =I22/$H$24 -> #DIV/0! | P22: =K22/$H$24 -> #VALUE!
C23: =C21-C22 -> 3042177.8 | D23: =D21-D22 -> 2682931.4 | E23: =E21-E22 -> 2682885.2 | G23: =G21+G22 -> 402150.57 | H23: =H21+H22 -> 2815054 | I23: =I21-I22 -> 2969904 | O23: =I23/$H$24 -> #DIV/0! | P23: =J23/$H$24 -> #DIV/0!
A24: RESERVO Y PRE PAGO | B24: X NOCHE | C24: =C23/7 -> 434596.82 | D24: =D23/7 -> 383275.92 | E24: =E23/7 -> 383269.32 | I24: =I23/7 -> 424272
A25: COBRAN | B25: x NOCHE | C25: 455393 | D25: 402000 | E25: 402000 | I25: 402000 | O25: =SUM(O20:O24) -> #REF! | P25: =SUM(P20:P23) -> #VALUE!
C26: =C25-C24 -> 20796.179 | D26: =D25-D24 -> 18724.084 | E26: =E25-E24 -> 18730.68 | F26: TOTAL | H26: =H21*19% -> 469823.26 | I26: =I25-I24 -> -22272
A27: DIFERENCIA | B27: 7 NOCHES | C27: =C26*7 -> 145573.25 | D27: =D26*7 -> 131068.59 | E27: =E26*7 -> 131114.76 | F27: =SUM(C27:E27) -> 407756.6 | I27: =I26*7 -> -155904
C29: =C24/3800 -> 114.36758 | D29: =D24/3800 -> 100.86208 | E29: =E24/3800 -> 100.86035
A30: 353250.57 2,472,754.00 2472754.00 11/08/2025 7 Restaurante incluido en tarifa 48900.00
B68: RAISON | C68: ANTHONY | D68: REEMY
B69: 2815054 | C69: 2815054 | D69: 3187755
A70: RETENCIÓN 3.5% | B70: =B69*3.5% -> 98526.89 | C70: =C69*3.5% -> 98526.89 | D70: =D69*3.5% -> 111571.43
A71: VALOR A PAGAR | B71: =B69-B70 -> 2716527.1 | C71: =C69-C70 -> 2716527.1 | D71: =D69-D70 -> 3076183.6 | E71: =SUM(B71:D71) -> 8509237.8 | F71: TOTAL
E72: 7700000 | F72: DEPÓSITO
E73: =E71-7700000 -> 809237.8 | F73: SALDO A PAGAR
B76: RAISON | C76: ANTHONY | D76: REEMY
B77: =(337286+48900)*7 -> 2703302 | C77: =(337286+48900)*7 -> 2703302 | D77: =(369429+48900)*7 -> 2928303
A80: RETENCIÓN 3.5% | B80: =B77*3.5% -> 94615.57 | C80: =C77*3.5% -> 94615.57 | D80: =D77*3.5% -> 102490.6
A81: VALOR A PAGAR | B81: =B77-B80 -> 2608686.4 | C81: =C77-C80 -> 2608686.4 | D81: =D77-D80 -> 2825812.4 | E81: =SUM(B81:D81) -> 8043185.3 | F81: TOTAL
E82: 7700000 | F82: DEPÓSITO
E83: =E81-7700000 -> 343185.26 | F83: SALDO A PAGAR

Sheet VUELOS
A1: 2302151378519
J5: HT61EF
K25: ACU00W
N33: 06:00 am
N34: 07:00 am
N35: 0.34375
N36: 09:15 am
