Workbook

Sheet Pasaporte - HC
A18: Nombre | B18: BRADLEY | D18: Nombre
A19: Nombre | B19: JARVIS CRISPIN | D19: Nombre
A20: Apellido | B20: POPPEN | D20: Apellido
A21: Género: . | B21: Masculino | D21: Género: .
A22: Pasaporte | B22: NS6RDHB45 | D22: Pasaporte
A23: Fecha de nacimiento | B23: 21597 | D23: Fecha de nacimiento
A24: Edad | B24: 66 | D24: Edad
A25: Estado civil | D25: Estado civil
A26: Dirección | D26: Dirección
A27: Nacionalidad y domicilio: | D27: Nacionalidad y domicilio:
A28: Email: | B28: bradleypoppen@gmail.com | D28: Email:
A29: Teléfono | B29: 59995684619 | D29: Teléfono
A30: Profesión | D30: Profesión
A31: RH | D31: RH
A32: Seguro | D32: Seguro
A33: Peso | D33: Peso
A34: Altura | D34: Altura
A35: Idioma | D35: Idioma
A36: Estadia:
D37: Salud

Sheet ITINERARIO
B3: ITINERARIO:
B4: Dia | C4: Fecha | D4: Hora | E4: Actividad | F4: ACP horas | G4: Traslado cerca | H4: Traslado lejos
C5: 1
E6: Vuelo Curazao - Medellín
E7: Traslado a aeropuerto - hotel
E8: Alojamiento
E11: No desayunar
E12: Traslado Hotel - Centro médico | F12: 0.5 | G12: 1
E13: Toma de muestras de sangre laboratorio clínico
E14: Ecografía de abdomen total
E15: Citología
E16: Mamografía
E17: Radiografía de tórax
E18: Radiografía pie derecho e izquierdo
E19: Electrocardiograma
E20: Traslado Centro médico - Hotel | G20: 1
E21: Día libre
E25: Desayuno en el hotel
E26: Traslado hotel - aeropuerto
E27: Vuelo internacional Curazao - Medellín
F28: =SUM(F5:F27) -> 0.5 | G28: =SUM(G5:G27) -> 2 | H28: =SUM(H5:H27) -> 0

Sheet COSTEO
C3: PAGOS | M3: 3700
B4: ACV documentos | C4: Contabilidad | D4: Operativo | E4: Concepto | F4: Proveedor | G4: Valor | H4: Días | I4: BRADLEY | M4: Comisionable
E5: Póliza de asistencia médica al viajero - producto visitor por 08 días | F5: Colasistencia | G5: 3500 | H5: 8 | I5: =G5*H5 -> 28000 | M5: =I5/0.6 -> 46666.667 | N5: =M5/$M$3 -> 12.612613
E6: Tiquete aéreo Curazao - Medellín - Curazao | F6: Wingo | G6: 1870000 | H6: 1 | I6: =G6*H6 -> 1870000 | M6: =I6 -> 1870000 | N6: 500
E7: Sim card física | F7: Claro | G7: 6000 | H7: 0 | I7: =G7*H7 -> 0 | M7: =I7/0.6 -> 0
E8: Recarga 10 gigas de datos | F8: Claro | G8: 12000 | H8: 0 | I8: =G8*H8 -> 0 | M8: =I8/0.75 -> 0
E9: Traslado aeropuerto - hotel - aeropuerto en MINIVAN | F9: Taxi van | G9: 260000 | H9: 0 | I9: =G9*H9/3 -> 0 | M9: =I9/0.95 -> 0
E10: Paquete de chequeo médico | H10: 0 | I10: 1300000
E11: Antígeno de Próstata | F11: Echavarría
E12: Citología | F12: CIMA
E13: Coprológico | F13: CIMA
E14: Vitamina D25 | F14: CIMA
E15: Vitamina B12 | F15: CIMA
E16: Perfil lipídico | F16: CIMA
E17: Colesterol HDL | F17: CIMA
E18: Colesterol LDL | F18: CIMA
E19: Colesterol total | F19: CIMA
E20: Triglicéridos | F20: CIMA
E21: Perfil Hepático | F21: CIMA
E22: ALT- Alanina transferasa | F22: CIMA
... E40: VIH 1 Y 2, Anticuerpos | F40: CIMA
E41: Imágenes diagnósticas
E42: Radiografía de tórax | F42: CIMA
E43: Mamografía | F43: CIMA
E44: Ecografía de abdomen total | F44: CIMA
E45: Electrocardiograma | F45: CIMA
E46: Cita con especialista en MEDICINA INTERNA
E47: 04 Traslados hotel - clínica por trayecto | F47: Yenny
E48: Medical Trip Colombia SAS - Acompañamiento virtual y presencial para exámenes y citas | F48: Yenny
E49: ÓRDENES MÉDICAS
E50: Entrevista virtual con médico Funcional | F50: Marcos Yépes | G50: 150000 | H50: 0 | I50: =G50*H50 -> 0 | M50: =I50/0.98 -> 0
E51: Homocisteína sérica (HCYSP) | F51: Echavarria | G51: 108000 | H51: 0 | I51: =G51*H51 -> 0 | M51: =I51/0.85 -> 0
E52: Frotis de sangre periférica - (extendido de sangre periférica estudio de morfología) | F52: Echavarria | G52: 45000 | H52: 0 | I52: =G52*H52 -> 0 | M52: =I52/0.6 -> 0
E53: Test de sicklemia: (Células Falciformes-drepanocitosis) | F53: Echavarría | G53: 40000 | H53: 0 | I53: =G53*H53 -> 0 | M53: =I53/0.6 -> 0
E54: Paratohormona | F54: Echavarria | G54: 116000 | H54: 0 | I54: =G54*H54 -> 0 | M54: =I54/0.85 -> 0
E55: Doppler arterial miembros inferiores | F55: CIMA | G55: 255000 | H55: 0 | I55: =G55*H55 -> 0 | M55: =I55/0.8 -> 0
E56: Doppler venoso de miembros inferiores | F56: CIMA | G56: 221000 | H56: 0 | I56: =G56*H56 -> 0 | M56: =I56/0.8 -> 0
E57: Ecografía del corazón - ecocardiografía | F57: CIMA | G57: 320000 | H57: 0 | I57: =G57*H57 -> 0 | M57: =I57/0.85 -> 0
E58: Prueba de esfuerzo cardíaco | F58: CIMA | G58: 240000 | H58: 0 | I58: =G58*H58 -> 0 | M58: =I58/0.8 -> 0
E59: Radiografía de pie derecho | F59: CIMA | G59: 70000 | H59: 0 | I59: =G59*H59 -> 0 | M59: =I59/0.8 -> 0
...

Sheet Detalle de servicios
B5: =COSTEO!E4 -> Concepto | C5: BRADLEY
B6: =COSTEO!E5 -> Póliza de asistencia médica al viajero - producto visitor por 08 días | C6: =COSTEO!N5 -> 12.612613
B7: =COSTEO!E6 -> Tiquete aéreo Curazao - Medellín - Curazao | C7: =COSTEO!N6 -> 500
B8: Servicio Medical Trip Colombia - Acompañamiento Virtual | C8: 10
B9: VALOR TOTAL | C9: =SUM(C6:C8) -> 522.61261 | D9: =#REF! -> #REF! | E9: =#REF! -> #REF! | F9: =#REF! -> #REF! | G9: =#REF! -> #REF!
B10: =#REF! -> #REF! | C10: =#REF! -> #REF! | D10: =#REF! -> #REF! | E10: =#REF! -> #REF! | F10: =#REF! -> #REF! | G10: =#REF! -> #REF!
B11: =#REF! -> #REF! | C11: =#REF! -> #REF! | D11: =#REF! -> #REF! | E11: =#REF! -> #REF! | F11: =#REF! -> #REF! | G11: =#REF! -> #REF!

Sheet Vuelo
C4: GWMMR8 | D4: LOCALIZADOR
C24: GWMMR8
