Workbook

Sheet Pasaporte - HC
H1: Nombre | I1: Geraldine
H2: Nombre | I2: Joanne R.A.
H3: Apellido | I3: Tromp
H4: Apellido de casada
H5: Género: . | I5: Femenino
H6: Pasaporte | I6: NYD6H38J5
H7: Fecha de nacimiento | I7: 18 - 1 - 1978
H8: Edad | I8: =2025-1978 -> 47
H9: Estado civil | I9: En una relación
H10: Dirección
H11: Nacionalidad y domicilio: | I11: Aruba
H12: Email: | I12: does18@hotmail.com
H13: Teléfono | I13: 297 563 2003
H14: Profesión
H15: RH | I15: o+
H16: Seguro | I16: AZV nr. 1074433900
H17: Peso | I17: 68 kilos
H18: Altura | I18: 1.57 m
H19: Idioma | I19: Papiamneto, Holandes, ingles y Español
H21: Salud
H22: Estadia | I22: 21 de julio al 1 de agosto
H27: Nombre | I27: Enrica
H28: Nombre | I28: Rosamalia
H29: Apellido | I29: Everon
H30: Apellido de casada
H31: Género: . | I31: femenino
H32: Pasaporte | I32: NY8BCHCJ2
H33: Fecha de nacimiento | I33: 14 de Julio 1956
H34: Edad
H35: Estado civil | I35: Soltera
H36: Dirección
H37: Nacionalidad y domicilio: | I37: Aruba
H38: Email: | I38: does18@hotmail.com
H39: Teléfono
H40: Profesión
H41: RH | I41: A+
H42: Seguro
H43: Peso | I43: 65kg
H44: Altura | I44: 1,63m
H45: Idioma | I45: Papiamneto, Holandes, ingles y Español
...

Sheet COSTEO
AC2: Libro diario contable | AK2: Factura electrónica
C3: PAGOS | T3: PAGOS | Z3: ESTADO DE CUENTA | AC3: PAGOS | AK3: FACTURA
B4: ACV documentos | C4: Contabilidad | D4: Operativo | E4: Concepto | F4: Proveedor | G4: Valor | H4: Días | I4: Geraldine | J4: Enrica | K4: Jair | M4: Geraldine | N4: Enrica | O4: Jair | P4: Geraldine | Q4: Enrica | R4: Jair | T4: Geraldine | U4: Enrica | V4: Jair | W4: Retención en la fuente | X4: Valor pagado | Z4: Valor Neto cobrado al cliente | AA4: DIFERENCIA | AC4: PROVEEDOR - NOMBRE COMERCIAL | AD4: ID | AE4: Fecha del pago | AF4: Valor del pago | AG4: Forma de pago de donde salió el dinero | AH4: Tipo de movimiento | AI4: Comentarios | AK4: Fecha de la factura | AL4: FACTURA O CUENTA COBRO | AM4: VALOR REAL DE LA FACTURA | AN4: CONCEPTO
B5: App | C5: Pre - compra | D5: Emitido | E5: Póliza de asistencia de medica
C6: Pagado | D6: Confirmado | E6: Domicilio | F6: Echavarria | G6: 35000 | H6: 1 | I6: =G6*H6/3 -> 11666.667 | J6: =G6*H6/3 -> 11666.667 | K6: =G6*H6/3 -> 11666.667 | M6: =I6/0.6 -> 19444.444 | N6: =J6/0.6 -> 19444.444 | O6: =K6/0.6 -> 19444.444 | P6: =M6/$H$46 -> 5.0505051 | Q6: =N6/$H$46 -> 5.0505051 | R6: =O6/$H$46 -> 5.0505051 | T6: 245760 | U6: 245760 | V6: 277260 | Z6: =SUM(I6:I29) -> 578666.67 | AA6: =SUM(J6:J29) -> 578666.67
B7: ARCHIVADO | D7: Confirmado | E7: Antígeno de próstata | F7: Echavarria | G7: 45000 | H7: 1 | K7: =G7*H7 -> 45000 | O7: =K7/0.6 -> 75000 | R7: =O7/$H$46 -> 19.480519
B8: ARCHIVADO | D8: Confirmado | E8: ALT- Alanina transferasa | F8: Echavarria | G8: 20000 | H8: 1 | I8: =G8*H8 -> 20000 | J8: =G8*H8 -> 20000 | K8: =G8*H8 -> 20000 | M8: =I8/0.6 -> 33333.333 | N8: =J8/0.6 -> 33333.333 | O8: =K8/0.6 -> 33333.333 | P8: =M8/$H$46 -> 8.6580087 | Q8: =N8/$H$46 -> 8.6580087 | R8: =O8/$H$46 -> 8.6580087 | Z8: =SUM(K6:K29) -> 623666.67
B9: ARCHIVADO | D9: Confirmado | E9: AST - aspartato transferasa | F9: Echavarria | G9: 20000 | H9: 1 | I9: =G9*H9 -> 20000 | J9: =G9*H9 -> 20000 | K9: =G9*H9 -> 20000 | M9: =I9/0.6 -> 33333.333 | N9: =J9/0.6 -> 33333.333 | O9: =K9/0.6 -> 33333.333 | P9: =M9/$H$46 -> 8.6580087 | Q9: =N9/$H$46 -> 8.6580087 | R9: =O9/$H$46 -> 8.6580087
B10: ARCHIVADO | D10: Confirmado | E10: Bilirrubina total y directa | F10: Echavarria | G10: 22000 | H10: 1 | I10: =G10*H10 -> 22000 | J10: =G10*H10 -> 22000 | K10: =G10*H10 -> 22000 | M10: =I10/0.6 -> 36666.667 | N10: =J10/0.6 -> 36666.667 | O10: =K10/0.6 -> 36666.667 | P10: =M10/$H$46 -> 9.5238095 | Q10: =N10/$H$46 -> 9.5238095 | R10: =O10/$H$46 -> 9.5238095
B11: ARCHIVADO | D11: Confirmado | E11: Colesterol HDL | F11: Echavarria | G11: 10000 | H11: 1 | I11: =G11*H11 -> 10000 | J11: =G11*H11 -> 10000 | K11: =G11*H11 -> 10000 | M11: =I11/0.6 -> 16666.667 | N11: =J11/0.6 -> 16666.667 | O11: =K11/0.6 -> 16666.667 | P11: =M11/$H$46 -> 4.3290043 | Q11: =N11/$H$46 -> 4.3290043 | R11: =O11/$H$46 -> 4.3290043
B12: ARCHIVADO | D12: Confirmado | E12: Colesterol LDL | F12: Echavarria | G12: 12000 | H12: 1 | I12: =G12*H12 -> 12000 | J12: =G12*H12 -> 12000 | K12: =G12*H12 -> 12000 | M12: =I12/0.6 -> 20000 | N12: =J12/0.6 -> 20000 | O12: =K12/0.6 -> 20000 | P12: =M12/$H$46 -> 5.1948052 | Q12: =N12/$H$46 -> 5.1948052 | R12: =O12/$H$46 -> 5.1948052
B13: ARCHIVADO | D13: Confirmado | E13: Colesterol total | F13: Echavarria | G13: 15000 | H13: 1 | I13: =G13*H13 -> 15000 | J13: =G13*H13 -> 15000 | K13: =G13*H13 -> 15000 | M13: =I13/0.6 -> 25000 | N13: =J13/0.6 -> 25000 | O13: =K13/0.6 -> 25000 | P13: =M13/$H$46 -> 6.4935065 | Q13: =N13/$H$46 -> 6.4935065 | R13: =O13/$H$46 -> 6.4935065
B14: ARCHIVADO | D14: Confirmado | E14: Creatinina | F14: Echavarria | G14: 15000 | H14: 1 | I14: =G14*H14 -> 15000 | J14: =G14*H14 -> 15000 | K14: =G14*H14 -> 15000 | M14: =I14/0.6 -> 25000 | N14: =J14/0.6 -> 25000 | O14: =K14/0.6 -> 25000 | P14: =M14/$H$46 -> 6.4935065 | Q14: =N14/$H$46 -> 6.4935065 | R14: =O14/$H$46 -> 6.4935065
B15: ARCHIVADO | D15: Confirmado | E15: Coprológico | F15: Echavarria | G15: 22000 | H15: 1 | I15: =G15*H15 -> 22000 | J15: =G15*H15 -> 22000 | K15: =G15*H15 -> 22000 | M15: =I15/0.6 -> 36666.667 | N15: =J15/0.6 -> 36666.667 | O15: =K15/0.6 -> 36666.667 | P15: =M15/$H$46 -> 9.5238095 | Q15: =N15/$H$46 -> 9.5238095 | R15: =O15/$H$46 -> 9.5238095
B16: ARCHIVADO | D16: Confirmado | E16: Ferritina | F16: Echavarria | G16: 50000 | H16: 1 | I16: =G16*H16 -> 50000 | J16: =G16*H16 -> 50000 | K16: =G16*H16 -> 50000 | M16: =I16/0.6 -> 83333.333 | N16: =J16/0.6 -> 83333.333 | O16: =K16/0.6 -> 83333.333 | P16: =M16/$H$46 -> 21.645022 | Q16: =N16/$H$46 -> 21.645022 | R16: =O16/$H$46 -> 21.645022
B17: ARCHIVADO | D17: Confirmado | E17: Gamma glutamil transferasa | F17: Echavarria | G17: 22000 | H17: 1 | I17: =G17*H17 -> 22000 | J17: =G17*H17 -> 22000 | K17: =G17*H17 -> 22000 | M17: =I17/0.6 -> 36666.667 | N17: =J17/0.6 -> 36666.667 | O17: =K17/0.6 -> 36666.667 | P17: =M17/$H$46 -> 9.5238095 | Q17: =N17/$H$46 -> 9.5238095 | R17: =O17/$H$46 -> 9.5238095
B18: ARCHIVADO | D18: Confirmado | E18: Glucosa sérica | F18: Echavarria | G18: 15000 | H18: 1 | I18: =G18*H18 -> 15000 | J18: =G18*H18 -> 15000 | K18: =G18*H18 -> 15000 | M18: =I18/0.6 -> 25000 | N18: =J18/0.6 -> 25000 | O18: =K18/0.6 -> 25000 | P18: =M18/$H$46 -> 6.4935065 | Q18: =N18/$H$46 -> 6.4935065 | R18: =O18/$H$46 -> 6.4935065
B19: ARCHIVADO | D19: Confirmado | E19: Hemoglobina Glicosilada | F19: Echavarria | G19: 45000 | H19: 1 | I19: =G19*H19 -> 45000 | J19: =G19*H19 -> 45000 | K19: =G19*H19 -> 45000 | M19: =I19/0.6 -> 75000 | N19: =J19/0.6 -> 75000 | O19: =K19/0.6 -> 75000 | P19: =M19/$H$46 -> 19.480519 | Q19: =N19/$H$46 -> 19.480519 | R19: =O19/$H$46 -> 19.480519
B20: ARCHIVADO | D20: Confirmado | E20: Hemograma completo | F20: Echavarria | G20: 25000 | H20: 1 | I20: =G20*H20 -> 25000 | J20: =G20*H20 -> 25000 | K20: =G20*H20 -> 25000 | M20: =I20/0.6 -> 41666.667 | N20: =J20/0.6 -> 41666.667 | O20: =K20/0.6 -> 41666.667 | P20: =M20/$H$46 -> 10.822511 | Q20: =N20/$H$46 -> 10.822511 | R20: =O20/$H$46 -> 10.822511
... B29: ARCHIVADO | D29: Confirmado | E29: Vitamina D25 | F29: Echavarria | G29: 65000 | H29: 1 | I29: =G29*H29 -> 65000 | J29: =G29*H29 -> 65000 | K29: =G29*H29 -> 65000 | M29: =I29/0.6 -> 108333.33 | N29: =J29/0.6 -> 108333.33 | O29: =K29/0.6 -> 108333.33 | P29: =M29/$H$46 -> 28.138528 | Q29: =N29/$H$46 -> 28.138528 | R29: =O29/$H$46 -> 28.138528
B30: ARCHIVADO | C30: Facturado | D30: Confirmado | E30: Radiografía de tórax | F30: CIMA | G30: 70000 | H30: 1 | J30: =G30*H30 -> 70000 | K30: =G30*H30 -> 70000 | N30: =J30/0.6 -> 116666.67 | O30: =K30/0.6 -> 116666.67 | Q30: =N30/$H$46 -> 30.30303 | R30: =O30/$H$46 -> 30.30303 | AC30: CIMA | AE30: 45859 | AF30: 1000000 | AG30: JENNY BANCOLOMBIA | AH30: TRANSFERENCIA
B31: ARCHIVADO | C31: Facturado | D31: Confirmado | E31: Ecografía de abdomen total | F31: CIMA | G31: 140000 | H31: 1 | I31: =G31*H31 -> 140000 | J31: =G31*H31 -> 140000 | K31: =G31*H31 -> 140000 | M31: =I31/0.6 -> 233333.33 | N31: =J31/0.6 -> 233333.33 | O31: =K31/0.6 -> 233333.33 | P31: =M31/$H$46 -> 60.606061 | Q31: =N31/$H$46 -> 60.606061 | R31: =O31/$H$46 -> 60.606061
B32: ARCHIVADO | C32: Facturado | D32: Confirmado | E32: Ecografía de tiroides y paratiroides | F32: CIMA | G32: 120000 | H32: 1 | I32: 120000 | K32: =G32*H32 -> 120000 | M32: =I32/0.7 -> 171428.57 | O32: =K32/0.7 -> 171428.57 | P32: =M32/$H$46 -> 44.526902 | R32: =O32/$H$46 -> 44.526902
B33: ARCHIVADO | C33: Facturado | D33: Confirmado | E33: Electrocardiograma | F33: CIMA | G33: 65000 | H33: 1 | I33: =G33*H33 -> 65000 | J33: =G33*H33 -> 65000 | K33: =G33*H33 -> 65000 | M33: =I33/0.6 -> 108333.33 | N33: =J33/0.6 -> 108333.33 | O33: =K33/0.6 -> 108333.33 | P33: =M33/$H$46 -> 28.138528 | Q33: =N33/$H$46 -> 28.138528 | R33: =O33/$H$46 -> 28.138528
E34: ESPECIALISTAS
B35: ARCHIVADO | C35: FACTURADO | D35: confirmado | E35: Cita con especialista en OFTALMOLOGÍA | G35: 280000 | H35: 1 | J35: =G35*H35 -> 280000 | K35: =G35*H35 -> 280000 | M35: =I35/0.95 -> 0 | N35: =J35/0.95 -> 294736.84 | O35: =K35/0.95 -> 294736.84 | Q35: =N35/$H$46 -> 76.555024 | R35: =O35/$H$46 -> 76.555024 | U35: 270000 | V35: 270000 | W35: 0 | X35: =U35+V35 -> 540000 | Z35: =J35+K35 -> 560000 | AA35: =Z35-X35 -> 20000 | AC35: CLINICA DE OFTALMOLOGÍA SAN DIEGO | AE35: 45859 | AF35: 540000 | AG35: JENNY BANCOLOMBIA | AH35: TRANSFERENCIA
B36: ARCHIVADO | C36: FACTURADO | D36: confirmado | E36: Cita con especialista en DERMATOLOGÍA | G36: 300000 | H36: 1 | I36: =G36*H36 -> 300000 | M36: =I36/0.95 -> 315789.47 | P36: =M36/$H$46 -> 82.02324 | T36: 270000 | W36: 0 | X36: =T36-W36 -> 270000 | Z36: =I36 -> 300000 | AA36: =Z36-X36 -> 30000 | AC36: ETIEMEDELLIN | AE36: 45859 | AF36: 280000 | AG36: JENNY BANCOLOMBIA | AH36: TRANSFERENCIA
B37: DSM | C37: FACTURADO | D37: confirmado | E37: 04 Traslados hotel - clínica - por trayecto para las tres personas en el área del poblado | G37: =40000/3 -> 13333.333 | H37: 4 | I37: =G37*H37 -> 53333.333 | J37: =G37*H37 -> 53333.333 | K37: =G37*H37 -> 53333.333 | M37: =K37/0.9 -> 59259.259 | N37: =J37/0.9 -> 59259.259 | O37: =K37/0.9 -> 59259.259 | P37: =M37/$H$46 -> 15.392015 | Q37: =N37/$H$46 -> 15.392015 | R37: =O37/$H$46 -> 15.392015
D38: confirmado | E38: Medical Trip Colombia SAS - Acompañamiento virtual permanente en ESPAÑOL | F38: Dayana | G38: =200000/3 -> 66666.667 | H38: 1 | I38: =G38*H38 -> 66666.667 | J38: =G38*H38 -> 66666.667 | K38: =G38*H38 -> 66666.667 | M38: =I38/0.95 -> 70175.439 | N38: =J38/0.95 -> 70175.439 | O38: =K38/0.95 -> 70175.439 | P38: =M38/$H$46 -> 18.227387 | Q38: =N38/$H$46 -> 18.227387 | R38: =O38/$H$46 -> 18.227387
B39: DSM | C39: FACTURADO | D39: confirmado | E39: Acompañamiento presencial en español para citas y exámenes | G39: =180000/3 -> 60000 | H39: 1 | I39: =G39*H39 -> 60000 | J39: =G39*H39 -> 60000 | K39: =G39*H39 -> 60000 | M39: =I39/0.95 -> 63157.895 | N39: =J39/0.95 -> 63157.895 | O39: =K39/0.95 -> 63157.895 | P39: =M39/$H$46 -> 16.404648 | Q39: =N39/$H$46 -> 16.404648 | R39: =O39/$H$46 -> 16.404648
D40: confirmado | E40: Caja menor | G40: 20000 | H40: 1 | I40: =G40*H40 -> 20000 | J40: =G40*H40 -> 20000 | K40: =G40*H40 -> 20000
H41: Total neto | I41: =SUM(I6:I40) -> 1403666.7 | J41: =SUM(J6:J40) -> 1333666.7 | K41: =SUM(K6:K40) -> 1498666.7
H42: 0.25 | I42: =I41/0.707 -> 1985384.3 | J42: =J41/0.698 -> 1910697.2 | K42: =K41/0.724 -> 2069981.6 | P42: =SUM(P6:P40) -> 515.82383 | Q42: =SUM(Q6:Q40) -> 496.13174 | R42: =SUM(R6:R40) -> 560.13916
G43: Gastos bancarios | H43: 4 * 1000 | I43: =I42*4/1000 -> 7941.537 | J43: =J42*4/1000 -> 7642.7889 | K43: =K42*4/1000 -> 8279.9263 | P43: =I43/$H$46 -> 2.0627369 | Q43: =J43/$H$46 -> 1.98514 | R43: =K43/$H$46 -> 2.1506302
G44: Gastos bancarios | H44: Transferencia nacional | I44: =(6000*1) -> 6000 | J44: =(6000*1) -> 6000 | K44: =(6000*1) -> 6000 | P44: =I44/$H$46 -> 1.5584416 | Q44: =J44/$H$46 -> 1.5584416 | R44: =K44/$H$46 -> 1.5584416
G45: Gastos bancarios | H45: Transferencia internacional
G46: Tasa del dólar | H46: 3850 | I46: =SUM(I42:I45) -> 1999325.8 | J46: =SUM(J42:J45) -> 1924340 | K46: =SUM(K42:K45) -> 2084261.5 | P46: =SUM(P42:P45) -> 519.44501 | Q46: =SUM(Q42:Q45) -> 499.67532 | R46: =SUM(R42:R45) -> 563.84824
I47: =I46/$H$46 -> 519.3054 | J47: =J46/$H$46 -> 499.82858 | K47: =K46/$H$46 -> 541.36663
D69: OK

Sheet 23-07-2025 COSTEO JAIR
AC2: Libro diario contable | AK2: Factura electrónica
C3: PAGOS | T3: PAGOS | Z3: ESTADO DE CUENTA | AC3: PAGOS | AK3: FACTURA
B4: ACV documentos | C4: Contabilidad | D4: Operativo | E4: Concepto | F4: Proveedor | G4: Valor | H4: Días | I4: Geraldine | J4: Enrica | K4: Jair | M4: Geraldine | N4: Enrica | O4: Jair | P4: Geraldine | Q4: Enrica | R4: Jair | T4: Geraldine | U4: Enrica | V4: Jair | W4: Retención en la fuente | X4: Valor pagado | Z4: Valor Neto cobrado al cliente | AA4: DIFERENCIA | AC4: PROVEEDOR - NOMBRE COMERCIAL | AD4: ID | AE4: Fecha del pago | AF4: Valor del pago | AG4: Forma de pago de donde salió el dinero | AH4: Tipo de movimiento | AI4: Comentarios | AK4: Fecha de la factura | AL4: FACTURA O CUENTA COBRO | AM4: VALOR REAL DE LA FACTURA | AN4: CONCEPTO
E5: PENTACAM | G5: 300000 | H5: 1 | I5: =G5*H5 -> 300000 | M5: =I5/0.95 -> 315789.47 | P5: =M5/$H$15 -> 82.02324 | T5: 270000 | W5: 0 | X5: =T5-W5 -> 270000 | Z5: =I5 -> 300000 | AA5: =Z5-X5 -> 30000 | AC5: ETIEMEDELLIN | AE5: 45859 | AF5: 280000 | AG5: JENNY BANCOLOMBIA | AH5: TRANSFERENCIA
E6: 04 Traslados hotel - clínica - por trayecto para las tres personas en el área del poblado | G6: =40000/3 -> 13333.333 | H6: 4 | I6: =G6*H6 -> 53333.333 | J6: =G6*H6 -> 53333.333 | K6: =G6*H6 -> 53333.333 | M6: =K6/0.9 -> 59259.259 | N6: =J6/0.9 -> 59259.259 | O6: =K6/0.9 -> 59259.259 | P6: =M6/$H$15 -> 15.392015 | Q6: =N6/$H$15 -> 15.392015 | R6: =O6/$H$15 -> 15.392015
E7: Medical Trip Colombia SAS - Acompañamiento virtual permanente en ESPAÑOL | F7: Dayana | G7: =200000/3 -> 66666.667 | H7: 1 | I7: =G7*H7 -> 66666.667 | J7: =G7*H7 -> 66666.667 | K7: =G7*H7 -> 66666.667 | M7: =I7/0.95 -> 70175.439 | N7: =J7/0.95 -> 70175.439 | O7: =K7/0.95 -> 70175.439 | P7: =M7/$H$15 -> 18.227387 | Q7: =N7/$H$15 -> 18.227387 | R7: =O7/$H$15 -> 18.227387
E8: Acompañamiento presencial en español para citas y exámenes | G8: =180000/3 -> 60000 | H8: 1 | I8: =G8*H8 -> 60000 | J8: =G8*H8 -> 60000 | K8: =G8*H8 -> 60000 | M8: =I8/0.95 -> 63157.895 | N8: =J8/0.95 -> 63157.895 | O8: =K8/0.95 -> 63157.895 | P8: =M8/$H$15 -> 16.404648 | Q8: =N8/$H$15 -> 16.404648 | R8: =O8/$H$15 -> 16.404648
E9: Caja menor | G9: 20000 | H9: 1 | I9: =G9*H9 -> 20000 | J9: =G9*H9 -> 20000 | K9: =G9*H9 -> 20000
H10: Total neto | I10: =SUM(I5:I9) -> 500000 | J10: =SUM(J5:J9) -> 200000 | K10: =SUM(K5:K9) -> 200000
H11: 0.25 | I11: =I10/0.707 -> 707213.58 | J11: =J10/0.698 -> 286532.95 | K11: =K10/0.724 -> 276243.09 | P11: =SUM(P5:P9) -> 132.04729 | Q11: =SUM(Q5:Q9) -> 50.02405 | R11: =SUM(R5:R9) -> 50.02405
G12: Gastos bancarios | H12: 4 * 1000 | I12: =I11*4/1000 -> 2828.8543 | J12: =J11*4/1000 -> 1146.1318 | K12: =K11*4/1000 -> 1104.9724 | P12: =I12/$H$15 -> 0.73476735 | Q12: =J12/$H$15 -> 0.29769657 | R12: =K12/$H$15 -> 0.28700581
G13: Gastos bancarios | H13: Transferencia nacional | I13: =(6000*1) -> 6000 | J13: =(6000*1) -> 6000 | K13: =(6000*1) -> 6000 | P13: =I13/$H$15 -> 1.5584416 | Q13: =J13/$H$15 -> 1.5584416 | R13: =K13/$H$15 -> 1.5584416
G14: Gastos bancarios | H14: Transferencia internacional
G15: Tasa del dólar | H15: 3850 | I15: =SUM(I11:I14) -> 716042.43 | J15: =SUM(J11:J14) -> 293679.08 | K15: =SUM(K11:K14) -> 283348.07 | P15: =SUM(P11:P14) -> 134.3405 | Q15: =SUM(Q11:Q14) -> 51.880188 | R15: =SUM(R11:R14) -> 51.869497
I16: =I15/$H$15 -> 185.98505 | J16: =J15/$H$15 -> 76.280281 | K16: =K15/$H$15 -> 73.5969
D38: OK

Sheet ITINERARIO
C3: ITINERARIO:
C4: Dia | D4: Fecha | E4: Hora | F4: Actividad | G4: ACP horas | H4: Traslados
C5: 1 | D5: 45859 | E5: Lunes
F6: Vuelo Curazao - Medellín
F7: Recibimiento en el aeropuerto
F8: Traslado a aeropuerto - hotel
F9: Alojamiento
D10: 45860 | E10: martes
B11: CONFIRMADO | C11: Echavarria domicilio HOTEL | D11: Enrica Geraldine - Jair | E11: 09:00 am | F11: Toma de muestras de sangre laboratorio clínico en su hotel
E12: 10:00 am | F12: Tiempo para desayunar
F13: Traslado hotel - centro médico | G13: 0.5 | H13: 1
B14: CONFIRMADO | C14: San Diego | D14: Jair | E14: 11:00 am | F14: Cita con especialista en OFTALMOLOGÍA
B15: CONFIRMADO | C15: San Diego | D15: Enrica | E15: 11:30 am | F15: Cita con especialista en OFTALMOLOGÍA
F16: Traslado centro médico - centro médico | H16: 1
B17: CONFIRMADO | C17: El tesoro | D17: Geraldine | E17: 01:00 pm | F17: Cita con especialista en DERMATOLOGÍA
F18: Traslado centro médico - hotel | H18: 1
F19: Inicia a tomar agua Geraldine
F20: Traslado Hotel - Centro médico | G20: 0.5 | H20: 1
B21: CONFIRMADO | C21: CIMA | D21: Geraldine | E21: 04:30 pm | F21: Ecografía de abdomen total
B22: CONFIRMADO | C22: CIMA | D22: Geraldine | F22: Ecografía de tiroides y paratiroides
B23: CONFIRMADO | C23: CIMA | D23: Geraldine | F23: Electrocardiograma
B24: CONFIRMADO | C24: CIMA | D24: Enrica | F24: Radiografía de tórax
B25: CONFIRMADO | C25: CIMA | D25: Enrica | F25: Ecografía de abdomen total
B26: CONFIRMADO | C26: CIMA | D26: Enrica | F26: Electrocardiograma
B27: CONFIRMADO | C27: CIMA | D27: Jair | F27: Electrocardiograma
B28: CONFIRMADO | C28: CIMA | D28: Jair | F28: Radiografía de tórax
B29: CONFIRMADO | C29: CIMA | D29: Jair | F29: Ecografía de abdomen total
B30: CONFIRMADO | C30: CIMA | D30: Jair | F30: Ecografía de tiroides y paratiroides
F31: Traslado centro médico - hotel | H31: 1
F32: Tiempo para desayunar
F33: Tarde libre
G34: =SUM(G10:G33) -> 1 | H34: =SUM(H10:H33) -> 5

Sheet Detalle de los servicios
B4: DETALLE DE SERVICIOS | C4: =COSTEO!P4 -> Geraldine | D4: =COSTEO!Q4 -> Enrica | E4: =COSTEO!R4 -> Jair | G4: DETALLE DE SERVICIOS | H4: Jair
B5: =COSTEO!E6 -> Domicilio | C5: =COSTEO!P6 -> 5.0505051 | D5: =COSTEO!Q6 -> 5.0505051 | E5: =COSTEO!R6 -> 5.0505051 | G5: Domicilio | H5: 5.0505051
B6: =COSTEO!E7 -> Antígeno de próstata | C6: =COSTEO!P7 | D6: =COSTEO!Q7 | E6: =COSTEO!R7 -> 19.480519 | G6: Antígeno de próstata | H6: 19.480519
B7: =COSTEO!E8 -> ALT- Alanina transferasa | C7: =COSTEO!P8 -> 8.6580087 | D7: =COSTEO!Q8 -> 8.6580087 | E7: =COSTEO!R8 -> 8.6580087 | G7: ALT- Alanina transferasa | H7: 8.6580087
B8: =COSTEO!E9 -> AST - aspartato transferasa | C8: =COSTEO!P9 -> 8.6580087 | D8: =COSTEO!Q9 -> 8.6580087 | E8: =COSTEO!R9 -> 8.6580087 | G8: AST - aspartato transferasa | H8: 8.6580087
B9: =COSTEO!E10 -> Bilirrubina total y directa | C9: =COSTEO!P10 -> 9.5238095 | D9: =COSTEO!Q10 -> 9.5238095 | E9: =COSTEO!R10 -> 9.5238095 | G9: Bilirrubina total y directa | H9: 9.5238095
B10: =COSTEO!E11 -> Colesterol HDL | C10: =COSTEO!P11 -> 4.3290043 | D10: =COSTEO!Q11 -> 4.3290043 | E10: =COSTEO!R11 -> 4.3290043 | G10: Colesterol HDL | H10: 4.3290043
B11: =COSTEO!E12 -> Colesterol LDL | C11: =COSTEO!P12 -> 5.1948052 | D11: =COSTEO!Q12 -> 5.1948052 | E11: =COSTEO!R12 -> 5.1948052 | G11: Colesterol LDL | H11: 5.1948052
B12: =COSTEO!E13 -> Colesterol total | C12: =COSTEO!P13 -> 6.4935065 | D12: =COSTEO!Q13 -> 6.4935065 | E12: =COSTEO!R13 -> 6.4935065 | G12: Colesterol total | H12: 6.4935065
B13: =COSTEO!E14 -> Creatinina | C13: =COSTEO!P14 -> 6.4935065 | D13: =COSTEO!Q14 -> 6.4935065 | E13: =COSTEO!R14 -> 6.4935065 | G13: Creatinina | H13: 6.4935065
B14: =COSTEO!E15 -> Coprológico | C14: =COSTEO!P15 -> 9.5238095 | D14: =COSTEO!Q15 -> 9.5238095 | E14: =COSTEO!R15 -> 9.5238095 | G14: Coprológico | H14: 9.5238095
B15: =COSTEO!E16 -> Ferritina | C15: =COSTEO!P16 -> 21.645022 | D15: =COSTEO!Q16 -> 21.645022 | E15: =COSTEO!R16 -> 21.645022 | G15: Ferritina | H15: 21.645022
B16: =COSTEO!E17 -> Gamma glutamil transferasa | C16: =COSTEO!P17 -> 9.5238095 | D16: =COSTEO!Q17 -> 9.5238095 | E16: =COSTEO!R17 -> 9.5238095 | G16: Gamma glutamil transferasa | H16: 9.5238095
... B32: =COSTEO!E33 -> Electrocardiograma | C32: =COSTEO!P33 -> 28.138528 | D32: =COSTEO!Q33 -> 28.138528 | E32: =COSTEO!R33 -> 28.138528 | G32: Electrocardiograma | H32: 28.138528
B33: =COSTEO!E34 -> ESPECIALISTAS | C33: =COSTEO!P34 | D33: =COSTEO!Q34 | E33: =COSTEO!R34 | G33: ESPECIALISTAS
B34: =COSTEO!E35 -> Cita con especialista en OFTALMOLOGÍA | C34: =COSTEO!P35 | D34: =COSTEO!Q35 -> 76.555024 | E34: =COSTEO!R35 -> 76.555024 | G34: Cita con especialista en OFTALMOLOGÍA | H34: 76.555024
B35: =COSTEO!E36 -> Cita con especialista en DERMATOLOGÍA | C35: =COSTEO!P36 -> 82.02324 | D35: =COSTEO!Q36 | E35: =COSTEO!R36 | G35: 04 Traslados hotel - clínica - por trayecto para las tres personas en el área del poblado | H35: 15.392015
B36: =COSTEO!E37 -> 04 Traslados hotel - clínica - por trayecto para las tres personas en el área del poblado | C36: =COSTEO!P37 -> 15.392015 | D36: =COSTEO!Q37 -> 15.392015 | E36: =COSTEO!R37 -> 15.392015 | G36: Medical Trip Colombia SAS - Acompañamiento virtual permanente en ESPAÑOL | H36: 18.227387
B37: =COSTEO!E38 -> Medical Trip Colombia SAS - Acompañamiento virtual permanente en ESPAÑOL | C37: =COSTEO!P38 -> 18.227387 | D37: =COSTEO!Q38 -> 18.227387 | E37: =COSTEO!R38 -> 18.227387 | G37: Acompañamiento presencial en español para citas y exámenes | H37: 16.404648
B38: =COSTEO!E39 -> Acompañamiento presencial en español para citas y exámenes | C38: =COSTEO!P39 -> 16.404648 | D38: =COSTEO!Q39 -> 16.404648 | E38: =COSTEO!R39 -> 16.404648 | G38: 4 * 1000 | H38: 2.1506302
B39: =COSTEO!H43 -> 4 * 1000 | C39: =COSTEO!P43 -> 2.0627369 | D39: =COSTEO!Q43 -> 1.98514 | E39: =COSTEO!R43 -> 2.1506302 | G39: Transferencia nacional | H39: 3.1168831
B40: =COSTEO!H44 -> Transferencia nacional | C40: =COSTEO!P44 -> 1.5584416 | D40: =COSTEO!Q44 -> 1.5584416 | E40: =COSTEO!R44 -> 1.5584416 | G40: TOTAL A PAGAR | H40: 565.40668
B41: TOTAL A PAGAR | C41: =SUM(C5:C40) -> 519.44501 | D41: =SUM(D5:D40) -> 499.67532 | E41: =SUM(E5:E40) -> 563.84824
B44: =B4 -> DETALLE DE SERVICIOS | C44: =C4 -> Geraldine
B45: =B5 -> Domicilio | C45: =C5 -> 5.0505051
B46: =B7 -> ALT- Alanina transferasa | C46: =C7 -> 8.6580087
B47: =B8 -> AST - aspartato transferasa | C47: =C8 -> 8.6580087
B48: =B9 -> Bilirrubina total y directa | C48: =C9 -> 9.5238095
B49: =B10 -> Colesterol HDL | C49: =C10 -> 4.3290043
B50: =B11 -> Colesterol LDL | C50: =C11 -> 5.1948052
B51: =B12 -> Colesterol total | C51: =C12 -> 6.4935065
B52: =B13 -> Creatinina | C52: =C13 -> 6.4935065
B53: =B14 -> Coprológico | C53: =C14 -> 9.5238095
B54: =B15 -> Ferritina | C54: =C15 -> 21.645022
B55: =B16 -> Gamma glutamil transferasa | C55: =C16 -> 9.5238095
B56: =B17 -> Glucosa sérica | C56: =C17 -> 6.4935065
B57: =B18 -> Hemoglobina Glicosilada | C57: =C18 -> 19.480519
... B67: =B28 -> Vitamina D25 | C67: =C28 -> 28.138528
B68: =B30 -> Ecografía de abdomen total | C68: =C30 -> 60.606061
B69: =B31 -> Ecografía de tiroides y paratiroides | C69: =C31 -> 44.526902
...

Sheet  Confirmación de 
F1: CITA CONFIRMADA CON DERMATOLOGÍA EL TESORO
C2: Servicio
C3: Proveedor-sede
C4: Fecha
C5: Hora
C6: Cliente | D6: Medical Trip Colombia SAS
C7: Correo | D7: reservasmedical@gmail.com
C8: Teléfono | D8: 315 772 1914
C9: Paciente Nombre
C10: Paciente Nombre
C11: Paciente Apellido
C12: Pasaporte
C13: Fecha de nacimiento
C15: ALOJAMIENTO | D15: SOLICITUD DE RESERVA | F15: 0
C16: Servicio
C17: Fecha check in | D17: pendiente
C18: Fecha check out | D18: pendiente
C19: # noches | D19: 11 | F19: CITA CONFIRMADA CON OFTALMOLOGÍA SAN DIEGO
C20: Tipo de habitación
C21: Huésped
C22: Nombre | D22: Geraldine
C23: Nombre | D23: Joanne
C24: Apellido | D24: Tromp
C25: Pasaporte | D25: NYD6H38J5
C26: Fecha de nacimiento | D26: 18 de enero 1978
C27: Cliente a facturar | D27: Medical Trip Colombia SAS
C28: Correo | D28: reservasmedical@gmail.com
C29: Teléfono | D29: 315 772 1914
D32: SOLICITUD DE RESERVA de TRANSPORTE
C33: Fecha | D33: 21 de julio 2025
C34: Hora | D34: pendiente
C35: RECOGIDA | D35: Aeropuerto José María Córdoba
C36: Vuelo | D36: pendiente
C37: Ruta | D37: pendiente
C38: DESTINO | D38: Aruba-Medellin
C39: Pasajero nombres | D39: Geraldine Joanne
C40: Pasajero apellidos | D40: Tromp
C41: Pasaporte | D41: NYD6H38J5
C42: No pasajeros | D42: 3
C43: Equipaje | D43: 2 maletas de 23 kilos + 2 maletas de 10 kilos
...

Sheet Vuelo
F6: 2C6XZL
G8: 4PJ9VB
