Workbook

Sheet PASAPORTE
D1: Nombre | E1: Earnie | F1: Hotel | G1: Hotel selis
D2: Nombre | E2: Gregory | F2: Direccion | G2: Cra. 41 #9-12, El Poblado, Medellín
D3: Apellido | E3: Sterling
D4: Género: . | E4: Masculino
D5: Pasaporte | E5: NY3C42C08
D6: Fecha de nacimiento | E6: 25969
D7: Edad | E7: =2025-1971 -> 54
D8: Estado civil | E8: soltero
D10: Dirección
D11: Nacionalidad y domicilio: | E11: Curazao, Paises Bajos
D12: Email: | E12: Jernie@hotmail.com
D13: Teléfono | E13: =59996860442 -> 59996860442
D14: Profesión
D15: RH | E15: 0+
D16: Seguro | E16: SVB only
D17: Peso | E17: 104 kg
D18: Altura | E18: 1.78 m
D19: Idioma | E19: Español, Ingles,
D20: Estadia | E20: 27 de Noviembre -
D21: Salud
D24: Nombre | E24: Rosary
D25: Nombre | E25: Irene
D26: Apellido | E26: Bishop
D27: Género: . | E27: Femenino
D28: Pasaporte | E28: NUJ41D4C8
D29: Fecha de nacimiento | E29: 25102
D30: Edad | E30: =2025-1968 -> 57
D31: Estado civil | E31: Soltera
D32: Dirección
D33: Nacionalidad y domicilio: | E33: Curazao, Paises bajos
D34: Email: | E34: Roosebilly@hotmail.com
D35: Teléfono
D36: Profesión
D37: RH | E37: 59995223636
D38: Seguro
D39: Peso | E39: 71 kg
D40: Altura
D41: Idioma | E41: Neerlandes, poco Español, Ingles
D42: Estadia
D43: Salud

Sheet CARPETA-ARCHIVO
A1: ok
A3: EARNIE | G3: ROSARY | H3: CARPETA DIGITAL ENVIADA OK
A4: ARCHIVO DIGITAL | B4: LABORATORIOS CLÍNICOS | C4: ARCHIVO DIGITAL | D4: IMÁGENES DIAGNÓSTICAS | E4: ARCHIVO DIGITAL | F4: ESPECIALISTAS | G4: ARCHIVO DIGITAL | H4: LABORATORIOS CLÍNICOS | I4: ARCHIVO DIGITAL | J4: IMÁGENES DIAGNÓSTICAS | K4: ARCHIVO DIGITAL | L4: ESPECIALISTAS
A5: ok | B5: Antígeno de próstata | C5: ok | D5: Ecografía de abdomen total | E5: ok | F5: Oftalmología | G5: ok | H5: Citología cervical | I5: ok | J5: Ecografía de abdomen total | K5: ok | L5: Medicina Interna
A6: ok | B6: Vitamina D25 | C6: ok | D6: Radiografía de tórax | E6: ok | F6: Medicina Interna | G6: ok | H6: Vitamina D25 | I6: ok | J6: Radiografía de tórax
A7: ok | B7: Vitamina B12 | C7: ok | D7: Electrocardiograma | G7: ok | H7: Vitamina B12 | I7: ok | J7: Electrocardiograma
A8: ok | B8: Perfil lipídico (Colesterol HDL, Colesterol LDL, Colesterol total, Triglicéridos) | G8: ok | H8: Perfil lipídico (Colesterol HDL, Colesterol LDL, Colesterol total, Triglicéridos) | I8: ok | J8: Ecografía de mama
A9: ok | B9: Perfil Hepático (ALT- Alanina transferasa, AST - aspartato transferasa, Bilirrubina total y directa,Gama Glutamil transferasa) | G9: ok | H9: Perfil Hepático (Alanina transferasa, aspartato transferasa, Bilirrubina total y directa, Gama Glutamil transferasa) | I9: ok | J9: Electromiografia con Neuroconduccion de Miembros Superiores
A10: ok | B10: Perfil renal (Uroanálisis, Nitrógeno Ureico en Sangre (BUN), Creatinina) | G10: ok | H10: Perfil Renal (Creatinina, Uroanálisis, Bun)
A11: ok | B11: Hemograma completo | G11: ok | H11: Hemograma completo
A12: ok | B12: Hemoglobina glicosilada | G12: ok | H12: Hemoglobina glicosilada
A13: ok | B13: Ferritina | G13: ok | H13: Ferritina
A14: ok | B14: Glucosa sérica | G14: ok | H14: Glucosa sérica
A15: ok | B15: Perfil Tiroideo (T4 libre, TSH) | G15: ok | H15: Perfil Tiroideo (T4 libre, TSH)
A16: ok | B16: VDRL | G16: ok | H16: VDRL
A17: ok | B17: VIH 1 Y 2, Anticuerpos | G17: ok | H17: VIH 1 Y 2, Anticuerpos

Sheet ITINERARIO
B3: ITINERARIO: | E3: 27 Noviembre al 05 diciembre
F4: ACP horas | G4: Traslados cerca | H4: Lejos
C5: Dia 01 | D5: 45988 | E5: JUEVES - LLegada a Medellín
B6: Avianca | C6: confirmado | E6: Vuelo Curazao - Bogotá
B7: Avianca | C7: confirmado | D7: 05:00 pm | E7: Vuelo Bogotá - Medellín Avianca
B8: Aeroturex | C8: confirmado | E8: Traslado Aeropuerto - Hotel
A9: Cra. 41 #9-12, El Poblado, Medellín | B9: Hotel Selis | C9: Pasajero directamente | D9: 06:30 pm | E9: Alojamiento
B10: Yenny | C10: confirmado | E10: Recarga de datos en Bogotá
C11: Día 02 | D11: 45989 | E11: VIERNES
E12: Desayuno en el Hotel
B13: Yenny | C13: UBER | D13: 09:30 am | E13: Traslado Hotel - Centro médico | F13: 0.25 | G13: 1
A14: CLÍNICA DE OFTALMOLOGÍA SAN DIEGO | B14: confirmado | C14: Earnie | D14: 10:00 am | E14: Cita con especialista en OFTALMOLOGÍA
A15: CLÍNICA DE OFTALMOLOGÍA SAN DIEGO | B15: Si el doctor la ordena | C15: Earnie | D15: Si el doctor la ordena | E15: Tomografía óptica bilateral
B16: Yenny | C16: UBER | E16: Traslado centro médico - hotel | G16: 1
E17: Tarde libre
C18: Día 03 | D18: 45990 | E18: SÁBADO
E19: No desayunar - tomar agua - No poner nada en la piel cremas lociones - No intimidad tres días antes
D20: 05:00 am | E20: Iniciar a tomar agua - no orinar
A21: YENNY | B21: confirmado | D21: 05:45 am | E21: Traslado Hotel - Centro médico | F21: 0.5 | G21: 1
A22: CIMA | B22: confirmado | C22: Earnie - Rosary | D22: 06:00 am | E22: Ecografía de abdomen total
A23: CIMA | B23: confirmado | C23: Rosary | E23: Ecografía de mama
A24: CIMA | B24: confirmado | C24: Earnie - Rosary | D24: 06:40 am | E24: Radiografía de tórax
A25: CIMA | B25: confirmado | C25: Earnie - Rosary | D25: 07:00 am | E25: Toma de muestras de laboratorio clínico
A26: CIMA | B26: confirmado | C26: Rosary | D26: 07:20 am | E26: Citología
A27: CIMA | B27: confirmado | C27: Earnie - Rosary | D27: 07:50 am | E27: Electrocardiograma
A28: YENNY | B28: confirmado | E28: Traslado centro médico - hotel | G28: 1
E29: Resto del día libre
C30: Día 04 | D30: 45991 | E30: DOMINGO - Día libre
C31: Día 05 | D31: 45992 | E31: LUNES
E32: Desayuno en su hotel
E33: Traslado Hotel - Centro médico | F33: 0.25 | G33: 1
A34: Clínica Las Vegas | B34: Dr Manuel Dávila | C34: CONFIRMADO | D34: 10:00 am | E34: Cita con MEDICINA INTERNA
A35: Clínica Las Vegas | B35: Dr Manuel Dávila | C35: CONFIRMADO | D35: 11:00 am | E35: Cita con MEDICINA INTERNA
E36: Traslado centro médico - hotel | G36: 1
E37: Tarde libre
C38: Día 06 | D38: 45993 | E38: MARTES - día libre
C39: Día 07 | D39: 45994 | E39: MIÉRCOLES - día libre
C40: Día 08 | D40: 45995 | E40: JUEVES - día libre
B41: Yenny | E41: Traslado Hotel - Centro médico
A42: IPS LAs Vegas | B42: Rosary | C42: CONFIRMADO | D42: 5:00 pm | E42: Electromiografia con Neuroconduccion de Miembros Superiores
...

Sheet RVA243-1-COSTEO
Z2: Libro diario contable
B3: ARCHIVO | C3: ARCHIVO | D3: PAGOS | E3: RESERVA | J3: COSTO NETO | K3: COSTO NETO | M3: PRECIO VENTA PESOS | O3: PRECIO VENTA USD | R3: PAGOS | W3: ESTADO DE CUENTA | Z3: PAGOS
B4: Earnie | C4: Rosary | D4: Contabilidad | E4: Operativo | F4: Concepto | G4: Proveedor | H4: Valor | I4: Días | J4: Earnie | K4: Rosary | M4: Earnie | N4: Rosary | O4: Earnie | P4: Rosary | R4: Earnie | S4: Rosary | T4: Retención en la fuente | U4: Valor pagado | W4: Valor Neto cobrado al cliente | X4: DIFERENCIA | Z4: PROVEEDOR - NOMBRE COMERCIAL | AA4: ID | AB4: Fecha del pago | AC4: Valor del pago | AD4: Forma de pago de donde salió el dinero | AE4: Tipo de movimiento | AF4: Comentarios
B5: App | C5: App | D5: Pre - compra | E5: Emitida | F5: Póliza de asistencia médica al viajero - producto visitor por 07 días | G5: Colasistencia | H5: 3000 | I5: 7 | J5: =H5*I5 -> 21000 | K5: =H5*I5 -> 21000 | M5: =J5/0.7 -> 30000 | N5: =K5/0.7 -> 30000 | O5: =M5/$I$53 -> 8.1081081 | P5: =N5/$I$53 -> 8.1081081 | R5: =2750*9 -> 24750 | S5: =2750*9 -> 24750 | T5: 0 | U5: =R5+S5-T5 -> 49500 | W5: =K5+J5 -> 42000 | X5: =W5-U5 -> -7500
D6: Facturado | E6: Confirmado | F6: Traslado aeropuerto - hotel - aeropuerto en CARRO | G6: Aeroturex | H6: 151000 | I6: 2 | J6: =H6*I6 -> 302000 | M6: =J6/0.95 -> 317894.74 | O6: =M6/$I$53 -> 85.917496 | R6: 151000 | S6: 151000 | T6: =(R6+S6)*3.5% -> 10570 | U6: =R6+S6-T6 -> 291430 | W6: =K6+J6 -> 302000 | X6: =W6-U6 -> 10570 | Z6: Aeroturex | AC6: =U6 -> 291430
F7: PAQUETE DE CHEQUEO MÉDICO | J7: 1300000 | K7: 1350000 | O7: 470 | P7: 485 | S7: 691000 | Z7: CIMA | AB7: 45987 | AC7: 1000000 | AD7: JURIDICA BANCOLOMBIA | AE7: TRANSFERENCIA BANCARIA | AF7: PRIMER DEPÓSITO
F8: LABORATORIOS CLÍNICOS | Z8: CIMA | AB8: 45994 | AC8: 102435 | AD8: Jurídica Bancolombia | AE8: Transferencia Bancaria
C9: Rosary | E9: NO SE REALIZÓ | F9: Cropológico | G9: ECHAVARRIA | J9: No | M9: No | O9: No
C10: ok resultado | D10: Facturado | E10: Confirmado | F10: Citología | G10: CIMA | J10: No | M10: No | O10: No
B11: ARCHIVADO | D11: Facturado | E11: Confirmado | F11: Antígeno de próstata | G11: CIMA | K11: No | N11: No | P11: No
B12: ARCHIVADO | C12: ARCHIVADO | D12: Facturado | E12: Confirmado | F12: Vitamina D25 | G12: CIMA
B13: ARCHIVADO | C13: ARCHIVADO | D13: Facturado | E13: Confirmado | F13: Vitamina B12 | G13: CIMA
F14: Perfil lipídico
B15: ARCHIVADO | C15: ARCHIVADO | D15: Facturado | E15: Confirmado | F15: Colesterol HDL | G15: CIMA
B16: ARCHIVADO | C16: ARCHIVADO | D16: Facturado | E16: Confirmado | F16: Colesterol LDL | G16: CIMA
B17: ARCHIVADO | C17: ARCHIVADO | D17: Facturado | E17: Confirmado | F17: Colesterol total | G17: CIMA
B18: ARCHIVADO | C18: ARCHIVADO | D18: Facturado | E18: Confirmado | F18: Triglicéridos | G18: CIMA
F19: Perfil Hepático
B20: ARCHIVADO | C20: ARCHIVADO | D20: Facturado | E20: Confirmado | F20: ALT- Alanina transferasa | G20: CIMA
B21: ARCHIVADO | C21: ARCHIVADO | D21: Facturado | E21: Confirmado | F21: AST - aspartato transferasa | G21: CIMA
B22: ARCHIVADO | C22: ARCHIVADO | D22: Facturado | E22: Confirmado | F22: Bilirrubina total y directa | G22: CIMA
B23: ARCHIVADO | C23: ARCHIVADO | D23: Facturado | E23: Confirmado | F23: Gama Glutamil transferasa | G23: CIMA
F24: Perfil Renal
B25: ARCHIVADO | C25: ARCHIVADO | D25: Facturado | E25: Confirmado | F25: Creatinina | G25: CIMA
B26: ARCHIVADO | C26: ARCHIVADO | D26: Facturado | E26: Confirmado | F26: Uroanálisis | G26: CIMA
B27: ARCHIVADO | C27: ARCHIVADO | D27: Facturado | E27: Confirmado | F27: Bun | G27: CIMA
F28: Sangre
B29: ARCHIVADO | C29: ok resultado | D29: Facturado | E29: Confirmado | F29: Hemograma completo | G29: CIMA
B30: ARCHIVADO | C30: ARCHIVADO | D30: Facturado | E30: Confirmado | F30: Hemoglobina glicosilada | G30: CIMA
B31: ARCHIVADO | C31: ARCHIVADO | D31: Facturado | E31: Confirmado | F31: Ferritina | G31: CIMA
B32: ARCHIVADO | C32: ARCHIVADO | D32: Facturado | E32: Confirmado | F32: Glucosa sérica | G32: CIMA
F33: Perfil Tiroideo
B34: ARCHIVADO | C34: ARCHIVADO | D34: Facturado | E34: Confirmado | F34: T4 libre | G34: CIMA
B35: ARCHIVADO | C35: ARCHIVADO | D35: Facturado | E35: Confirmado | F35: TSH | G35: CIMA
F36: Enfermedades de transmisión sexual
B37: ARCHIVADO | C37: ARCHIVADO | D37: Facturado | E37: Confirmado | F37: VDRL serología | G37: CIMA
B38: ARCHIVADO | C38: ok resultado | D38: Facturado | E38: Confirmado | F38: VIH 1 Y 2, Anticuerpos | G38: CIMA
F39: IMÁGENES DIAGNÓSTICAS
B40: ARCHIVADO | C40: ARCHIVADO | D40: Facturado | E40: Confirmado | F40: Radiografía de tórax | G40: CIMA
B41: ARCHIVADO | C41: ARCHIVADO | D41: Facturado | E41: Confirmado | F41: Ecografía de abdomen total | G41: CIMA
...

Sheet RVA243-2-COSTEO
B3: ARCHIVO | C3: PAGOS | D3: RESERVA | N3: PAGOS
C4: Contabilidad | D4: Operativo | E4: Concepto | F4: Cantidad | G4: Precio unitario | H4: Importe | K4: Retención en la fuente | L4: Valor pagado | N4: PROVEEDOR - NOMBRE COMERCIAL | O4: ID | P4: Fecha del pago | Q4: Valor del pago | R4: Forma de pago de donde salió el dinero | S4: Tipo de movimiento | T4: Comentarios
C5: Pagado | D5: Confirmado | E5: Electromiografía de miembros superiores | F5: 1,00 Unidades | G5: 94,00 | H5: $ 94,00 | J5: 270000 | K5: 0 | L5: =J5-K5 -> 270000 | N5: IPS ELECTRODIAGNÓSTICO | P5: 45995 | Q5: 270000 | R5: JURIDICA BANCOLOMBIA | S5: TRANSFERENCIA BANCARIA
D6: Confirmado | E6: Acompañamiento presencial en español para citas y exámenes para 8 horas diurnas | F6: 0,25 Unidades | G6: 59,00 | H6: $ 14,75
D7: Confirmado | E7: Traslados hotel-clínica en CARRO-privado conductor habla español-Hotel en el Poblado | F7: 2,00 Unidades | G7: 10,00 | H7: $ 20,00
E8: Total | F8: $ 128,75

Sheet CONFIRMACIÓN DE SERVICIOS
H1: CONFIRMACION DE CITA INTERNISTA-STERLING Y ROSARY
B3: PASAJERO RESERVO DIRECTAMENTE
B4: Hotel | C4: Hotel Selis | T4: 320 379 4893
B5: Direccion | C5: Cra. 41 #9-12, El Poblado, Medellín | T5: 321 755 1679
A7: CONFIRMACIÓN DE CITA OFTALMOLOGIA-STERLING

Sheet PAGOS
B3: INTERNISTA | G3: OFTALMOLOGIA | K3: CIMA EXÁMENES
B23: INTERNISTA

Sheet ANTERIOR -COSTEO
Z2: Libro diario contable
B3: ARCHIVO | C3: ARCHIVO | D3: PAGOS | E3: RESERVA | J3: COSTO NETO | K3: COSTO NETO | M3: PRECIO VENTA PESOS | O3: PRECIO VENTA USD | R3: PAGOS | W3: ESTADO DE CUENTA | Z3: PAGOS
B4: Earnie | C4: Rosary | D4: Contabilidad | E4: Operativo | F4: Concepto | G4: Proveedor | H4: Valor | I4: Días | J4: Earnie | K4: Rosary | M4: Earnie | N4: Rosary | O4: Earnie | P4: Rosary | T4: Retención en la fuente | U4: Valor pagado | W4: Valor Neto cobrado al cliente | X4: DIFERENCIA | Z4: PROVEEDOR - NOMBRE COMERCIAL | AA4: ID | AB4: Fecha del pago | AC4: Valor del pago | AD4: Forma de pago de donde salió el dinero | AE4: Tipo de movimiento | AF4: Comentarios
B5: App | C5: App | D5: Pre - compra | E5: Emitida | F5: Póliza de asistencia médica al viajero - producto visitor por 07 días | G5: Colasistencia | H5: 3000 | I5: 7 | J5: =H5*I5 -> 21000 | K5: =H5*I5 -> 21000 | M5: =J5/0.7 -> 30000 | N5: =K5/0.7 -> 30000 | O5: =M5/$I$54 -> 8.1081081 | P5: =N5/$I$54 -> 8.1081081
B6: Earnie | F6: Recarga 20 gigas de datos | H6: 25000 | I6: 1 | J6: =H6*I6 -> 25000 | M6: =J6/0.7 -> 35714.286 | N6: =K6/0.7 -> 0 | O6: =M6/$I$54 -> 9.6525097 | P6: =N6/$I$54 -> 0
F7: Traslado aeropuerto - hotel - aeropuerto en CARRO | H7: 151000 | I7: 2 | J7: =H7*I7 -> 302000 | M7: =J7/0.95 -> 317894.74 | N7: =K7/0.95 -> 0 | O7: =M7/$I$54 -> 85.917496 | P7: =N7/$I$54 -> 0
F8: PAQUETE DE CHEQUEO MÉDICO | J8: 1300000 | K8: 1350000 | O8: 470 | P8: 485
F9: LABORATORIOS CLÍNICOS
C10: Rosary | F10: Citología | G10: CIMA | J10: No | M10: No | O10: No
B11: Earnie | F11: Antígeno de próstata | G11: CIMA | K11: No | N11: No | P11: No
B12: Earnie | C12: Rosary | F12: Vitamina D25 | G12: CIMA
B13: Earnie | C13: Rosary | F13: Vitamina B12 | G13: CIMA
F14: Perfil lipídico
B15: Earnie | C15: Rosary | F15: Colesterol HDL | G15: CIMA
B16: Earnie | C16: Rosary | F16: Colesterol LDL | G16: CIMA
B17: Earnie | C17: Rosary | F17: Colesterol total | G17: CIMA
B18: Earnie | C18: Rosary | F18: Triglicéridos | G18: CIMA
F19: Perfil Hepático
B20: Earnie | C20: Rosary | F20: ALT- Alanina transferasa | G20: CIMA
B21: Earnie | C21: Rosary | F21: AST - aspartato transferasa | G21: CIMA
B22: Earnie | C22: Rosary | F22: Bilirrubina total y directa | G22: CIMA
B23: Earnie | C23: Rosary | F23: Gama Glutamil transferasa | G23: CIMA
F24: Perfil Renal
B25: Earnie | C25: Rosary | F25: Creatinina | G25: CIMA
B26: Earnie | C26: Rosary | F26: Uroanálisis | G26: CIMA
B27: Earnie | C27: Rosary | F27: Bun | G27: CIMA
F28: Sangre
B29: Earnie | C29: Rosary | F29: Hemograma completo | G29: CIMA
B30: Earnie | C30: Rosary | F30: Hemoglobina glicosilada | G30: CIMA
B31: Earnie | C31: Rosary | F31: Ferritina | G31: CIMA
B32: Earnie | C32: Rosary | F32: Glucosa sérica | G32: CIMA
F33: Perfil Tiroideo
B34: Earnie | C34: Rosary | F34: T4 libre | G34: CIMA
B35: Earnie | C35: Rosary | F35: TSH | G35: CIMA
F36: Enfermedades de transmisión sexual
B37: Earnie | C37: Rosary | F37: VDRL serología | G37: CIMA
B38: Earnie | C38: Rosary | F38: VIH 1 Y 2, Anticuerpos | G38: CIMA
F39: IMÁGENES DIAGNÓSTICAS
B40: Earnie | C40: Rosary | F40: Radiografía de tórax | G40: CIMA
B41: Earnie | C41: Rosary | F41: Ecografía de abdomen total | G41: CIMA
...

Sheet DETALLE
B3: DETALLE DE LOS SERVICIOS
B4: ='ANTERIOR -COSTEO'!F4 -> Concepto | C4: ='ANTERIOR -COSTEO'!O4 -> Earnie | D4: ='ANTERIOR -COSTEO'!P4 -> Rosary
B5: ='ANTERIOR -COSTEO'!F5 -> Póliza de asistencia médica al viajero - producto visitor por 07 días | C5: ='ANTERIOR -COSTEO'!O5 -> 8.1081081 | D5: ='ANTERIOR -COSTEO'!P5 -> 8.1081081
B6: ='ANTERIOR -COSTEO'!F6 -> Recarga 20 gigas de datos | C6: ='ANTERIOR -COSTEO'!O6 -> 9.6525097
B7: ='ANTERIOR -COSTEO'!F7 -> Traslado aeropuerto - hotel - aeropuerto en CARRO | C7: ='ANTERIOR -COSTEO'!O7 -> 85.917496
B8: ='ANTERIOR -COSTEO'!F8 -> PAQUETE DE CHEQUEO MÉDICO | C8: ='ANTERIOR -COSTEO'!O8 -> 470 | D8: ='ANTERIOR -COSTEO'!P8 -> 485
B9: ='ANTERIOR -COSTEO'!F9 -> LABORATORIOS CLÍNICOS | C9: ='ANTERIOR -COSTEO'!O9 | D9: ='ANTERIOR -COSTEO'!P9
B10: ='ANTERIOR -COSTEO'!F10 -> Citología | C10: ='ANTERIOR -COSTEO'!O10 -> No | D10: ='ANTERIOR -COSTEO'!P10
B11: ='ANTERIOR -COSTEO'!F11 -> Antígeno de próstata | C11: ='ANTERIOR -COSTEO'!O11 | D11: ='ANTERIOR -COSTEO'!P11 -> No
B12: ='ANTERIOR -COSTEO'!F12 -> Vitamina D25 | C12: ='ANTERIOR -COSTEO'!O12 | D12: ='ANTERIOR -COSTEO'!P12
B13: ='ANTERIOR -COSTEO'!F13 -> Vitamina B12 | C13: ='ANTERIOR -COSTEO'!O13 | D13: ='ANTERIOR -COSTEO'!P13
B14: ='ANTERIOR -COSTEO'!F14 -> Perfil lipídico | C14: ='ANTERIOR -COSTEO'!O14 | D14: ='ANTERIOR -COSTEO'!P14
B15: ='ANTERIOR -COSTEO'!F15 -> Colesterol HDL | C15: ='ANTERIOR -COSTEO'!O15 | D15: ='ANTERIOR -COSTEO'!P15
B16: ='ANTERIOR -COSTEO'!F16 -> Colesterol LDL | C16: ='ANTERIOR -COSTEO'!O16 | D16: ='ANTERIOR -COSTEO'!P16
B17: ='ANTERIOR -COSTEO'!F17 -> Colesterol total | C17: ='ANTERIOR -COSTEO'!O17 | D17: ='ANTERIOR -COSTEO'!P17
B18: ='ANTERIOR -COSTEO'!F18 -> Triglicéridos | C18: ='ANTERIOR -COSTEO'!O18 | D18: ='ANTERIOR -COSTEO'!P18
B19: ='ANTERIOR -COSTEO'!F19 -> Perfil Hepático | C19: ='ANTERIOR -COSTEO'!O19 | D19: ='ANTERIOR -COSTEO'!P19
... B49: ='ANTERIOR -COSTEO'!F49 -> Servicios Medical Trip Colombia: Acompañamiento Virtual y presencial | C49: ='ANTERIOR -COSTEO'!O49 | D49: ='ANTERIOR -COSTEO'!P49
B50: Impuesto bancario 4 * 1000 | C50: ='ANTERIOR -COSTEO'!O53 -> 3.1036606 | D50: ='ANTERIOR -COSTEO'!P53 -> 1.9708831
B51: TOTAL A PAGAR EN DÓLARES | C51: =SUM(C5:C50) -> 777.9604 | D51: =SUM(D5:D50) -> 495.07899
B52: ='ANTERIOR -COSTEO'!F51 | C52: ='ANTERIOR -COSTEO'!O51 | D52: ='ANTERIOR -COSTEO'!P51
B53: ='ANTERIOR -COSTEO'!F52
B54: ='ANTERIOR -COSTEO'!F53
B55: ='ANTERIOR -COSTEO'!F54
B56: ='ANTERIOR -COSTEO'!F55 | C56: ='ANTERIOR -COSTEO'!O55 | D56: ='ANTERIOR -COSTEO'!P55
B57: ='ANTERIOR -COSTEO'!F56 | C57: ='ANTERIOR -COSTEO'!O56 | D57: ='ANTERIOR -COSTEO'!P56
B58: ='ANTERIOR -COSTEO'!F57 | C58: ='ANTERIOR -COSTEO'!O57 | D58: ='ANTERIOR -COSTEO'!P57
B59: ='ANTERIOR -COSTEO'!F58 | C59: ='ANTERIOR -COSTEO'!O58 | D59: ='ANTERIOR -COSTEO'!P58
B60: ='ANTERIOR -COSTEO'!F59 | C60: ='ANTERIOR -COSTEO'!O59 | D60: ='ANTERIOR -COSTEO'!P59
C61: ='ANTERIOR -COSTEO'!O60 | D61: ='ANTERIOR -COSTEO'!P60
C62: ='ANTERIOR -COSTEO'!O61 | D62: ='ANTERIOR -COSTEO'!P61
C63: ='ANTERIOR -COSTEO'!O62 | D63: ='ANTERIOR -COSTEO'!P62
C64: ='ANTERIOR -COSTEO'!O63 | D64: ='ANTERIOR -COSTEO'!P63
C65: ='ANTERIOR -COSTEO'!O64 | D65: ='ANTERIOR -COSTEO'!P64
C66: ='ANTERIOR -COSTEO'!O65 | D66: ='ANTERIOR -COSTEO'!P65
C67: ='ANTERIOR -COSTEO'!O66 | D67: ='ANTERIOR -COSTEO'!P66
C68: ='ANTERIOR -COSTEO'!O67 | D68: ='ANTERIOR -COSTEO'!P67
C69: ='ANTERIOR -COSTEO'!O68 | D69: ='ANTERIOR -COSTEO'!P68
C70: ='ANTERIOR -COSTEO'!O69 | D70: ='ANTERIOR -COSTEO'!P69
C71: ='ANTERIOR -COSTEO'!O70 | D71: ='ANTERIOR -COSTEO'!P70
...

Sheet VUELO
F2: BU5QSW | G2: BU5QSW
L5: BU5QSW
L6: BISHOP
L30: AV9557
L31: 0.42152778
