Workbook

Sheet Pasaporte - HC
A18: Nombre | B18: SUZETTE | D18: Nombre | E18: HERIBERTO | G18: Nombre | H18: NAOMI
A19: Nombre | B19: IGNACIA | D19: Nombre | E19: HILARIO
A20: Apellido | B20: CLIFTON | D20: Apellido | E20: FRANCISKA
A21: Apellido de casada | D21: Apellido de casado
A22: Género: . | B22: FEMENINO | D22: Género: . | E22: MASCULINO
A23: Pasaporte | B23: NUHF4L459 | D23: Pasaporte | E23: NN89475H6
A24: Fecha de nacimiento | B24: 23954 | D24: Fecha de nacimiento | E24: 21260
A25: Edad | B25: 59 | D25: Edad | E25: 67
A26: Estado civil | D26: Estado civil
A27: Dirección | D27: Dirección
A28: Nacionalidad y domicilio: | B28: CURAZAO | D28: Nacionalidad y domicilio: | E28: CURAZAO
A29: Email: | B29: Susyclifton31@gmail.com | D29: Email: | E29: Susyclifton31@gmail.com
A30: Teléfono | B30: 599 9 563 6389 | D30: Teléfono | E30: 5999 528 4833 | G30: Teléfono | H30: 599 9 515 1143
A31: Profesión | D31: Profesión
A32: RH | B32: O + | D32: RH | E32: O +
A33: Seguro | B33: SVB | D33: Seguro | E33: SVB
A34: Peso | B34: 89 kg | D34: Peso | E34: 82 kg
A35: Altura | B35: 1.58 | D35: Altura | E35: 1.68
A36: Idioma | B36: Papiameto, Spanish, English | D36: Idioma | E36: Papiameto, Spanish, English
D38: Salud

Sheet CARPERA - ARCHIVO
A2: SUZETTE | B2: CARPETA MEDICA DIGITAL ENVIADA | G2: HERIBERTO | H2: CARPETA MEDICA DIGITAL ENVIADA
A3: ARCHIVO DIGITAL | B3: LABORATORIOS CLÍNICOS | C3: ARCHIVO DIGITAL | D3: IMÁGENES DIAGNÓSTICAS | E3: ARCHIVO DIGITAL | F3: ESPECIALISTAS | G3: ARCHIVO DIGITAL | H3: LABORATORIOS CLÍNICOS | I3: ARCHIVO DIGITAL | J3: IMÁGENES DIAGNÓSTICAS | K3: ARCHIVO DIGITAL | L3: ESPECIALISTAS
A4: ok | B4: Citología cervical | C4: ok | D4: Ecografía de abdomen total | E4: ok | F4: Cardiologo-Internista | G4: ok | H4: Antígeno de próstata | I4: ok | J4: Ecografía de abdomen total | K4: ok | L4: Cardiologo-Internista
A5: ok | B5: Coprológico | C5: ok | D5: Ecografía de mama | G5: ok | H5: Coprológico | I5: ok | J5: Radiografía de tórax | K5: ok | L5: Urologo
A6: ok | B6: Vitamina D25 | C6: ok | D6: Radiografía de tórax | G6: ok | H6: Vitamina D25 | I6: ok | J6: Electrocardiograma
A7: ok | B7: Vitamina B12 | C7: ok | D7: Electrocardiograma | G7: ok | H7: Vitamina B12 | I7: ok | J7: Ecocardiografía
A8: ok | B8: Perfil lipídico (Colesterol HDL, Colesterol LDL, Colesterol total, Triglicéridos) | C8: ok | D8: Ecocardiografía | G8: ok | H8: Perfil lipídico (Colesterol HDL, Colesterol LDL, Colesterol total, Triglicéridos) | I8: ok | J8: Prueba de esfuerzo
A9: ok | B9: Perfil Hepático (ALT, AST, Bilirrubina total y directa, Gamma Glutamil transferasa) | C9: ok | D9: Prueba de esfuerzo | G9: ok | H9: Perfil Hepático (ALT, AST, Bilirrubina total y directa, Gamma Glutamil transferasa) | I9: ok | J9: Doppler venoso de miembros inferiores
A10: ok | B10: Perfil Renal (Creatinina, Uroanálisis, Nitrógeno Ureico en Sangre (BUN)) | C10: ok | D10: Doppler venoso de miembros inferiores | G10: ok | H10: Perfil Renal (Creatinina, Uroanálisis, Nitrógeno Ureico en Sangre (BUN)) | I10: ok | J10: Doppler arterial miembros inferiores
A11: ok | B11: Hemograma completo | C11: ok | D11: Doppler arterial miembros inferiores | G11: ok | H11: Hemograma completo
A12: ok | B12: Hemoglobina glicosilada | G12: ok | H12: Hemoglobina glicosilada
A13: ok | B13: Ferritina | G13: ok | H13: Ferritina
A14: ok | B14: Glucosa sérica | G14: ok | H14: Glucosa sérica
A15: ok | B15: Perfil Tiroideo (T4 total, TSH) | G15: ok | H15: Perfil Tiroideo (T4 total, TSH)
A16: ok | B16: VDRL | G16: ok | H16: VDRL
A17: ok | B17: VIH 1 Y 2, Anticuerpos | G17: ok | H17: VIH 1 Y 2, Anticuerpos
A18: ok | B18: Homocisteína sérica (HCYSP) | G18: ok | H18: Homocisteína sérica (HCYSP)

Sheet ITINERARIO
F1: miercoles 08
B3: ITINERARIO: | F3: 05 - 10 OCTUBRE
B4: Dia | D4: Fecha | E4: Hora | F4: Actividad | G4: ACP horas | H4: Traslado cerca | I4: Traslado lejos
D5: 1 | E5: 45935 | F5: DOMINGO
F6: Vuelo Curazao - Medellín
B7: AEROTUREX | C7: CONFIRMADO | E7: 10:26 pm | F7: Traslado a aeropuerto - hotel
B8: BH EL POBLADO | C8: CONFIRMADO | F8: Alojamiento
D9: 2 | E9: 45936 | F9: LUNES
F10: No desayunar - no tomar agua
A11: DOMICILIO HOTEL | B11: ECHAVARRIA | C11: CONFIRMADO | D11: El - Ella | E11: 07:00 am | F11: Toma de muestras de sangre laboratorio clínico en su hotel
E12: 08:00 am | F12: Tiempo para desayunar
B13: JOHANNS | C13: CONFIRMADO | F13: Traslado Hotel - Centro médico | G13: 1 | H13: 1
A14: TESORO TORRE 2 | B14: IMÁGENES Y ESPECIALISTAS | C14: Sin Cita | F14: Radiografía panorámica dental
A15: TESORO TORRE 2 | B15: ALTA ESTÉTICA DENTAL | C15: CONFIRMADA | D15: El | E15: 11:00 am | F15: Cita con especialista en Odontología
F16: Tiempo para almorzar y conocer el centro comercial El Tesoro
B17: AEROTUREX | E17: 2:00 pm | F17: Traslado centro médico - hotel | H17: 1
F18: TARDE LIBRE
D19: 3 | E19: 45937 | F19: MARTES
F20: No desayunar - tomar agua
B21: JOHANNS | C21: CONFIRMADA | E21: 5:30 am | F21: Traslado Hotel - Centro médico | G21: 1 | H21: 1
A22: Ciudad del Rio, Cra 44 # 18 70 | B22: CIMA | C22: CONFIRMADA | D22: El - Ella | E22: 5:45 am | F22: Ecografía de abdomen total
A23: Ciudad del Rio, Cra 44 # 18 71 | B23: CIMA | C23: CONFIRMADA | D23: Ella | F23: Ecografía de mama
A24: Ciudad del Rio, Cra 44 # 18 72 | B24: CIMA | C24: CONFIRMADA | D24: Ella | F24: Citología cervical
A25: Ciudad del Rio, Cra 44 # 18 73 | B25: CIMA | C25: CONFIRMADA | D25: El - Ella | F25: Radiografía de tórax
A26: Ciudad del Rio, Cra 44 # 18 74 | B26: CIMA | C26: CONFIRMADA | D26: El - Ella | F26: Electrocardiograma
A27: Ciudad del Rio, Cra 44 # 18 75 | B27: CIMA | C27: CONFIRMADA | D27: El - Ella | F27: Ecocardiografía
A28: Ciudad del Rio, Cra 44 # 18 76 | B28: CIMA | C28: CONFIRMADA | D28: El - Ella | E28: 6;40 am | F28: Prueba de esfuerzo
E29: 8:00 am | F29: Traslado Centro médico - Hotel | H29: 1
F30: Tiempo para desayunar y descansar
B31: AEROTUREX | C31: CAROLINA | E31: 11:00 am | F31: Traslado Hotel - Centro médico | H31: 1
A32: Piso 1 local 9628 Torre Medica 1 El Tesoro | B32: CEDIMED | C32: CONFIRMADA | D32: EL | E32: 12:00 pm | F32: Ecografía transrectal de próstata
A33: Piso 13 Torre Medica 1 El Tesoro | B33: INCARE | C33: CONFIRMADA | D33: Ella | E33: 1:00 pm | F33: Doppler venoso de miembros inferiores
A34: Piso 13 Torre Medica 1 El Tesoro | B34: INCARE | C34: CONFIRMADA | D34: Ella | E34: 1:15 pm | F34: Doppler arterial miembros inferiores
A35: Piso 13 Torre Medica 1 El Tesoro | B35: INCARE | C35: CONFIRMADA | D35: El | E35: 1:30 pm | F35: Doppler venoso de miembros inferiores
A36: Piso 13 Torre Medica 1 El Tesoro | B36: INCARE | C36: CONFIRMADA | D36: El | E36: 1:45 pm | F36: Doppler arterial miembros inferiores
F37: Tiempo para almorzar
F38: Traslado centro médico - hotel | H38: 1
F39: TARDE LIBRE
D40: 4 | E40: 45938 | F40: MIÉRCOLES
F41: Traslado Hotel - Parque el Poblado
...

Sheet COSTEO
X2: Libro diario contable
C3: PAGOS | M3: 3700 | P3: PAGOS | U3: ESTADO DE CUENTA | X3: PAGOS
B4: ACV documentos | C4: Contabilidad | D4: Operativo | E4: Concepto | F4: Proveedor | G4: Valor | H4: Días | I4: SUZETTE | J4: HERIBERTO | L4: Comisionable | M4: SUZETTE | N4: HERIBERTO | P4: SUZETTE | Q4: HERIBERTO | R4: RTE FUENTE | S4: Valor pagado | U4: Valor Neto cobrado al cliente | V4: DIFERENCIA | X4: PROVEEDOR - NOMBRE COMERCIAL | Y4: ID | Z4: Fecha del pago | AA4: Valor del pago | AB4: Forma de pago de donde salió el dinero | AC4: Tipo de movimiento | AD4: Comentarios
B5: APP | C5: PRECOMPRA | D5: EMITIDA | E5: Póliza de asistencia médica al viajero - producto visitor por 08 días | F5: Colasistencia | G5: 3500 | H5: 8 | I5: =G5*H5 -> 28000 | J5: =G5*H5 -> 28000 | L5: =I5/0.6 -> 46666.667 | M5: =L5/$M$3 -> 12.612613 | N5: =L5/$M$3 -> 12.612613 | P5: =2750*8 -> 22000 | Q5: =2750*8 -> 22000 | R5: 0 | S5: =P5+Q5-R5 -> 44000 | U5: =I5+J5 -> 56000 | V5: =U5-P5-Q5 -> 12000 | X5: COLASISTENCIA
C6: YENNY | D6: COMPRADA | E6: Sim card física | F6: Claro | G6: 6000 | H6: 1 | I6: =G6*H6 -> 6000 | L6: =I6/0.6 -> 10000 | M6: =L6/$M$3 -> 2.7027027 | P6: 5000 | R6: 0 | S6: =P6+Q6-R6 -> 5000 | U6: =I6+J6 -> 6000 | V6: =U6-P6-Q6 -> 1000 | X6: YENNY ROBERTO
C7: Recargada | D7: COMPRADA | E7: Recarga de datos 10 gigas x 7 dias | F7: Claro | G7: 12000 | H7: 1 | I7: =G7*H7 -> 12000 | L7: =I7/0.6 -> 20000 | M7: =L7/$M$3 -> 5.4054054 | P7: 12000
C8: Facturado | D8: CONFIRMADO | E8: Tour a Guatapé compartido | F8: Aeroturex | G8: 135000 | H8: 1 | I8: =G8*H8 -> 135000 | J8: =G8*H8 -> 135000 | L8: =I8/0.9 -> 150000 | M8: =L8/$M$3 -> 40.540541 | N8: =L8/$M$3 -> 40.540541
E9: Traslado hotel - parque del poblado - hotel | F9: Uber | G9: 25000 | H9: 2 | I9: =G9*H9 -> 50000 | L9: =I9/0.9 -> 55555.556 | M9: =L9/$M$3 -> 15.015015
D10: CONFIRMADO | E10: Traslado aeropuerto - hotel - aeropuerto Hotel HB Poblado | F10: Aeroturex | G10: 171000 | H10: 2 | I10: =G10*H10 -> 342000 | L10: =I10/0.98 -> 348979.59 | M10: =L10/$H$70 -> 94.318809 | P10: =171000*2 -> 342000
E11: Paquete de chequeo médico | I11: 1300000 | J11: 1350000 | M11: 470 | N11: 485
C12: PAGADO | D12: CONFIRMADO | E12: Citología cervical | F12: CIMA
C13: PAGADO | D13: CONFIRMADO | E13: Antígeno de próstata | F13: Echavarria | P13: 344555 | R13: 0 | S13: =P13+Q13 -> 344555 | X13: ECHAVARRIA | Z13: 45898 | AA13: 298955 | AB13: BANCOLOMBIA JURIDICA | AC13: TRANSFERENCIA
C14: PAGADO | D14: CONFIRMADO | E14: Coprológico | F14: Echavarria | Q14: 406055 | R14: 0 | S14: =P14+Q14 -> 406055 | X14: ECHAVARRIA | Z14: 45898 | AA14: 300455 | AB14: BANCOLOMBIA JURIDICA | AC14: TRANSFERENCIA
C15: PAGADO | D15: CONFIRMADO | E15: Vitamina D25 | F15: Echavarria | X15: ECHAVARRIA | Z15: 45933 | AA15: 151200 | AB15: BANCOLOMBIA JURIDICA | AC15: TRANSFERENCIA
C16: PAGADO | D16: CONFIRMADO | E16: Vitamina B12 | F16: Echavarria | P16: 840000 | R16: =P16*2% -> 16800 | S16: =P16-R16 -> 823200 | X16: CIMA | AA16: =S16+S17 -> 1517040
E17: Perfil lipídico | Q17: 708000 | R17: =Q17*2% -> 14160 | S17: =Q17-R17 -> 693840 | AA17: 1365823 | AB17: SALDO A FAVOR
C18: PAGADO | D18: CONFIRMADO | E18: Colesterol HDL | F18: Echavarria | X18: CIMA | Z18: 45937 | AA18: =AA16-AA17 -> 151217 | AB18: BANCOLOMBIA JURIDICA | AC18: TRANSFERENCIA
C19: PAGADO | D19: CONFIRMADO | E19: Colesterol LDL | F19: Echavarria
C20: PAGADO | D20: CONFIRMADO | E20: Colesterol total | F20: Echavarria
C21: PAGADO | D21: CONFIRMADO | E21: Triglicéridos | F21: Echavarria
E22: Perfil Hepático
C23: PAGADO | D23: CONFIRMADO | E23: ALT- Alanina transferasa | F23: Echavarria
C24: PAGADO | D24: CONFIRMADO | E24: AST - aspartato transferasa | F24: Echavarria
C25: PAGADO | D25: CONFIRMADO | E25: Bilirrubina total y directa | F25: Echavarria
C26: PAGADO | D26: CONFIRMADO | E26: Gama Glutamil transferasa | F26: Echavarria
E27: Perfil Renal
C28: PAGADO | D28: CONFIRMADO | E28: Creatinina | F28: Echavarria
C29: PAGADO | D29: CONFIRMADO | E29: Uroanálisis | F29: Echavarria
C30: PAGADO | D30: CONFIRMADO | E30: Nitrógeno Ureico en Sangre (BUN) | F30: Echavarria
E31: Sangre
C32: PAGADO | D32: CONFIRMADO | E32: Hemograma completo | F32: Echavarria
C33: PAGADO | D33: CONFIRMADO | E33: Hemoglobina glicosilada | F33: Echavarria
C34: PAGADO | D34: CONFIRMADO | E34: Ferritina | F34: Echavarria
C35: PAGADO | D35: CONFIRMADO | E35: Glucosa sérica | F35: Echavarria
E36: Perfil Tiroideo
C37: PAGADO | D37: CONFIRMADO | E37: T4 total | F37: Echavarria
C38: PAGADO | D38: CONFIRMADO | E38: TSH | F38: Echavarria
E39: Enfermedades de transmisión sexual
C40: PAGADO | D40: CONFIRMADO | E40: VDRL | F40: Echavarria
C41: PAGADO | D41: CONFIRMADO | E41: VIH 1 Y 2, Anticuerpos | F41: Echavarria
...

Sheet VUELO
A2: 7OTG77 | M2: CODIGO DE RVA
M3: 7OTG77

Sheet Confirmacion de servicios
B2: SUZETTE CLIFTON | H2: HERIBERTO FRANCISKA
B3: DUPLEX VENOSO MIEMBROS INFERIORES | H3: CITA ODONTOLOGICA | N3: RESERVA HOTAL PRIMERA NOCHE PAGADA
B19: DUPLEX ARTERIAL
N23: SOLICITUD DOMICILIO ECHAVARRIA
H24: DUPLEX VENOSO MIEMBROS INFERIORES | N24: Nombre | O24: SUZETTE
N25: Nombre | O25: IGNACIA
N26: Apellido | O26: CLIFTON
N27: Género: . | O27: FEMENINO
N28: Pasaporte | O28: NUHF4L459
N29: Fecha de nacimiento | O29: 23954
N30: Edad | O30: 59
N31: HOTEL | O31: Hotel BH El Poblado
N32: DIRECCIÓN | O32: Cra. 43 #9 Sur - 35
N33: HABITACIÓN | O33: Pendiente
B34: CITA CARDIOLOGIA | N34: FECHA: | O34: 45935
N35: SERVICIOS A DOMICILIO | O35: MEDICAL TRIP COLOMBIA
N38: Nombre | O38: HERIBERTO
N39: Nombre | O39: HILARIO
N40: Apellido | O40: FRANCISKA
H41: DUPLEX ARTERIAL | N41: Género: . | O41: MASCULINO
N42: Pasaporte | O42: NN89475H6
N43: Fecha de nacimiento | O43: 21321
N44: Edad | O44: 67
N45: HOTEL | O45: Hotel BH El Poblado
N46: DIRECCIÓN | O46: Cra. 43 #9 Sur - 35
N47: HABITACIÓN | O47: Pendiente
N48: FECHA: | O48: 45935
N49: SERVICIOS A DOMICILIO | O49: MEDICAL TRIP COLOMBIA
H59: CITA UROLOGIA
C71: 320 789 7803
H86: CITA CARDIOLOGIA

Sheet PAGOS
B3: PAGO LABORATORIOS ECHAVARRIA | E3: PAGO LABORATORIOS ECHAVARRIA | H3: PAGO INCARE | K3: IMAGENES Y ESPECIALISTAS

Sheet DETALLE DE LOS SERVICIOS
C5: DETALLE DE LOS SERVICIOS
C6: =COSTEO!E4 -> Concepto | D6: =COSTEO!M4 -> SUZETTE | E6: =COSTEO!N4 -> HERIBERTO
C7: =COSTEO!E5 -> Póliza de asistencia médica al viajero - producto visitor por 08 días | D7: =COSTEO!M5 -> 12.612613 | E7: =COSTEO!N5 -> 12.612613
C8: =COSTEO!E6 -> Sim card física | D8: =COSTEO!M6 -> 2.7027027 | E8: =COSTEO!N6
C9: =COSTEO!E7 -> Recarga de datos 10 gigas x 7 dias | D9: =COSTEO!M7 -> 5.4054054 | E9: =COSTEO!N7
C10: =COSTEO!E8 -> Tour a Guatapé compartido | D10: =COSTEO!M8 -> 40.540541 | E10: =COSTEO!N8 -> 40.540541
C11: =COSTEO!E9 -> Traslado hotel - parque del poblado - hotel | D11: =COSTEO!M9 -> 15.015015 | E11: =COSTEO!N9
C12: =COSTEO!E10 -> Traslado aeropuerto - hotel - aeropuerto Hotel HB Poblado | D12: =COSTEO!M10 -> 94.318809 | E12: =COSTEO!N10
C13: =COSTEO!E11 -> Paquete de chequeo médico | D13: =COSTEO!M11 -> 470 | E13: =COSTEO!N11 -> 485
C14: =COSTEO!E13 -> Antígeno de próstata | D14: No | E14: =COSTEO!N12
C15: =COSTEO!E12 -> Citología cervical | D15: =COSTEO!M12 | E15: No
C16: =COSTEO!E14 -> Coprológico | D16: =COSTEO!M14 | E16: =COSTEO!N14
C17: =COSTEO!E15 -> Vitamina D25 | D17: =COSTEO!M15 | E17: =COSTEO!N15
C18: =COSTEO!E16 -> Vitamina B12 | D18: =COSTEO!M16 | E18: =COSTEO!N16 | G18: =COSTEO!M13 | H18: =COSTEO!N13
C19: =COSTEO!E17 -> Perfil lipídico | D19: =COSTEO!M17 | E19: =COSTEO!N17 | G19: =COSTEO!M14 | H19: =COSTEO!N14
C20: =COSTEO!E18 -> Colesterol HDL | D20: =COSTEO!M18 | E20: =COSTEO!N18 | G20: =COSTEO!M15 | H20: =COSTEO!N15
C21: =COSTEO!E19 -> Colesterol LDL | D21: =COSTEO!M19 | E21: =COSTEO!N19 | G21: =COSTEO!M16 | H21: =COSTEO!N16
C22: =COSTEO!E20 -> Colesterol total | D22: =COSTEO!M20 | E22: =COSTEO!N20 | G22: =COSTEO!M17 | H22: =COSTEO!N17
C23: =COSTEO!E21 -> Triglicéridos | D23: =COSTEO!M21 | E23: =COSTEO!N21 | G23: =COSTEO!M18 | H23: =COSTEO!N18
C24: =COSTEO!E22 -> Perfil Hepático | D24: =COSTEO!M22 | E24: =COSTEO!N22 | G24: =COSTEO!M19 | H24: =COSTEO!N19
C25: =COSTEO!E23 -> ALT- Alanina transferasa | D25: =COSTEO!M23 | E25: =COSTEO!N23 | G25: =COSTEO!M20 | H25: =COSTEO!N20
C26: =COSTEO!E24 -> AST - aspartato transferasa | D26: =COSTEO!M24 | E26: =COSTEO!N24 | G26: =COSTEO!M21 | H26: =COSTEO!N21
C27: =COSTEO!E25 -> Bilirrubina total y directa | D27: =COSTEO!M25 | E27: =COSTEO!N25 | G27: =COSTEO!M22 | H27: =COSTEO!N22
C28: =COSTEO!E26 -> Gama Glutamil transferasa | D28: =COSTEO!M26 | E28: =COSTEO!N26 | G28: =COSTEO!M23 | H28: =COSTEO!N23
C29: =COSTEO!E27 -> Perfil Renal | D29: =COSTEO!M27 | E29: =COSTEO!N27 | G29: =COSTEO!M24 | H29: =COSTEO!N24
... C45: =COSTEO!E43 -> Radiografía de tórax | D45: =COSTEO!M43 | E45: =COSTEO!N43 | G45: =COSTEO!M40 | H45: =COSTEO!N40
C46: =COSTEO!E44 -> Ecografía de mama | D46: =COSTEO!M44 | E46: No | G46: =COSTEO!M41 | H46: =COSTEO!N41
C47: =COSTEO!E45 -> Ecografía de abdomen total | D47: =COSTEO!M45 | E47: =COSTEO!N45 | G47: =COSTEO!M42 | H47: =COSTEO!N42
C48: =COSTEO!E46 -> Electrocardiograma | D48: =COSTEO!M46 | E48: =COSTEO!N46 | G48: =COSTEO!M43 | H48: =COSTEO!N43
C49: =COSTEO!E47 -> Cita con especialista en INTERNISTA | D49: =COSTEO!M47 | E49: =COSTEO!N47 | G49: =COSTEO!M44 | H49: =COSTEO!N44
C50: =COSTEO!E48 -> 04 Traslados hotel - clínica por trayecto | D50: =COSTEO!M48 | E50: =COSTEO!N48 | G50: =COSTEO!M45 | H50: =COSTEO!N45
C51: =COSTEO!E49 -> Medical Trip Colombia SAS - Acompañamiento virtual y presencial para exámenes y citas | D51: =COSTEO!M49 | E51: =COSTEO!N49
C52: =COSTEO!E50 -> CHEQUEO ESPECÍFICO CORAZÓN | D52: =COSTEO!M49 | E52: =COSTEO!N49
C53: =COSTEO!E51 -> Homocisteína sérica (HCYSP) | D53: =COSTEO!M51 -> 34.340223 | E53: =COSTEO!N51 -> 34.340223
C54: =COSTEO!E52 -> Doppler arterial miembros inferiores | D54: =COSTEO!M52 -> 86.148649 | E54: =COSTEO!N52 -> 86.148649
C55: =COSTEO!E53 -> Doppler venoso de miembros inferiores | D55: =COSTEO!M53 -> 74.662162 | E55: =COSTEO!N53 -> 74.662162
C56: =COSTEO!E54 -> Ecografía del corazón - ecocardiografía | D56: =COSTEO!M54 -> 101.74881 | E56: =COSTEO!N54 -> 101.74881
C57: =COSTEO!E55 -> Prueba de esfuerzo cardíaco | D57: =COSTEO!M55 -> 81.081081 | E57: =COSTEO!N55 -> 81.081081
C58: =COSTEO!E56 -> Ecografía transrectal de próstata | D58: No | E58: =COSTEO!N56 -> 57.915058
C59: ESPECIALISTAS | D59: =COSTEO!F57 | E59: =COSTEO!G57
...
