Workbook

Sheet Pasaporte - HC
A18: Nombre | D18: Nombre | G18: Nombre
A19: Nombre | D19: Nombre | G19: Nombre
A20: Apellido | D20: Apellido | G20: Nombre
A21: Apellido de casada | D21: Apellido de casada | G21: Apellido
A22: Género: . | D22: Género: . | G22: Apellido de casada
A23: Pasaporte | D23: Pasaporte | G23: Género: .
A24: Fecha de nacimiento | D24: Fecha de nacimiento | G24: Pasaporte
A25: Edad | D25: Edad | G25: Fecha de nacimiento
A26: Estado civil | D26: Estado civil | G26: Edad
A27: Dirección | D27: Dirección | G27: Estado civil
A28: Nacionalidad y domicilio: | D28: Nacionalidad y domicilio: | G28: Dirección
A29: Email: | D29: Email: | G29: Nacionalidad y domicilio:
... A36: Idioma | D36: Idioma | G36: Altura
A37: Estadia: | G37: Idioma
D38: Salud
G39: Salud

Sheet ITINERARIO
B3: ITINERARIO: | E3: 03 - 12 OCTUBRE
B4: Dia | C4: Fecha | D4: Hora | E4: Actividad | F4: ACP horas | G4: VAN
D5: 45938 | E5: MIÉRCOLES
I7: Es su hermano
I8: Vista de Medellín
I9: Flores
I10: Sencillo naturaleza
I11: Atardecer
I12: 08 o 09 octubre
I13: Matriarca música en vivo
I14: 02 horas
I15: Letrero en Inglés
I18: ¿qué tipo de flores?

Sheet COSTEO ANTERIOR
U2: Libro diario contable
C3: PAGOS | L3: 3700 | N3: PAGOS | R3: ESTADO DE CUENTA | U3: PAGOS
B4: ACV documentos | C4: Contabilidad | D4: Operativo | E4: Concepto | F4: Proveedor | G4: Valor | K4: Comisionable | O4: RTE FUENTE | P4: Valor pagado | R4: Valor Neto cobrado al cliente | S4: DIFERENCIA | U4: PROVEEDOR - NOMBRE COMERCIAL | V4: ID | W4: Fecha del pago | X4: Valor del pago | Y4: Forma de pago de donde salió el dinero | Z4: Tipo de movimiento | AA4: Comentarios
E5: FOTOGRAFÍA Y VIDEO
C6: DSM | D6: Confirmado | E6: Registro de video Full - HD formato Horizontal 2:00 minutos | F6: CAMILO PEREZ | G6: 260000 | H6: 1 | I6: =G6*H6 -> 260000 | K6: =I6/0.9 -> 288888.89 | L6: =K6/$L$3 -> 78.078078 | N6: 260000 | U6: ANNE CAMILO PEREZ | W6: 45932 | X6: 100000 | Y6: JURIDICA BANCOLOMBIA | Z6: TRANSFERENCIA
C7: DSM | D7: Confirmado | E7: 30 a 40 fotografías - Editadas en full calidad | F7: CAMILO PEREZ | G7: 150000 | H7: 1 | I7: =G7*H7 -> 150000 | K7: =I7/0.9 -> 166666.67 | L7: =K7/$L$3 -> 45.045045 | N7: 150000 | U7: ANNE CAMILO PEREZ | W7: 45937 | X7: 240000 | Y7: JURIDICA BANCOLOMBIA | Z7: TRANSFERENCIA
C8: DSM | D8: Confirmado | E8: Piloto de Drone | F8: CAMILO PEREZ | G8: 200000 | H8: 1 | I8: =G8*H8 -> 200000 | N8: 200000 | U8: ANNE CAMILO PEREZ | W8: 45948 | X8: 240000 | Y8: JURIDICA BANCOLOMBIA | Z8: TRANSFERENCIA
E9: MÚSICA | U9: ANNE CAMILO PEREZ | W9: 45953 | X9: 30000 | Y9: JURIDICA BANCOLOMBIA | Z9: TRANSFERENCIA
C10: Yenny | D10: Confirmado | E10: Artista por 45 minutos | G10: 700000 | H10: 1 | I10: =G10*H10 -> 700000 | K10: =I10/0.9 -> 777777.78 | L10: =K10/$L$3 -> 210.21021 | N10: 500000
E11: DECORACIÓN
C12: DSM | D12: Confirmado | E12: Decorador | G12: 250000 | H12: 1 | I12: =G12*H12 -> 250000 | K12: =I12/0.9 -> 277777.78 | L12: =K12/$L$3 -> 75.075075
C13: DSM | D13: Confirmado | E13: Estructura combo arco - piso - letrero | G13: 180000 | H13: 1 | I13: =G13*H13 -> 180000 | K13: =I13/0.9 -> 200000 | L13: =K13/$L$3 -> 54.054054
C14: DSM | D14: Confirmado | E14: Decoración del arco de corazón con flores artificiales | G14: 695000 | H14: 1 | I14: =G14*H14 -> 695000 | K14: =I14/0.9 -> 772222.22 | L14: =K14/$L$3 -> 208.70871
C15: DSM | D15: Confirmado | E15: Velas blancas | G15: 10000 | H15: 5 | I15: =G15*H15 -> 50000 | K15: =I15/0.8 -> 62500 | L15: =K15/$L$3 -> 16.891892
C16: DSM | D16: Confirmado | E16: Tapete Rojo | G16: 30000 | H16: 1 | I16: =G16*H16 -> 30000 | K16: =I16/0.9 -> 33333.333 | L16: =K16/$L$3 -> 9.009009
C17: DSM | D17: Confirmado | E17: Pétalos de rosa artificiales | G17: 4000 | H17: 5 | I17: =G17*H17 -> 20000 | K17: =I17/0.9 -> 22222.222 | L17: =K17/$L$3 -> 6.006006
C18: DSM | D18: Confirmado | E18: Letrero con el nombre SHAINA | G18: 45000 | H18: 6 | I18: =G18*H18 -> 270000 | K18: =I18/0.9 -> 300000 | L18: =K18/$L$3 -> 81.081081
C19: DSM | D19: Confirmado | E19: Polvora FRIA 2 un solo disparo | G19: 130000 | H19: 2 | I19: =G19*H19 -> 260000 | K19: =I19/0.9 -> 288888.89 | L19: =K19/$L$3 -> 78.078078
E20: OBSEQUIO
C21: Yenny | D21: Confirmado | E21: Arreglo floral para la novia | G21: 400000 | H21: 1 | I21: =G21*H21 -> 400000 | K21: =I21/0.9 -> 444444.44 | L21: =K21/$L$3 -> 120.12012
E22: TRANSPORTE
C23: Yenny | D23: Confirmado | E23: Transporte decoración | G23: 80000 | H23: 2 | I23: =G23*H23 -> 160000 | K23: =I23/0.9 -> 177777.78 | L23: =K23/$L$3 -> 48.048048
E24: LOGISTICA
C25: DSM | D25: Confirmado | E25: Medical Trip Colombia | F25: Johana | G25: 600000 | H25: 1 | I25: =G25*H25 -> 600000 | K25: =I25/0.9 -> 666666.67 | L25: =K25/$L$3 -> 180.18018
H26: Total neto | I26: =SUM(I6:I25) -> 4225000 | L26: =SUM(L6:L25) -> 1210.5856
H27: 0.1 | I27: =I26/0.9 -> 4694444.4
G28: Gastos bancarios | H28: 4 * 1000 | I28: =I27*4/1000 -> 18777.778 | L28: =I28/H30 -> 5.0750751
G29: Gastos bancarios | H29: Transferencia internacional
G30: Tasa del dólar | H30: 3700 | I30: =SUM(I27:I29) -> 4713222.2
I31: =I30/$H$30 -> 1273.8438 | L31: =SUM(L26:L30) -> 1215.6607

Sheet RVA205- COSTEO
U2: Libro diario contable
C3: PAGOS | L3: 3700 | N3: PAGOS | R3: ESTADO DE CUENTA | U3: PAGOS
B4: ACV documentos | C4: Contabilidad | D4: Operativo | E4: Concepto | F4: Proveedor | G4: Valor | K4: Comisionable | O4: RTE FUENTE | P4: Valor pagado | R4: Valor Neto cobrado al cliente | S4: DIFERENCIA | U4: PROVEEDOR - NOMBRE COMERCIAL | V4: ID | W4: Fecha del pago | X4: Valor del pago | Y4: Forma de pago de donde salió el dinero | Z4: Tipo de movimiento | AA4: Comentarios
E5: ESPACIO PARA LA DECORACIÓN
D6: Confirmado | E6: Waira Balcón | G6: 250000 | H6: 1 | I6: =G6*H6 -> 250000 | K6: =I6/0.75 -> 333333.33 | L6: =K6/$L$3 -> 90.09009 | M6: OK | N6: 260000 | R6: =G6 -> 250000 | S6: =R6-N6 -> -10000 | U6: ANNE CAMILO PEREZ | W6: 45932 | X6: 100000 | Y6: JURIDICA BANCOLOMBIA | Z6: TRANSFERENCIA
E7: FOTOGRAFÍA Y VIDEO
C8: DSM | D8: Confirmado | E8: Registro de video Full - HD formato Horizontal 2:00 minutos | F8: CAMILO PEREZ | G8: 260000 | H8: 1 | I8: =G8*H8 -> 260000 | K8: =I8/0.8 -> 325000 | L8: =K8/$L$3 -> 87.837838 | N8: 260000 | R8: =G8 -> 260000 | S8: =R8-N8 -> 0 | U8: ANNE CAMILO PEREZ | W8: 45932 | X8: 100000 | Y8: JURIDICA BANCOLOMBIA | Z8: TRANSFERENCIA
D9: Confirmado | E9: 30 - 40 fotografías - Editadas en full calidad | F9: CAMILO PEREZ | G9: 150000 | H9: 1 | I9: =G9*H9 -> 150000 | K9: =I9/0.8 -> 187500 | L9: =K9/$L$3 -> 50.675676 | N9: 150000 | R9: =G9 -> 150000 | S9: =R9-N9 -> 0 | U9: ANNE CAMILO PEREZ | X9: =610000-X8 -> 510000 | Y9: JURIDICA BANCOLOMBIA | Z9: TRANSFERENCIA
D10: Confirmado | E10: Piloto Drone | F10: CAMILO PEREZ | G10: 200000 | H10: 1 | I10: =G10*H10 -> 200000 | K10: =I10/0.8 -> 250000 | L10: =K10/$L$3 -> 67.567568 | N10: 200000 | R10: =G10 -> 200000 | S10: =R10-N10 -> 0 | U10: ANNE CAMILO PEREZ
E11: MÚSICA
C12: Pagado | D12: Confirmado | E12: Pianista x 45 minutos | G12: 700000 | H12: 1 | I12: =G12*H12 -> 700000 | K12: =I12/0.8 -> 875000 | L12: =K12/$L$3 -> 236.48649 | N12: 500000 | R12: =G12 -> 700000 | S12: =R12-N12 -> 200000 | U12: ANDRES FELIPE MONTOYA | W12: 45932 | X12: 250000 | Y12: EFECTIVO YENNY CAMBIO USD | Z12: EFECTIVO
C13: Pagado | D13: Confirmado | E13: Violinista | G13: 500000 | H13: 1 | I13: =G13*H13 -> 500000 | K13: =I13/0.8 -> 625000 | L13: =K13/$L$3 -> 168.91892 | N13: 500000 | R13: =G13 -> 500000 | S13: =R13-N13 -> 0 | U13: ANDRES FELIPE MONTOYA | W13: 45936 | X13: 500000 | Y13: JENNY BANCOLOMBIA | Z13: TRASFERENCIA
E14: DECORACIÓN | U14: ANDRES FELIPE MONTOYA | W14: 45937 | X14: 250000 | Y14: JURIDICA BANCOLOMBIA | Z14: TRANSFERENCIA
C15: DSM | D15: Confirmado | E15: Estructura combo arco - piso - letrero | G15: 180000 | H15: 1 | I15: =G15*H15 -> 180000 | K15: =I15/0.9 -> 200000 | L15: =K15/$L$3 -> 54.054054 | N15: 180000 | R15: =G15 -> 180000 | S15: =R15-N15 -> 0 | U15: ALTIUM EVENTS | W15: 45936 | X15: 500000 | Y15: JENNY BANCOLOMBIA | Z15: TRANSFERENCIA
C16: DSM | D16: Confirmado | E16: Letrero con el nombre SHAINA | G16: 50000 | H16: 6 | I16: =G16*H16 -> 300000 | K16: =I16/0.85 -> 352941.18 | L16: =K16/$L$3 -> 95.389507 | N16: 300000 | R16: =I16 -> 300000 | S16: =R16-N16 -> 0 | U16: ALTIUM EVENTS | W16: 45932 | X16: 800000 | Y16: EFECTIVO YENNY CAMBIO USD | Z16: EFECTIVO
C17: DSM | D17: Confirmado | E17: Tapete Rojo | G17: 110000 | H17: 1 | I17: =G17*H17 -> 110000 | K17: =I17/0.9 -> 122222.22 | L17: =K17/$L$3 -> 33.033033 | N17: 110000 | R17: =I17 -> 110000 | S17: =R17-N17 -> 0 | U17: ALTIUM EVENTS | W17: 45937 | X17: 656000 | Y17: JURIDICA BANCOLOMBIA | Z17: TRANSFERENCIA
C18: DSM | D18: Confirmado | E18: Decoración del arco de corazón con flores naturales | G18: 695000 | H18: 1 | I18: =G18*H18 -> 695000 | K18: =I18/0.9 -> 772222.22 | L18: =K18/$L$3 -> 208.70871 | N18: 600000 | R18: =G18 -> 695000 | S18: =R18-N18 -> 95000
C19: DSM | D19: Confirmado | E19: Decorador | G19: 250000 | H19: 1 | I19: =G19*H19 -> 250000 | K19: =I19/0.9 -> 277777.78 | L19: =K19/$L$3 -> 75.075075 | N19: 0 | R19: =G19 -> 250000 | S19: =R19-N19 -> 250000
C20: DSM | D20: Confirmado | E20: Pétalos de rosa artificiales | G20: 4000 | H20: 5 | I20: =G20*H20 -> 20000 | K20: =I20/0.9 -> 22222.222 | L20: =K20/$L$3 -> 6.006006 | N20: 0 | R20: =I20 -> 20000 | S20: =R20-N20 -> 20000
C21: DSM | D21: Confirmado | E21: Velas blancas | G21: 13500 | H21: 8 | I21: =G21*H21 -> 108000 | K21: =I21/0.8 -> 135000 | L21: =K21/$L$3 -> 36.486486 | N21: =216000/2 -> 108000 | R21: =I21 -> 108000 | S21: =R21-N21 -> 0
C22: DSM | D22: Confirmado | E22: Polvora FRIA 2 un solo disparo | G22: 130000 | H22: 2 | I22: =G22*H22 -> 260000 | K22: =I22/0.9 -> 288888.89 | L22: =K22/$L$3 -> 78.078078 | N22: 80000 | R22: =I22 -> 260000 | S22: =R22-N22 -> 180000
E23: OBSEQUIO
C24: Pagado | D24: Confirmado | E24: Arreglo floral para la novia | G24: 400000 | H24: 1 | I24: =G24*H24 -> 400000 | K24: =I24/0.9 -> 444444.44 | L24: =K24/$L$3 -> 120.12012 | N24: 150000 | R24: =G24 -> 400000 | S24: =R24-N24 -> 250000
E25: TRANSPORTE
C26: Pagado | D26: Confirmado | E26: Transporte decoración | G26: 130000 | H26: 2 | I26: =G26*H26 -> 260000 | K26: =I26/0.9 -> 288888.89 | L26: =K26/$L$3 -> 78.078078 | N26: 260000 | R26: =I26 -> 260000 | S26: =R26-N26 -> 0
E27: LOGISTICA | U27: Johana Granados | V27: 45948 | W27: ACP | X27: 185250 | Y27: JURIDICA BANCOLOMBIA
C28: DSM | D28: Confirmado | E28: Medical Trip Colombia | F28: Johana | G28: 600000 | H28: 1 | I28: =G28*H28 -> 600000 | K28: =I28/0.8 -> 750000 | L28: =K28/$L$3 -> 202.7027 | U28: Johana Granados | V28: 45939 | W28: RVA205- UNIFORMES | Y28: 50000 | Z28: Johanns le dio en efectivo
C29: Pagado | D29: Confirmado | E29: Caja menor | H29: Total neto | I29: =SUM(I5:I28) -> 5243000 | L29: =SUM(L5:L28) -> 1689.3084 | U29: Johana Granados | V29: 45940 | W29: RVA205- SALON | X29: $300.000 (Ella pago $250.000 mil del salón del evento, y $ 50.000 de caja menor | Z29: Johanns le dio en efectivo
H30: 0.16 | I30: =I29/0.84 -> 6241666.7
G31: Gastos bancarios | H31: 4 * 1000 | I31: =I30*4/1000 -> 24966.667 | L31: =I31/H33 -> 6.7477477
G32: Gastos bancarios | H32: Transferencia internacional
G33: Tasa del dólar | H33: 3700 | I33: =SUM(I30:I32) -> 6266633.3
I34: =I33/$H$33 -> 1693.6847 | L34: =SUM(L29:L33) -> 1696.0562

Sheet PAGOS
B4: FOTOGRAFO DEPOSITO | F4: DEPOSITO FLORISTERIA | J4: DEPÓSITO MÚSICO

Sheet DETALLE DE LOS SERVICIOS
C2: PRESUPUESTO | D2: DÓLARES | F2: PRESUPUESTO FINAL | G2: DÓLARES
C3: ='COSTEO ANTERIOR'!E5 -> FOTOGRAFÍA Y VIDEO | D3: ='COSTEO ANTERIOR'!L5 | F3: ='RVA205- COSTEO'!E5 -> ESPACIO PARA LA DECORACIÓN | G3: ='RVA205- COSTEO'!L5 | H3: ='RVA205- COSTEO'!L5
C4: ='COSTEO ANTERIOR'!E6 -> Registro de video Full - HD formato Horizontal 2:00 minutos | D4: ='COSTEO ANTERIOR'!L6 -> 78.078078 | F4: ='RVA205- COSTEO'!E6 -> Waira Balcón | G4: ='RVA205- COSTEO'!L6 -> 90.09009
C5: ='COSTEO ANTERIOR'!E7 -> 30 a 40 fotografías - Editadas en full calidad | D5: ='COSTEO ANTERIOR'!L7 -> 45.045045 | F5: ='RVA205- COSTEO'!E7 -> FOTOGRAFÍA Y VIDEO | G5: ='RVA205- COSTEO'!L7
C6: ='COSTEO ANTERIOR'!E9 -> MÚSICA | D6: ='COSTEO ANTERIOR'!L9 | F6: ='RVA205- COSTEO'!E8 -> Registro de video Full - HD formato Horizontal 2:00 minutos | G6: ='RVA205- COSTEO'!L8 -> 87.837838
C7: ='COSTEO ANTERIOR'!E10 -> Artista por 45 minutos | D7: ='COSTEO ANTERIOR'!L10 -> 210.21021 | F7: ='RVA205- COSTEO'!E9 -> 30 - 40 fotografías - Editadas en full calidad | G7: ='RVA205- COSTEO'!L9 -> 50.675676
C8: ='COSTEO ANTERIOR'!E11 -> DECORACIÓN | D8: ='COSTEO ANTERIOR'!L11 | F8: ='RVA205- COSTEO'!E10 -> Piloto Drone | G8: ='RVA205- COSTEO'!L10 -> 67.567568
C9: ='COSTEO ANTERIOR'!E12 -> Decorador | D9: ='COSTEO ANTERIOR'!L12 -> 75.075075 | F9: ='RVA205- COSTEO'!E11 -> MÚSICA | G9: ='RVA205- COSTEO'!L11
C10: ='COSTEO ANTERIOR'!E13 -> Estructura combo arco - piso - letrero | D10: ='COSTEO ANTERIOR'!L13 -> 54.054054 | F10: ='RVA205- COSTEO'!E12 -> Pianista x 45 minutos | G10: ='RVA205- COSTEO'!L12 -> 236.48649
C11: ='COSTEO ANTERIOR'!E14 -> Decoración del arco de corazón con flores artificiales | D11: ='COSTEO ANTERIOR'!L14 -> 208.70871 | F11: ='RVA205- COSTEO'!E13 -> Violinista | G11: ='RVA205- COSTEO'!L13 -> 168.91892
C12: ='COSTEO ANTERIOR'!E15 -> Velas blancas | D12: ='COSTEO ANTERIOR'!L15 -> 16.891892 | F12: ='RVA205- COSTEO'!E14 -> DECORACIÓN | G12: ='RVA205- COSTEO'!L14
C13: ='COSTEO ANTERIOR'!E16 -> Tapete Rojo | D13: ='COSTEO ANTERIOR'!L16 -> 9.009009 | F13: ='RVA205- COSTEO'!E15 -> Estructura combo arco - piso - letrero | G13: ='RVA205- COSTEO'!L15 -> 54.054054
C14: ='COSTEO ANTERIOR'!E17 -> Pétalos de rosa artificiales | D14: ='COSTEO ANTERIOR'!L17 -> 6.006006 | F14: ='RVA205- COSTEO'!E16 -> Letrero con el nombre SHAINA | G14: ='RVA205- COSTEO'!L16 -> 95.389507
C15: ='COSTEO ANTERIOR'!E18 -> Letrero con el nombre SHAINA | D15: ='COSTEO ANTERIOR'!L18 -> 81.081081 | F15: ='RVA205- COSTEO'!E17 -> Tapete Rojo | G15: ='RVA205- COSTEO'!L17 -> 33.033033
C16: ='COSTEO ANTERIOR'!E19 -> Polvora FRIA 2 un solo disparo | D16: ='COSTEO ANTERIOR'!L19 -> 78.078078 | F16: ='RVA205- COSTEO'!E18 -> Decoración del arco de corazón con flores naturales | G16: ='RVA205- COSTEO'!L18 -> 208.70871
C17: ='COSTEO ANTERIOR'!E20 -> OBSEQUIO | D17: ='COSTEO ANTERIOR'!L20 | F17: ='RVA205- COSTEO'!E19 -> Decorador | G17: ='RVA205- COSTEO'!L19 -> 75.075075
... C22: ='COSTEO ANTERIOR'!E25 -> Medical Trip Colombia | D22: ='COSTEO ANTERIOR'!L25 -> 180.18018 | F22: ='RVA205- COSTEO'!E24 -> Arreglo floral para la novia | G22: ='RVA205- COSTEO'!L24 -> 120.12012
C23: TOTAL | D23: =SUM(D4:D22) -> 1210.5856 | F23: ='RVA205- COSTEO'!E25 -> TRANSPORTE | G23: ='RVA205- COSTEO'!L25
C24: ='COSTEO ANTERIOR'!E27 | F24: ='RVA205- COSTEO'!E26 -> Transporte decoración | G24: ='RVA205- COSTEO'!L26 -> 78.078078
C25: ='COSTEO ANTERIOR'!E28 | F25: ='RVA205- COSTEO'!E27 -> LOGISTICA | G25: ='RVA205- COSTEO'!L27
C26: ='COSTEO ANTERIOR'!E29 | F26: ='RVA205- COSTEO'!E28 -> Medical Trip Colombia | G26: ='RVA205- COSTEO'!L28 -> 202.7027
C27: ='COSTEO ANTERIOR'!E30 | F27: Impuesto bancario 4 * 1000 | G27: =1616*4/1000 -> 6.464
C28: ='COSTEO ANTERIOR'!E31 | F28: Transferencia internacional | G28: 30
C29: ='COSTEO ANTERIOR'!E32 | F29: TOTAL A PAGAR | G29: =SUM(G3:G28) -> 1725.7724
C30: ='COSTEO ANTERIOR'!E33 | G30: =1726-30 -> 1696
C31: ='COSTEO ANTERIOR'!E34 | G31: 1678
C32: ='COSTEO ANTERIOR'!E35 | G32: =G30-G31 -> 18 | H32: usd
C33: ='COSTEO ANTERIOR'!E36 | G33: 15 | H33: usd de gastos
C34: ='COSTEO ANTERIOR'!E37
C35: ='COSTEO ANTERIOR'!E38
C36: ='COSTEO ANTERIOR'!E39
C37: ='COSTEO ANTERIOR'!E40
C38: ='COSTEO ANTERIOR'!E41
C39: ='COSTEO ANTERIOR'!E42
C40: ='COSTEO ANTERIOR'!E43
C41: ='COSTEO ANTERIOR'!E44
C42: ='COSTEO ANTERIOR'!E45
H45: ='RVA205- COSTEO'!L47
H46: ='RVA205- COSTEO'!L48
H47: ='RVA205- COSTEO'!L49
...

Sheet  Confirmación de 
H3: https://pinateriatufiesta.com/product/2230/petalos_de_rosa_artificiales_x100

Sheet CONFIRMACIÓN 

Sheet Hoja 18
